Workbook
Name Beg_Bal: #REF!
Name Beg_Bal: #REF!
Name Cum_Int: #REF!
Name Data: #REF!
Name DisbursementType: #REF!
Name DisbursementType: #REF!
Name End_Bal: #REF!
Name End_Bal: #REF!
Name EXPENSES: #REF!
Name EXPENSES: #REF!
Name Extra_Pay: #REF!
Name Extra_Pay: #REF!
Name Full_Print: #REF!
Name Full_Print: #REF!
Name Header_Row: ROW(#REF!)
Name Header_Row: ROW(#REF!)
Name Int: #REF!
Name Int: #REF!
Name Interest_Rate: #REF!
Name Interest_Rate: #REF!
Name Last_Row: IF('504-Hybrid'!Values_Entered,Header_Row+'504-Hybrid'!Number_of_Payments,Header_Row)
Name Last_Row: IF(Scores!Values_Entered,Scores!Header_Row+Scores!Number_of_Payments,Scores!Header_Row)
Name Last_Row: IF(Values_Entered,Header_Row+Number_of_Payments,Header_Row)
Name Loan_Amount: #REF!
Name Loan_Amount: #REF!
Name Loan_Start: #REF!
Name Loan_Start: #REF!
Name Loan_Years: #REF!
Name Loan_Years: #REF!
Name MajorExpensesList: #REF!
Name MajorExpensesList: #REF!
Name Num_Pmt_Per_Year: #REF!
Name Num_Pmt_Per_Year: #REF!
Name Number_of_Payments: MATCH(0.01,End_Bal,-1)+1
Name Number_of_Payments: MATCH(0.01,Scores!End_Bal,-1)+1
Name Number_of_Payments: MATCH(0.01,End_Bal,-1)+1
Name Pay_Date: #REF!
Name Pay_Num: #REF!
Name Pay_Num: #REF!
Name Payment_Date: DATE(YEAR(Scores!Loan_Start),MONTH(Scores!Loan_Start)+Payment_Number,DAY(Scores!Loan_Start))
Name Payment_Date: DATE(YEAR(Loan_Start),MONTH(Loan_Start)+Payment_Number,DAY(Loan_Start))
Name Periodic_rate: Annual_interest_rate/Payments_per_year
Name Periodic_rate: Annual_interest_rate/Payments_per_year
Name Periodic_rate: Annual_interest_rate/Payments_per_year
Name Princ: #REF!
Name Princ: #REF!
Name Print_Area_Reset: OFFSET(Full_Print,0,0,[0]!Last_Row)
Name Print_Area_Reset: OFFSET(Scores!Full_Print,0,0,Scores!Last_Row)
Name Print_Area_Reset: OFFSET(Full_Print,0,0,Last_Row)
Name Sched_Pay: #REF!
Name Sched_Pay: #REF!
Name Scheduled_Extra_Payments: #REF!
Name Scheduled_Extra_Payments: #REF!
Name Scheduled_Interest_Rate: #REF!
Name Scheduled_Monthly_Payment: #REF!
Name Scheduled_Monthly_Payment: #REF!
Name Total_Interest: #REF!
Name Total_Pay: #REF!
Name Total_Pay: #REF!
Name Total_Payment: Scheduled_Payment+Extra_Payment

Sheet Financial Spreads
B1: Financing Structure
C2: ='BDO Prequal'!C31 -> T Bank Loan | D2: ='BDO Prequal'!D31 -> T Bank Loan | E2: ='BDO Prequal'!E31 -> CDC Debenture | F2: ='BDO Prequal'!F31 -> T Bank Loan | G2: ='BDO Prequal'!G31 -> T Bank Loan | H2: ='BDO Prequal'!H31 -> Equity | I2: ='BDO Prequal'!I31 -> Seller Note | J2: ='BDO Prequal'!J31 -> 3rd Party
B3: Financing Source | C3: =IF('BDO Prequal'!C32=0,"", 'BDO Prequal'!C32) -> P&E | D3: =IF('BDO Prequal'!D32=0,"", 'BDO Prequal'!D32) -> USDA | E3: =IF('BDO Prequal'!E32=0,"", 'BDO Prequal'!E32) -> Conventional | F3: =IF('BDO Prequal'!F32=0,"", 'BDO Prequal'!F32) -> 7A Express | G3: =IF('BDO Prequal'!G32=0,"", 'BDO Prequal'!G32) -> CAPLine | H3: ='BDO Prequal'!H31 -> Equity | I3: ='BDO Prequal'!I31 -> Seller Note | J3: ='BDO Prequal'!J31 -> 3rd Party
B4: Guarantee % | C4: 0.75 | D4: 0 | E4: 0.5 | F4: 0.24 | G4: 0.6 | H4: 0.54 | I4: 0.02 | J4: 0.03
B5: Amount | C5: ='BDO Prequal'!C33 -> 1000 | D5: ='BDO Prequal'!D33 -> 20000 | E5: ='BDO Prequal'!E33 -> 30000 | F5: ='BDO Prequal'!F33 -> 4 | G5: ='BDO Prequal'!G33 -> 5 | H5: ='BDO Prequal'!H33 -> 6 | I5: ='BDO Prequal'!I33 -> 7 | J5: ='BDO Prequal'!J33 -> 8
B6: Rate Type | C6: Variable | D6: Variable | E6: Fixed | F6: Fixed | G6: Fixed | H6: Fixed | I6: Fixed | J6: N/A
B7: Term Yrs | C7: ='BDO Prequal'!C38 -> 10 | D7: ='BDO Prequal'!D38 -> 10 | E7: ='BDO Prequal'!E38 -> 10 | F7: ='BDO Prequal'!F38 -> 10 | G7: ='BDO Prequal'!G38 -> 0 | H7: ='BDO Prequal'!H38 -> 0 | I7: ='BDO Prequal'!I38 -> 10 | J7: ='BDO Prequal'!J38 -> 25
B8: Amortization (Months) | C8: ='BDO Prequal'!C39 -> 120 | D8: ='BDO Prequal'!D39 -> 120 | E8: ='BDO Prequal'!E39 -> 120 | F8: ='BDO Prequal'!F39 -> 120 | G8: ='BDO Prequal'!G39 -> 0 | H8: ='BDO Prequal'!H39 -> 0 | I8: ='BDO Prequal'!I39 -> 120 | J8: ='BDO Prequal'!J39 -> 300
B9: Base Rate | C9: ='BDO Prequal'!C34 -> 0.075 | D9: ='BDO Prequal'!D34 -> 0.075 | E9: ='BDO Prequal'!E34 -> 0.075 | F9: ='BDO Prequal'!F34 -> 0.075 | G9: ='BDO Prequal'!G34 -> 0 | H9: ='BDO Prequal'!H34 -> 0 | I9: ='BDO Prequal'!I34 -> 0.08 | J9: ='BDO Prequal'!J34 -> 0.0624
B10: Spread | C10: ='BDO Prequal'!C35 -> 0.015 | D10: ='BDO Prequal'!D35 -> 0.015 | E10: ='BDO Prequal'!E35 -> 0.015 | F10: ='BDO Prequal'!F35 -> 0.015 | G10: ='BDO Prequal'!G35 -> 0 | H10: ='BDO Prequal'!H35 -> 0 | I10: ='BDO Prequal'!I35 -> 0 | J10: ='BDO Prequal'!J35 -> 0
B11: Total Rate | C11: =C9+C10 -> 0.09 | D11: =D9+D10 -> 0.09 | E11: =E9+E10 -> 0.09 | F11: =F9+F10 -> 0.09 | G11: =G9+G10 -> 0 | H11: =H9+H10 -> 0 | I11: =I9+I10 -> 0.08 | J11: =J9+J10 -> 0.0624
B13: Sources and Uses of Proceeds
C14: ='BDO Prequal'!C47 -> P&E | D14: ='BDO Prequal'!D47 -> USDA | E14: ='BDO Prequal'!E47 -> Conventional | F14: ='BDO Prequal'!F47 -> 7A Express | G14: ='BDO Prequal'!G47 -> CAPLine | H14: ='BDO Prequal'!H47 -> Equity | I14: ='BDO Prequal'!I47 -> Seller Note | J14: ='BDO Prequal'!J47 -> 3rd Party | K14: ='BDO Prequal'!K47 -> Total
B15: Real Estate Acquisition | C15: ='BDO Prequal'!C49 -> 896000 | D15: ='BDO Prequal'!D49 -> 896000 | E15: ='BDO Prequal'!E49 -> 896000 | F15: ='BDO Prequal'!F49 -> 896000 | G15: ='BDO Prequal'!G49 -> 896000 | H15: ='BDO Prequal'!H49 -> 8000 | I15: ='BDO Prequal'!I49 -> 80000 | J15: ='BDO Prequal'!J49 -> 16000 | K15: ='BDO Prequal'!K49 -> 1000000
B16: Debt Refi - CRE | C16: ='BDO Prequal'!C50 -> 5387 | D16: ='BDO Prequal'!D50 -> 5387 | E16: ='BDO Prequal'!E50 -> 5387 | F16: ='BDO Prequal'!F50 -> 5387 | G16: ='BDO Prequal'!G50 -> 5387 | H16: ='BDO Prequal'!H50 -> 10 | I16: ='BDO Prequal'!I50 -> 1 | J16: ='BDO Prequal'!J50 -> 2 | K16: ='BDO Prequal'!K50 -> 5400
B17: Debt Refi - Non-CRE | C17: ='BDO Prequal'!C51 -> 55987 | D17: ='BDO Prequal'!D51 -> 55987 | E17: ='BDO Prequal'!E51 -> 55987 | F17: ='BDO Prequal'!F51 -> 55987 | G17: ='BDO Prequal'!G51 -> 55987 | H17: ='BDO Prequal'!H51 -> 10 | I17: ='BDO Prequal'!I51 -> 1 | J17: ='BDO Prequal'!J51 -> 2 | K17: ='BDO Prequal'!K51 -> 56000
B18: Machinery & Equipment | C18: ='BDO Prequal'!C52 -> 4499 | D18: ='BDO Prequal'!D52 -> 4499 | E18: ='BDO Prequal'!E52 -> 4499 | F18: ='BDO Prequal'!F52 -> 4499 | G18: ='BDO Prequal'!G52 -> 4499 | H18: ='BDO Prequal'!H52 -> 10 | I18: ='BDO Prequal'!I52 -> 1 | J18: ='BDO Prequal'!J52 -> 2 | K18: ='BDO Prequal'!K52 -> 4512
B19: Furniture & Fixtures (TIs) | C19: ='BDO Prequal'!C53 -> 2499 | D19: ='BDO Prequal'!D53 -> 2499 | E19: ='BDO Prequal'!E53 -> 2499 | F19: ='BDO Prequal'!F53 -> 2499 | G19: ='BDO Prequal'!G53 -> 2499 | H19: ='BDO Prequal'!H53 -> 10 | I19: ='BDO Prequal'!I53 -> 1 | J19: ='BDO Prequal'!J53 -> 2 | K19: ='BDO Prequal'!K53 -> 2512
B20: Inventory | C20: ='BDO Prequal'!C54 -> 4202 | D20: ='BDO Prequal'!D54 -> 4202 | E20: ='BDO Prequal'!E54 -> 4202 | F20: ='BDO Prequal'!F54 -> 4202 | G20: ='BDO Prequal'!G54 -> 4202 | H20: ='BDO Prequal'!H54 -> 10 | I20: ='BDO Prequal'!I54 -> 1 | J20: ='BDO Prequal'!J54 -> 2 | K20: ='BDO Prequal'!K54 -> 4215
B21: Working Capital | C21: ='BDO Prequal'!C55 -> 84348 | D21: ='BDO Prequal'!D55 -> 84348 | E21: ='BDO Prequal'!E55 -> 84348 | F21: ='BDO Prequal'!F55 -> 84348 | G21: ='BDO Prequal'!G55 -> 84348 | H21: ='BDO Prequal'!H55 -> 10 | I21: ='BDO Prequal'!I55 -> 1 | J21: ='BDO Prequal'!J55 -> 2 | K21: ='BDO Prequal'!K55 -> 84361
B22: Working Capital - Pre Opening | C22: ='BDO Prequal'!C56 -> 58397 | D22: ='BDO Prequal'!D56 -> 58397 | E22: ='BDO Prequal'!E56 -> 58397 | F22: ='BDO Prequal'!F56 -> 58397 | G22: ='BDO Prequal'!G56 -> 58397 | H22: ='BDO Prequal'!H56 -> 10 | I22: ='BDO Prequal'!I56 -> 1 | J22: ='BDO Prequal'!J56 -> 2 | K22: ='BDO Prequal'!K56 -> 58410
B23: Business Acquisition | C23: ='BDO Prequal'!C57 -> 2919 | D23: ='BDO Prequal'!D57 -> 2919 | E23: ='BDO Prequal'!E57 -> 2919 | F23: ='BDO Prequal'!F57 -> 2919 | G23: ='BDO Prequal'!G57 -> 2919 | H23: ='BDO Prequal'!H57 -> 10 | I23: ='BDO Prequal'!I57 -> 1 | J23: ='BDO Prequal'!J57 -> 2 | K23: ='BDO Prequal'!K57 -> 2932
B24: Franchise Fees | C24: ='BDO Prequal'!C58 -> 3593 | D24: ='BDO Prequal'!D58 -> 3593 | E24: ='BDO Prequal'!E58 -> 3593 | F24: ='BDO Prequal'!F58 -> 3593 | G24: ='BDO Prequal'!G58 -> 3593 | H24: ='BDO Prequal'!H58 -> 10 | I24: ='BDO Prequal'!I58 -> 1 | J24: ='BDO Prequal'!J58 -> 2 | K24: ='BDO Prequal'!K58 -> 3606
B25: Construction Hard Costs | C25: ='BDO Prequal'!C59 -> 45097 | D25: ='BDO Prequal'!D59 -> 45097 | E25: ='BDO Prequal'!E59 -> 45097 | F25: ='BDO Prequal'!F59 -> 45097 | G25: ='BDO Prequal'!G59 -> 45097 | H25: ='BDO Prequal'!H59 -> 10 | I25: ='BDO Prequal'!I59 -> 1 | J25: ='BDO Prequal'!J59 -> 2 | K25: ='BDO Prequal'!K59 -> 45110
B26: Interim Interest Reserve | C26: ='BDO Prequal'!C60 -> 8000 | D26: ='BDO Prequal'!D60 -> 200 | E26: ='BDO Prequal'!E60 -> 2230 | F26: ='BDO Prequal'!F60 -> 2000 | G26: ='BDO Prequal'!G60 -> 0 | H26: ='BDO Prequal'!H60 -> 373817 | I26: ='BDO Prequal'!I60 -> 8000 | J26: ='BDO Prequal'!J60 -> 800 | K26: ='BDO Prequal'!K60 -> 381817
... B31: Total | C31: ='BDO Prequal'!C65 -> -115502 | D31: ='BDO Prequal'!D65 -> -128272 | E31: ='BDO Prequal'!E65 -> -125522 | F31: ='BDO Prequal'!F65 -> -126472 | G31: ='BDO Prequal'!G65 -> -128552 | H31: ='BDO Prequal'!H65 -> 1336917 | I31: ='BDO Prequal'!I65 -> 257182 | J31: ='BDO Prequal'!J65 -> 214570 | K31: ='BDO Prequal'!K65 -> 1684367
B32: Percentage of Project | C32: ='BDO Prequal'!C66 -> -0.068572942 | D32: ='BDO Prequal'!D66 -> -0.076154425 | E32: ='BDO Prequal'!G66 -> -0.076320659 | F32: ='BDO Prequal'!H66 -> 0.79372073 | G32: ='BDO Prequal'!I66 -> 0.15268763 | H32: ='BDO Prequal'!H66 -> 0.79372073 | I32: ='BDO Prequal'!I66 -> 0.15268763 | J32: ='BDO Prequal'!J66 -> 0.1273891 | K32: ='BDO Prequal'!K66 -> 1
B34: Income Statement Spreads
C35: Period 1 | D35: Period 2 | E35: Period 3 | F35: Period 4
B36: Statement Date | C36: ='BDO Prequal'!D85 -> 44926 | D36: ='BDO Prequal'!F85 -> 45291 | E36: ='BDO Prequal'!H85 -> 45657 | F36: ='BDO Prequal'!J85 -> 45747
B37: Months Covered | C37: ='BDO Prequal'!D86 -> 12 | D37: ='BDO Prequal'!F86 -> 12 | E37: ='BDO Prequal'!H86 -> 12 | F37: ='BDO Prequal'!J86 -> 3
B38: Statement Type (Tax Returns / Internal) | C38: =IF(OR('BDO Prequal'!D87="",'BDO Prequal'!D87=0),"",'BDO Prequal'!D87) -> Tax Returns | D38: =IF(OR('BDO Prequal'!F87="",'BDO Prequal'!F87=0),"",'BDO Prequal'!F87) -> Tax Returns | E38: =IF(OR('BDO Prequal'!H87="",'BDO Prequal'!H87=0),"",'BDO Prequal'!H87) -> Form 10K | F38: =IF(OR('BDO Prequal'!J87="",'BDO Prequal'!J87=0),"",'BDO Prequal'!J87) -> Internal
B39: Revenue Recognition (Cash / Accrual) | C39: =IF(OR('BDO Prequal'!D88="",'BDO Prequal'!D88=0),"",'BDO Prequal'!D88) -> Accrual | D39: =IF(OR('BDO Prequal'!F88="",'BDO Prequal'!F88=0),"",'BDO Prequal'!F88) -> Accrual | E39: =IF(OR('BDO Prequal'!H88="",'BDO Prequal'!H88=0),"",'BDO Prequal'!H88) -> Cash | F39: =IF(OR('BDO Prequal'!J88="",'BDO Prequal'!J88=0),"",'BDO Prequal'!J88) -> Cash
B40: GROSS INCOME
B41: Total Revenue | C41: ='BDO Prequal'!D99 -> 9000 | D41: ='BDO Prequal'!F99 -> 2166 | E41: ='BDO Prequal'!H99 -> 1145 | F41: ='BDO Prequal'!J99 -> 880
B42: Total COGS | C42: ='BDO Prequal'!D100 -> 50 | D42: ='BDO Prequal'!F100 -> 500 | E42: ='BDO Prequal'!H100 -> 400 | F42: ='BDO Prequal'!J100 -> 8000
B43: Total Gross Margin | C43: ='BDO Prequal'!D101 -> 8950 | D43: ='BDO Prequal'!F101 -> 1666 | E43: ='BDO Prequal'!H101 -> 745 | F43: ='BDO Prequal'!J101 -> -7120
B44: NET INCOME
B45: Total Operating Expenses | C45: ='BDO Prequal'!D128 -> 800 | D45: ='BDO Prequal'!F128 -> 800 | E45: ='BDO Prequal'!H128 -> 500 | F45: ='BDO Prequal'!J128 -> 5000
B46: Ordinary Income | C46: ='BDO Prequal'!D130 -> 8150 | D46: ='BDO Prequal'!F130 -> 866 | E46: ='BDO Prequal'!H130 -> 245 | F46: ='BDO Prequal'!G130 -> 0.39981533
...

Sheet Summary
B2: Loan ID
B4: Financing Structure
B5: Terms | C5: Source 1 | D5: Source 2 | E5: Source 3 | F5: Source 4 | G5: Source 5 | H5: Source 6 | I5: Source 7 | J5: Source 8
B6: Financing Type | C6: ='BDO Prequal'!C31 -> T Bank Loan | D6: ='BDO Prequal'!D31 -> T Bank Loan | E6: ='BDO Prequal'!E31 -> CDC Debenture | F6: ='BDO Prequal'!F31 -> T Bank Loan | G6: ='BDO Prequal'!G31 -> T Bank Loan | H6: ='BDO Prequal'!H31 -> Equity | I6: ='BDO Prequal'!I31 -> Seller Note | J6: ='BDO Prequal'!J31 -> 3rd Party
B7: SBA Product Type | C7: =IF('BDO Prequal'!C32=0,"", 'BDO Prequal'!C32) -> P&E | D7: =IF('BDO Prequal'!D32=0,"", 'BDO Prequal'!D32) -> USDA | E7: =IF('BDO Prequal'!E32=0,"", 'BDO Prequal'!E32) -> Conventional | F7: =IF('BDO Prequal'!F32=0,"", 'BDO Prequal'!F32) -> 7A Express | G7: =IF('BDO Prequal'!G32=0,"", 'BDO Prequal'!G32) -> CAPLine | H7: ='BDO Prequal'!H31 -> Equity | I7: ='BDO Prequal'!I31 -> Seller Note | J7: ='BDO Prequal'!J31 -> 3rd Party
B8: Guarantee % | C8: 0.75
B9: Amount | C9: ='BDO Prequal'!C33 -> 1000 | D9: ='BDO Prequal'!D33 -> 20000 | E9: ='BDO Prequal'!E33 -> 30000 | F9: ='BDO Prequal'!F33 -> 4 | G9: ='BDO Prequal'!G33 -> 5 | H9: ='BDO Prequal'!H33 -> 6 | I9: ='BDO Prequal'!I33 -> 7 | J9: ='BDO Prequal'!J33 -> 8
B10: Rate Type | C10: Variable
B11: Term Yrs | C11: ='BDO Prequal'!C38 -> 10 | D11: ='BDO Prequal'!D38 -> 10 | E11: ='BDO Prequal'!E38 -> 10 | F11: ='BDO Prequal'!F38 -> 10 | G11: ='BDO Prequal'!G38 -> 0 | H11: ='BDO Prequal'!H38 -> 0 | I11: ='BDO Prequal'!I38 -> 10 | J11: ='BDO Prequal'!J38 -> 25
B12: Amortization (Months) | C12: ='BDO Prequal'!C39 -> 120 | D12: ='BDO Prequal'!D39 -> 120 | E12: ='BDO Prequal'!E39 -> 120 | F12: ='BDO Prequal'!F39 -> 120 | G12: ='BDO Prequal'!G39 -> 0 | H12: ='BDO Prequal'!H39 -> 0 | I12: ='BDO Prequal'!I39 -> 120 | J12: ='BDO Prequal'!J39 -> 300
B13: Base Rate | C13: ='BDO Prequal'!C34 -> 0.075 | D13: ='BDO Prequal'!D34 -> 0.075 | E13: ='BDO Prequal'!E34 -> 0.075 | F13: ='BDO Prequal'!F34 -> 0.075 | G13: ='BDO Prequal'!G34 -> 0 | H13: ='BDO Prequal'!H34 -> 0 | I13: ='BDO Prequal'!I34 -> 0.08 | J13: ='BDO Prequal'!J34 -> 0.0624
B14: Spread | C14: ='BDO Prequal'!C35 -> 0.015 | D14: ='BDO Prequal'!D35 -> 0.015 | E14: ='BDO Prequal'!E35 -> 0.015 | F14: ='BDO Prequal'!F35 -> 0.015 | G14: ='BDO Prequal'!G35 -> 0 | H14: ='BDO Prequal'!H35 -> 0 | I14: ='BDO Prequal'!I35 -> 0 | J14: ='BDO Prequal'!J35 -> 0
B15: Total Rate | C15: =C13+C14 -> 0.09 | D15: =D13+D14 -> 0.09 | E15: =E13+E14 -> 0.09 | F15: =F13+F14 -> 0.09 | G15: =G13+G14 -> 0 | H15: =H13+H14 -> 0 | I15: =I13+I14 -> 0.08 | J15: =J13+J14 -> 0.0624
B18: Sources and Uses of Proceeds
B19: Direct Project Costs | C19: ='BDO Prequal'!C47 -> P&E | D19: ='BDO Prequal'!D47 -> USDA | E19: ='BDO Prequal'!E47 -> Conventional | F19: ='BDO Prequal'!F47 -> 7A Express | G19: ='BDO Prequal'!G47 -> CAPLine | H19: ='BDO Prequal'!H47 -> Equity | I19: ='BDO Prequal'!I47 -> Seller Note | J19: ='BDO Prequal'!J47 -> 3rd Party | K19: ='BDO Prequal'!K47 -> Total
B20: Real Estate Acquisition | C20: ='BDO Prequal'!C49 -> 896000 | D20: ='BDO Prequal'!D49 -> 896000 | E20: ='BDO Prequal'!E49 -> 896000 | F20: ='BDO Prequal'!F49 -> 896000 | G20: ='BDO Prequal'!G49 -> 896000 | H20: ='BDO Prequal'!H49 -> 8000 | I20: ='BDO Prequal'!I49 -> 80000 | J20: ='BDO Prequal'!J49 -> 16000 | K20: =SUM(C20:J20) -> 4584000
B21: Debt Refi - CRE | C21: ='BDO Prequal'!C50 -> 5387 | D21: ='BDO Prequal'!D50 -> 5387 | E21: ='BDO Prequal'!E50 -> 5387 | F21: ='BDO Prequal'!F50 -> 5387 | G21: ='BDO Prequal'!G50 -> 5387 | H21: ='BDO Prequal'!H50 -> 10 | I21: ='BDO Prequal'!I50 -> 1 | J21: ='BDO Prequal'!J50 -> 2 | K21: =SUM(C21:J21) -> 26948
B22: Debt Refi - Non-CRE | C22: ='BDO Prequal'!C51 -> 55987 | D22: ='BDO Prequal'!D51 -> 55987 | E22: ='BDO Prequal'!E51 -> 55987 | F22: ='BDO Prequal'!F51 -> 55987 | G22: ='BDO Prequal'!G51 -> 55987 | H22: ='BDO Prequal'!H51 -> 10 | I22: ='BDO Prequal'!I51 -> 1 | J22: ='BDO Prequal'!J51 -> 2 | K22: =SUM(C22:J22) -> 279948
B23: Machinery & Equipment | C23: ='BDO Prequal'!C52 -> 4499 | D23: ='BDO Prequal'!D52 -> 4499 | E23: ='BDO Prequal'!E52 -> 4499 | F23: ='BDO Prequal'!F52 -> 4499 | G23: ='BDO Prequal'!G52 -> 4499 | H23: ='BDO Prequal'!H52 -> 10 | I23: ='BDO Prequal'!I52 -> 1 | J23: ='BDO Prequal'!J52 -> 2 | K23: =SUM(C23:J23) -> 22508
B24: Furniture & Fixtures (TIs) | C24: ='BDO Prequal'!C53 -> 2499 | D24: ='BDO Prequal'!D53 -> 2499 | E24: ='BDO Prequal'!E53 -> 2499 | F24: ='BDO Prequal'!F53 -> 2499 | G24: ='BDO Prequal'!G53 -> 2499 | H24: ='BDO Prequal'!H53 -> 10 | I24: ='BDO Prequal'!I53 -> 1 | J24: ='BDO Prequal'!J53 -> 2 | K24: =SUM(C24:J24) -> 12508
B25: Inventory | C25: ='BDO Prequal'!C54 -> 4202 | D25: ='BDO Prequal'!D54 -> 4202 | E25: ='BDO Prequal'!E54 -> 4202 | F25: ='BDO Prequal'!F54 -> 4202 | G25: ='BDO Prequal'!G54 -> 4202 | H25: ='BDO Prequal'!H54 -> 10 | I25: ='BDO Prequal'!I54 -> 1 | J25: ='BDO Prequal'!J54 -> 2 | K25: =SUM(C25:J25) -> 21023
B26: Working Capital | C26: ='BDO Prequal'!C55 -> 84348 | D26: ='BDO Prequal'!D55 -> 84348 | E26: ='BDO Prequal'!E55 -> 84348 | F26: ='BDO Prequal'!F55 -> 84348 | G26: ='BDO Prequal'!G55 -> 84348 | H26: ='BDO Prequal'!H55 -> 10 | I26: ='BDO Prequal'!I55 -> 1 | J26: ='BDO Prequal'!J55 -> 2 | K26: =SUM(C26:J26) -> 421753
B27: Working Capital - Pre Opening | C27: ='BDO Prequal'!C56 -> 58397 | D27: ='BDO Prequal'!D56 -> 58397 | E27: ='BDO Prequal'!E56 -> 58397 | F27: ='BDO Prequal'!F56 -> 58397 | G27: ='BDO Prequal'!G56 -> 58397 | H27: ='BDO Prequal'!H56 -> 10 | I27: ='BDO Prequal'!I56 -> 1 | J27: ='BDO Prequal'!J56 -> 2 | K27: =SUM(C27:J27) -> 291998
B28: Business Acquisition | C28: ='BDO Prequal'!C57 -> 2919 | D28: ='BDO Prequal'!D57 -> 2919 | E28: ='BDO Prequal'!E57 -> 2919 | F28: ='BDO Prequal'!F57 -> 2919 | G28: ='BDO Prequal'!G57 -> 2919 | H28: ='BDO Prequal'!H57 -> 10 | I28: ='BDO Prequal'!I57 -> 1 | J28: ='BDO Prequal'!J57 -> 2 | K28: =SUM(C28:J28) -> 14608
B29: Franchise Fees | C29: ='BDO Prequal'!C58 -> 3593 | D29: ='BDO Prequal'!D58 -> 3593 | E29: ='BDO Prequal'!E58 -> 3593 | F29: ='BDO Prequal'!F58 -> 3593 | G29: ='BDO Prequal'!G58 -> 3593 | H29: ='BDO Prequal'!H58 -> 10 | I29: ='BDO Prequal'!I58 -> 1 | J29: ='BDO Prequal'!J58 -> 2 | K29: =SUM(C29:J29) -> 17978
B30: Construction Hard Costs | C30: ='BDO Prequal'!C59 -> 45097 | D30: ='BDO Prequal'!D59 -> 45097 | E30: ='BDO Prequal'!E59 -> 45097 | F30: ='BDO Prequal'!F59 -> 45097 | G30: ='BDO Prequal'!G59 -> 45097 | H30: ='BDO Prequal'!H59 -> 10 | I30: ='BDO Prequal'!I59 -> 1 | J30: ='BDO Prequal'!J59 -> 2 | K30: =SUM(C30:J30) -> 225498
B31: Interim Interest Reserve | C31: ='BDO Prequal'!C60 -> 8000 | D31: ='BDO Prequal'!D60 -> 200 | E31: ='BDO Prequal'!E60 -> 2230 | F31: ='BDO Prequal'!F60 -> 2000 | G31: ='BDO Prequal'!G60 -> 0 | H31: ='BDO Prequal'!H60 -> 373817 | I31: ='BDO Prequal'!I60 -> 8000 | J31: ='BDO Prequal'!J60 -> 800 | K31: =SUM(C31:J31) -> 395047
... B35: SBA Gty Fee | C35: ='BDO Prequal'!C64 -> 5050 | D35: ='BDO Prequal'!D64 -> 80 | E35: ='BDO Prequal'!E64 -> 800 | F35: ='BDO Prequal'!F64 -> 80 | G35: ='BDO Prequal'!G64 -> 0 | H35: ='BDO Prequal'!H64 -> -5050 | I35: ='BDO Prequal'!I64 -> 0 | J35: ='BDO Prequal'!J64 -> 0 | K35: =SUM(C35:J35) -> 960
B36: Total | C36: =SUM(C20:C35) -> -115502 | D36: =SUM(D20:D35) -> -128272 | E36: =SUM(E20:E35) -> -125522 | F36: =SUM(F20:F35) -> -126472 | G36: =SUM(G20:G35) -> -128552 | H36: =SUM(H20:H35) -> 1336917 | I36: =SUM(I20:I35) -> 257182 | J36: =SUM(J20:J35) -> 214570 | K36: =SUM(C36:J36) -> 1184349
B37: Percentage of Project | C37: =C36/$K$36 -> -0.097523618 | D37: =D36/$K$36 -> -0.10830591 | E37: =E36/$K$36 -> -0.10598396 | F37: =F36/$K$36 -> -0.10678609 | G37: =G36/$K$36 -> -0.10854233 | H37: =H36/$K$36 -> 1.1288201 | I37: =I36/$K$36 -> 0.21715052 | J37: =J36/$K$36 -> 0.18117126 | K37: =K36/K36 -> 1
B39: Income Statement Spreads - Subject Business | H39: Income Statement Projections
B40: ='BDO Prequal'!B83 -> {Insert business name which represents PSOR} | H40: ='BDO Prequal'!B83 -> {Insert business name which represents PSOR}
C42: Statement Date | D42: ='BDO Prequal'!D85 -> 44926 | E42: ='BDO Prequal'!F85 -> 45291 | F42: ='BDO Prequal'!H85 -> 45657 | G42: ='BDO Prequal'!J85 -> 45747 | H42: Projections | I42: Projections
C43: Months Covered | D43: ='BDO Prequal'!D86 -> 12 | E43: ='BDO Prequal'!F86 -> 12 | F43: ='BDO Prequal'!H86 -> 12 | G43: ='BDO Prequal'!J86 -> 3 | H43: Customer | I43: Customer
C44: Statement Type | D44: ='BDO Prequal'!D87 -> Tax Returns | E44: ='BDO Prequal'!F87 -> Tax Returns | F44: ='BDO Prequal'!H87 -> Form 10K | G44: ='BDO Prequal'!J87 -> Internal | H44: Year | I44: Year
C45: Revenue Recognition | D45: ='BDO Prequal'!D88 -> Accrual | E45: ='BDO Prequal'!F88 -> Accrual | F45: ='BDO Prequal'!H88 -> Cash | G45: ='BDO Prequal'!J88 -> Cash | H45: 1 | I45: 2
C47: Total Revenue | D47: ='BDO Prequal'!D99 -> 9000 | E47: ='BDO Prequal'!F99 -> 2166 | F47: ='BDO Prequal'!H99 -> 1145 | G47: ='BDO Prequal'!J99 -> 880 | H47: ='BDO Prequal'!N99 -> 210 | I47: ='BDO Prequal'!P99 -> 620
C48: Total COGS | D48: ='BDO Prequal'!D100 -> 50 | E48: ='BDO Prequal'!F100 -> 500 | F48: ='BDO Prequal'!H100 -> 400 | G48: ='BDO Prequal'!J100 -> 8000 | H48: ='BDO Prequal'!N100 -> 30 | I48: ='BDO Prequal'!P100 -> 0
C49: Total Gross Margin | D49: ='BDO Prequal'!D101 -> 8950 | E49: ='BDO Prequal'!F101 -> 1666 | F49: ='BDO Prequal'!H101 -> 745 | G49: ='BDO Prequal'!J101 -> -7120 | H49: ='BDO Prequal'!N101 -> 180 | I49: ='BDO Prequal'!P101 -> 620
C51: Total Operating Expenses | D51: ='BDO Prequal'!D128 -> 800 | E51: ='BDO Prequal'!F128 -> 800 | F51: ='BDO Prequal'!H128 -> 500 | G51: ='BDO Prequal'!J128 -> 5000 | H51: ='BDO Prequal'!N128 -> 6747 | I51: ='BDO Prequal'!P128 -> 7603
...

Sheet BDO Prequal
B2: BDO Prequalification
B7: Loan Structure
B8: Purchase and Sale Close Date, if known, otherwise Target Closing Date
B11: Entity Name: | D11: Role | F11: Yrs. In Bus. | G11: Guarantor?
I12: BDO:
I13: Cooperating BDO:
I14: Broker Name:
I15: Broker Fee:
B17: * List entities in the following order (as applicable): Borrower, Co-Borrower, Operating Entity, Corp. Guarantor, Affiliate.
B18: Individual Guarantor Info: | C18: Ownership Exp. (yrs) | D18: Ownership % | E18: FICO | F18: Prior BK? | G18: Prior Loss to Gov't | H18: Debarred by SBA? | I18: Pending Legal Action? | J18: Criminal History?
B26: Business / Property Address:
C27: (Street) | F27: (City) (State) (ZIP)
B29: Loan Terms | Q29: Closing Costs | R29: Cost | S29: Quantity | T29: Total | Y29: Closing Cost Calculator ---> Expand/Collapse Above --->
S30: Loan Packaging Fee | T30: 2500 | U30: 1 | V30: =T30*U30 -> 2500 | W30: $1.5M - 2.5M
C31: T Bank Loan | D31: T Bank Loan | E31: CDC Debenture | F31: T Bank Loan | G31: T Bank Loan | H31: Equity | I31: Seller Note | J31: 3rd Party | Q31: Title Insurance | R31: 0 | S31: 0 | T31: =R31*S31 -> 0 | U31: 0.5%-1% of CRE value (FL & NY +)
B32: Product Type | C32: P&E | D32: USDA | E32: Conventional | F32: 7A Express | G32: CAPLine | M32: SBA Gty % | N32: 0.75 | Q32: Real Estate Tax Fee | R32: 0 | S32: 0 | T32: =R32*S32 -> 0 | U32: $150 for 1st $500M, $200 for $956M
B33: Loan Amount/Injection | C33: 1000 | D33: 20000 | E33: 30000 | F33: 4 | G33: 5 | H33: 6 | I33: 7 | J33: 8 | M33: Est. Appraisal Costs | N33: =SUM(T34,T35,T36,T40) -> 0 | Q33: Survey Charges | R33: 3000 | S33: 0 | T33: =R33*S33 -> 0 | U33: $1M - $3M
B34: Base Rate | C34: 0.075 | D34: 0.075 | E34: 0.075 | F34: 0.075 | I34: 0.08 | J34: 0.0624 | M34: Est. Environmental Report Costs | N34: =SUM(T37,T38) -> 0 | Q34: CRE Appraisal | R34: 3500 | S34: 0 | T34: =R34*S34 -> 0 | U34: $3.5M - $6.0M
B35: Spread | C35: 0.015 | D35: 0.015 | E35: 0.015 | F35: 0.015 | I35: 0 | J35: 0 | M35: Packaging Fee | N35: =SUM(V30) -> 2500 | Q35: Equipment Appraisal | R35: 0 | S35: 0 | T35: =R35*S35 -> 0 | U35: $1.5M - $3.5M
B36: Indicative Rate | C36: =C34+C35 -> 0.09 | D36: =D34+D35 -> 0.09 | E36: =E34+E35 -> 0.09 | F36: =F34+F35 -> 0.09 | I36: =I34+I35 -> 0.08 | J36: =J34+J35 -> 0.0624 | M36: Survey | N36: =SUM(T33) -> 0 | Q36: Appraisal Review | R36: 0 | S36: 0 | T36: =R36*S36 -> 0 | U36: $250 - $900
B37: Amortization Basis | C37: Actual/365 | D37: Actual/365 | E37: Actual/365 | F37: Actual/366 | M37: Business Valuation | N37: =SUM(T39) -> 0 | Q37: Site Visit | R37: 350 | S37: 0 | T37: =R37*S37 -> 0 | U37: 200
B38: Term (years) | C38: 10 | D38: 10 | E38: 10 | F38: 10 | I38: 10 | J38: 25 | M38: Title / Escrow / Closing | N38: =SUM(T31,T32) -> 0 | Q38: Environmental Investigation | R38: 2500 | S38: 0 | T38: =R38*S38 -> 0 | U38: $2M
B39: Amortization (mos) | C39: =C38*12 -> 120 | D39: =D38*12 -> 120 | E39: =E38*12 -> 120 | F39: =F38*12 -> 120 | I39: =I38*12 -> 120 | J39: =J38*12 -> 300 | M39: SBA GTY Fee | N39: =BE56 -> 0 | Q39: Business Valuation | R39: 2500 | S39: 0 | T39: =R39*S39 -> 0 | U39: $2.5M - $3M
B40: Estimated Payment | C40: =IFERROR(INDEX($BL$82:$BL$84,MATCH($C$37,$BC$82:$BC$84,0)),0) -> 12.671581 | D40: =IFERROR(INDEX($BL$82:$BL$84,MATCH($C$37,$BC$82:$BC$84,0)),0) -> 12.671581 | E40: =IFERROR(INDEX($BL$82:$BL$84,MATCH($C$37,$BC$82:$BC$84,0)),0) -> 12.671581 | F40: =IFERROR(INDEX($BL$82:$BL$84,MATCH($C$37,$BC$82:$BC$84,0)),0) -> 12.671581 | I40: =IFERROR(PMT(I36/12,I39,-I33),0) -> 0.084929316 | J40: =IFERROR(PMT(J36/12,J39,-J33),0) -> 0.05272411 | M40: Other Costs | N40: =T46-SUM(N33:O38) -> -2500 | Q40: Residential Appr / Valuation | R40: 0 | S40: 0 | T40: =R40*S40 -> 0 | U40: $500 - $700
B41: Est Const Period (mths) | C41: 120 | D41: 0 | E41: 0 | F41: 0 | M41: Total SBA Fees & Closing Costs | N41: =SUM(N33:O40) -> 0 | Q41: Attorney Doc Prep | R41: 6000 | S41: 1 | T41: =R41*S41 -> 6000 | U41: $3.5M-$6.0M
B42: Are there funded SBA Loans in last 90 days? | C42: No | D42: No | E42: No | F42: No | H42: Amount? | I42: 0 | J42: Guarantee %? | K42: 0 | Q42: Interim Loan Fee / Origination | R42: 0 | S42: 1 | T42: =R42*S42 -> 0 | U42: 1.0% -2.0% Conv/USDA Loans
Q43: Construction Monitoring | R43: 0 | S43: 1 | T43: =R43*S43 -> 0 | U43: See Partner ESI pricing sheet
Q44: Rounding | R44: 700 | S44: 1 | T44: =R44*S44 -> 700 | U44: =_xlfn.CONCAT("<--- To round to next $100, input $",ROUNDUP(T46,-2)-T46) -> <--- To round to next $100, input $0
B45: Sources and Uses of Proceeds | Q45: Other: UCCs and Misc Closing | T45: =T58 -> 800 | BC45: =IF(C32="SBA 7a","SBA 7a","Not 7a, Guaranty Calculation not applicable") -> Not 7a, Guaranty Calculation not applicable
Q46: Total Estimated Closing Costs | T46: =SUM(P30:P45) -> 0 | BF46: SBA Guaranty % | BH46: =N32 -> 0.75
C47: =IF(C32=0,"",C32) -> P&E | D47: =IF(D32=0,"",D32) -> USDA | E47: =IF(E32=0,"",E32) -> Conventional | F47: =IF(F32=0,"",F32) -> 7A Express | G47: =IF(G32=0,"",G32) -> CAPLine | H47: =H31 -> Equity | I47: =I31 -> Seller Note | J47: =J31 -> 3rd Party | K47: Total | L47: SBA Term (yrs) | M47: % | N47: Wgt | BC47: If there has been a previous SBA 7a loan funded within the last 90 days, enter loan amount and guaranty %.
B48: Direct Project Costs | Q48: Miscellaneous Closing Costs | R48: Cost | S48: Quantity | T48: Total | BC48: Previous Loan Amount | BG48: =I42 -> 0
B49: Real Estate Acquisition | C49: =$K49-SUM($H49:$J49) -> 896000 | D49: =$K49-SUM($H49:$J49) -> 896000 | E49: =$K49-SUM($H49:$J49) -> 896000 | F49: =$K49-SUM($H49:$J49) -> 896000 | G49: =$K49-SUM($H49:$J49) -> 896000 | H49: 8000 | I49: 80000 | J49: 16000 | K49: 1000000 | L49: 25 | M49: =IF($C$65=0,0,C49/$C$65) -> -7.7574414 | N49: =L49*M49 -> -193.93604 | Q49: Business Credit Report | R49: 35 | S49: 1 | T49: =R49*S49 -> 35 | BC49: Previous Guaranty % | BG49: =K42 -> 0
B50: Debt Refi - CRE | C50: =$K50-SUM($H50:$J50) -> 5387 | D50: =$K50-SUM($H50:$J50) -> 5387 | E50: =$K50-SUM($H50:$J50) -> 5387 | F50: =$K50-SUM($H50:$J50) -> 5387 | G50: =$K50-SUM($H50:$J50) -> 5387 | H50: 10 | I50: 1 | J50: 2 | K50: 5400 | L50: 25 | M50: =IF($C$65=0,0,C50/$C$65) -> -0.046639885 | N50: =L50*M50 -> -1.1659971 | Q50: Personal Credit Report | R50: 25 | S50: 2 | T50: =R50*S50 -> 50 | BC50: SBA Guaranty Fee Calculation
B51: Debt Refi - Non-CRE | C51: =$K51-SUM($H51:$J51) -> 55987 | D51: =$K51-SUM($H51:$J51) -> 55987 | E51: =$K51-SUM($H51:$J51) -> 55987 | F51: =$K51-SUM($H51:$J51) -> 55987 | G51: =$K51-SUM($H51:$J51) -> 55987 | H51: 10 | I51: 1 | J51: 2 | K51: 56000 | L51: 10 | M51: =IF($C$65=0,0,C51/$C$65) -> -0.48472754 | N51: =L51*M51 -> -4.8472754 | Q51: IRS Transcript Service | R51: 65 | S51: 2 | T51: =R51*S51 -> 130 | BC51: T Bank SBA Loan | BG51: Previous SBA Loan Within 90 Days | BJ51: Two Loans Combined
B52: Machinery & Equipment | C52: =$K52-SUM($H52:$J52) -> 4499 | D52: =$K52-SUM($H52:$J52) -> 4499 | E52: =$K52-SUM($H52:$J52) -> 4499 | F52: =$K52-SUM($H52:$J52) -> 4499 | G52: =$K52-SUM($H52:$J52) -> 4499 | H52: 10 | I52: 1 | J52: 2 | K52: 4512 | L52: 10 | M52: =IF($C$65=0,0,C52/$C$65) -> -0.038951706 | N52: =L52*M52 -> -0.38951706 | Q52: UCC Searches | R52: 300 | S52: 1 | T52: =R52*S52 -> 300 | BC52: Loan Amount | BF52: =IF(BC45="SBA 7a",C65,0) -> 0 | BG52: Loan Amount | BI52: =BG48 -> 0 | BJ52: Loan Amount | BL52: =BI52+BF52 -> 0
B53: Furniture & Fixtures (TIs) | C53: =$K53-SUM($H53:$J53) -> 2499 | D53: =$K53-SUM($H53:$J53) -> 2499 | E53: =$K53-SUM($H53:$J53) -> 2499 | F53: =$K53-SUM($H53:$J53) -> 2499 | G53: =$K53-SUM($H53:$J53) -> 2499 | H53: 10 | I53: 1 | J53: 2 | K53: 2512 | L53: 10 | M53: =IF($C$65=0,0,C53/$C$65) -> -0.021635989 | N53: =L53*M53 -> -0.21635989 | Q53: Certificate of Good Standing | R53: 20 | S53: 1 | T53: =R53*S53 -> 20 | BC53: Guaranteed Portion | BF53: =BF52*BH46 -> 0 | BG53: Guaranteed Portion | BI53: =BI52*BG49 -> 0 | BJ53: Guaranteed Portion | BL53: =BF53+BI53 -> 0
B54: Inventory | C54: =$K54-SUM($H54:$J54) -> 4202 | D54: =$K54-SUM($H54:$J54) -> 4202 | E54: =$K54-SUM($H54:$J54) -> 4202 | F54: =$K54-SUM($H54:$J54) -> 4202 | G54: =$K54-SUM($H54:$J54) -> 4202 | H54: 10 | I54: 1 | J54: 2 | K54: 4215 | L54: 10 | M54: =IF($C$65=0,0,C54/$C$65) -> -0.036380322 | N54: =L54*M54 -> -0.36380322 | Q54: Flood Certification | R54: 18 | S54: 1 | T54: =R54*S54 -> 18 | BC54: Guaranty Fee | BF54: =SUM(BF59:BF63) -> 0 | BG54: Guaranty Fee | BI54: =SUM(BG59:BH63) -> 0 | BJ54: Guaranty Fee | BL54: =SUM(BK59:BK63) -> 0
B55: Working Capital | C55: =$K55-SUM($H55:$J55) -> 84348 | D55: =$K55-SUM($H55:$J55) -> 84348 | E55: =$K55-SUM($H55:$J55) -> 84348 | F55: =$K55-SUM($H55:$J55) -> 84348 | G55: =$K55-SUM($H55:$J55) -> 84348 | H55: 10 | I55: 1 | J55: 2 | K55: 84361 | L55: 10 | M55: =IF($C$65=0,0,C55/$C$65) -> -0.73027307 | N55: =L55*M55 -> -7.3027307 | Q55: Filing & Recording Fees | R55: 100 | S55: 1 | T55: =R55*S55 -> 100 | U55: avg $100 | BC55: Add'l Gty Fee | BF55: =IF(BG48>0,BL54-BI54-BF54,0) -> 0
B56: Working Capital - Pre Opening | C56: =$K56-SUM($H56:$J56) -> 58397 | D56: =$K56-SUM($H56:$J56) -> 58397 | E56: =$K56-SUM($H56:$J56) -> 58397 | F56: =$K56-SUM($H56:$J56) -> 58397 | G56: =$K56-SUM($H56:$J56) -> 58397 | H56: 10 | I56: 1 | J56: 2 | K56: 58410 | L56: 10 | M56: =IF($C$65=0,0,C56/$C$65) -> -0.50559298 | N56: =L56*M56 -> -5.0559298 | Q56: FedEx Charges | R56: 50 | S56: 1 | T56: =R56*S56 -> 50 | U56: avg $50 | BC56: Total Gty Fee (Rounded) | BE56: =ROUNDUP(BF54+BF55,-0.1) -> 0 | BG56: Total Gty Fee (Rounded) | BI56: =ROUNDUP(BI54+BI55,-0.1) -> 0 | BJ56: Total Gty Fee (Rounded) | BL56: =ROUNDUP(BL54+BL55,-0.1) -> 0
...

Sheet Scores
B2: T Bank, N.A. SCORING GRID
B3: Total Score | C3: REPAYMENT | D3: MANAGEMENT | E3: CREDIT | F3: EQUITY | G3: COLLATERAL | H3: Working Capital/Liquidity
B4: =SUM(C4:H4) -> 0
B5: 5 | C5: Pro forma DSC of 1.40x in the most recent year and 1.25x or better for the prior 2 years plus stable/positive trends in the interim. Stable is considered + - 0.05 change in DSC. | D5: 3 or more years ownership in SBC or 3 years as primary responsible employee in SBC or 5 years recent experience in near identical type business as Principal Manager with P&L and HR responsibility. | E5: N/A | F5: 25% cash equity from personal sources Expansions: pro forma tangible D/W of 4:1 or less. | G5: Secured 120% of the loan on a discounted basis with any collateral or 100% secured with 1st lien on RE. 504 1st lien No construction | H5: N/A
B6: 4 | C6: Pro forma DSC of 1.40x or better for most recent years plus 1.25x for the 1 prior year plus stable/positive trends in the interim. Stable is considered + - 0.05 change in DSC. | D6: 2 or more years ownership in SBC or 3 years experience in near identical type business. For startups - this experience, must have been within the last 5 years AND one of the guarantors will devote 100% of time to SBC | E6: FICO Score greater than 750. | F6: 25% cash equity from any source or 20% from personal sources Expansions: pro forma tangible D/W of 5:1 or less. | G6: Secured 100% of the loan on a discounted basis with any collateral or 75% with 1st lien on RE. 504 1st Lien Construction | H6: N/A
B7: 3 | C7: Pro forma DSC of an 1.25x or better in most recent FYE and interim plus stable/positive trends in the interim. Stable is considered + - 0.05 change in DSC. Regardless of DSC declining revenue or profitability trends in the most recent year and/or interim. | D7: 2 years ownership in any industry or 3 years of transferable management experience in any industry, or approved franchise For startups - this experience, must have been within the last 5 years AND one of the guarantors will devote 100% of time to SBC. | E7: FICO Score of 700 to 749. Regardless of any higher FICO score BK between 3 and 5 years in time. Regardless of any higher FICO score expected continuing income of between $5500 and $6000 for every $1000 of CC debt | F7: 20% cash equity from any source or 15% from personal sources Expansions: pro forma tangible D/W of 6:1 or less. | G7: Secured 75% of the loan on a discounted basis with any collateral or 50% with 1st lien on RE. | H7: No or minimal working capital requirement OR Borrower has 1.5X working capital from own liquid resources. Minimal is the lesser of 5% of loan amount or $50K. None is included in loan.
B8: 2 | C8: Pro forma DSC of 1.15x or better in most recent FYE and interim plus positive trends in the interim. Regardless of DSC declining revenue or profitability trends in all periods Projection Based or Start Up with Approved Franchise. | D8: 2 years transferable management experience not specific to this industry or non-approved franchise. For startups - this experience must have been within the last 3 years AND one of the guarantors will 100% of time devoted to SBC | E8: FICO Score 650 to 699 Regardless of any higher FICO score expected continuing income of between $5000 and $5499 for every $1000 of CC debt | F8: 10% cash equity from any source Expansions: pro forma tangible D/W of 8:1 or less. | G8: Secured 50% of the loan on a discounted basis with any collateral or 25% with 1st lien on RE. | H8: Borrower has sufficient documented working Capital to inject from own resources (WC as calculated by U/W). In loan is OK as long as borrower has 1x or greater residual liquidity.
B9: 1 | C9: Projection based or start-up. | D9: Less than 2 years transferable management experience OR reliant on prior owner or franchisor for training. For startups - the experience was over 3 years ago. | E9: FICO Score less than 650 Regardless of any higher FICO score expected continuing income of between $4500 and $4999 for every $1000 of CC debt | F9: Less than 10% injection and/or 50% or more Equity is from Seller note on full standby | G9: < 50% secured with any collateral or less than 25% 1st lien on RE. | H9: All, or substantially all of W/C is included in loan or companion loan and borrower has little or no residual liquidity.
B10: 0 | C10: N/A | D10: Remote management or long distance management with no prior experience of remote management. | E10: BK in the last 3 years. Regardless of any higher FICO score expected continuing income of less than $4500 for every $1000 of CC debt | F10: Any other allowable SBA SOP structure that does not require injection. | G10: No CRE included in collateral or only junior liens on residential. | H10: Working capital included in loan proceeds exceeds 50% of borrower cash injection.
C14: ='BDO Prequal'!B73 -> Owner/Guarantor 1 | E14: ='BDO Prequal'!B74 -> Owner/Guarantor 2 | G14: ='BDO Prequal'!B75 -> Owner/Guarantor 3
C15: Income | D15: ='BDO Prequal'!C632 -> 0 | E15: Income | F15: ='BDO Prequal'!E632 -> 0 | G15: Income | H15: ='BDO Prequal'!G632 -> 0
C16: CC Debt | D16: 0 | E16: CC Debt | F16: 0 | G16: CC Debt | H16: 0
C17: Income Needed $4,500 | D17: =D16*4.5 -> 0 | E17: Income Needed $4,500 | F17: =F16*4.5 -> 0 | G17: Income Needed $4,500 | H17: =H16*4.5 -> 0
C18: Income Needed $4,999 | D18: =D16*4.999 -> 0 | E18: Income Needed $4,999 | F18: =F16*4.999 -> 0 | G18: Income Needed $4,999 | H18: =H16*4.999 -> 0
C19: Income Needed $5,499 | D19: =D16*5.499 -> 0 | E19: Income Needed $5,499 | F19: =F16*5.499 -> 0 | G19: Income Needed $5,499 | H19: =H16*5.499 -> 0
C20: Income Needed $6,000+ | D20: =D16*6 -> 0 | E20: Income Needed $6,000+ | F20: =F16*6 -> 0 | G20: Income Needed $6,000+ | H20: =H16*6 -> 0
C21: ='BDO Prequal'!B76 -> Owner/Guarantor 4
C22: Income | D22: ='BDO Prequal'!I632 -> 0 | E22: Income | F22: 0 | G22: Income | H22: 0
C23: CC Debt | D23: 0 | E23: CC Debt | F23: 0 | G23: CC Debt | H23: 0
C24: Income Needed $4,500 | D24: =D23*4.5 -> 0 | E24: Income Needed $4,500 | F24: =F23*4.5 -> 0 | G24: Income Needed $4,500 | H24: =H23*4.5 -> 0
C25: Income Needed $4,999 | D25: =D23*4.999 -> 0 | E25: Income Needed $4,999 | F25: =F23*4.999 -> 0 | G25: Income Needed $4,999 | H25: =H23*4.999 -> 0
C26: Income Needed $5,499 | D26: =D23*5.499 -> 0 | E26: Income Needed $5,499 | F26: =F23*5.499 -> 0 | G26: Income Needed $5,499 | H26: =H23*5.499 -> 0
C27: Income Needed $6,000+ | D27: =D23*6 -> 0 | E27: Income Needed $6,000+ | F27: =F23*6 -> 0 | G27: Income Needed $6,000+ | H27: =H23*6 -> 0

Sheet Charts
B3: Loan Request | I3: Loan Request | N3: Loan Request | T3: Loan Request
C5: ='BDO Prequal'!C47 -> P&E | D5: ='BDO Prequal'!H47 -> Equity | E5: ='BDO Prequal'!I47 -> Seller Note | F5: ='BDO Prequal'!J47 -> 3rd Party | G5: ='BDO Prequal'!K47 -> Total | J5: =C5 -> P&E | K5: =D5 -> Equity | L5: =G5 -> Total | O5: =C5 -> P&E | P5: =D5 -> Equity | Q5: =E5 -> Seller Note | R5: =G5 -> Total | U5: =C5 -> P&E | V5: =D5 -> Equity | W5: =F5 -> 3rd Party | X5: =G5 -> Total
B6: ='BDO Prequal'!B49 -> Real Estate Acquisition | C6: ='BDO Prequal'!C49 -> 896000 | D6: ='BDO Prequal'!H49 -> 8000 | E6: ='BDO Prequal'!I49 -> 80000 | F6: ='BDO Prequal'!J49 -> 16000 | G6: ='BDO Prequal'!K49 -> 1000000 | I6: =B6 -> Real Estate Acquisition | J6: =C6 -> 896000 | K6: =D6 -> 8000 | L6: =G6 -> 1000000 | N6: =B6 -> Real Estate Acquisition | O6: =C6 -> 896000 | P6: =D6 -> 8000 | Q6: =E6 -> 80000 | R6: =G6 -> 1000000 | T6: =B6 -> Real Estate Acquisition | U6: =C6 -> 896000 | V6: =D6 -> 8000 | W6: =F6 -> 16000 | X6: =G6 -> 1000000
B7: ='BDO Prequal'!B50 -> Debt Refi - CRE | C7: ='BDO Prequal'!C50 -> 5387 | D7: ='BDO Prequal'!H50 -> 10 | E7: ='BDO Prequal'!I50 -> 1 | F7: ='BDO Prequal'!J50 -> 2 | G7: ='BDO Prequal'!K50 -> 5400 | I7: =B7 -> Debt Refi - CRE | J7: =C7 -> 5387 | K7: =D7 -> 10 | L7: =G7 -> 5400 | N7: =B7 -> Debt Refi - CRE | O7: =C7 -> 5387 | P7: =D7 -> 10 | Q7: =E7 -> 1 | R7: =G7 -> 5400 | T7: =B7 -> Debt Refi - CRE | U7: =C7 -> 5387 | V7: =D7 -> 10 | W7: =F7 -> 2 | X7: =G7 -> 5400
B8: ='BDO Prequal'!B51 -> Debt Refi - Non-CRE | C8: ='BDO Prequal'!C51 -> 55987 | D8: ='BDO Prequal'!H51 -> 10 | E8: ='BDO Prequal'!I51 -> 1 | F8: ='BDO Prequal'!J51 -> 2 | G8: ='BDO Prequal'!K51 -> 56000 | I8: =B8 -> Debt Refi - Non-CRE | J8: =C8 -> 55987 | K8: =D8 -> 10 | L8: =G8 -> 56000 | N8: =B8 -> Debt Refi - Non-CRE | O8: =C8 -> 55987 | P8: =D8 -> 10 | Q8: =E8 -> 1 | R8: =G8 -> 56000 | T8: =B8 -> Debt Refi - Non-CRE | U8: =C8 -> 55987 | V8: =D8 -> 10 | W8: =F8 -> 2 | X8: =G8 -> 56000
B9: ='BDO Prequal'!B52 -> Machinery & Equipment | C9: ='BDO Prequal'!C52 -> 4499 | D9: ='BDO Prequal'!H52 -> 10 | E9: ='BDO Prequal'!I52 -> 1 | F9: ='BDO Prequal'!J52 -> 2 | G9: ='BDO Prequal'!K52 -> 4512 | I9: =B9 -> Machinery & Equipment | J9: =C9 -> 4499 | K9: =D9 -> 10 | L9: =G9 -> 4512 | N9: =B9 -> Machinery & Equipment | O9: =C9 -> 4499 | P9: =D9 -> 10 | Q9: =E9 -> 1 | R9: =G9 -> 4512 | T9: =B9 -> Machinery & Equipment | U9: =C9 -> 4499 | V9: =D9 -> 10 | W9: =F9 -> 2 | X9: =G9 -> 4512
B10: ='BDO Prequal'!B53 -> Furniture & Fixtures (TIs) | C10: ='BDO Prequal'!C53 -> 2499 | D10: ='BDO Prequal'!H53 -> 10 | E10: ='BDO Prequal'!I53 -> 1 | F10: ='BDO Prequal'!J53 -> 2 | G10: ='BDO Prequal'!K53 -> 2512 | I10: =B10 -> Furniture & Fixtures (TIs) | J10: =C10 -> 2499 | K10: =D10 -> 10 | L10: =G10 -> 2512 | N10: =B10 -> Furniture & Fixtures (TIs) | O10: =C10 -> 2499 | P10: =D10 -> 10 | Q10: =E10 -> 1 | R10: =G10 -> 2512 | T10: =B10 -> Furniture & Fixtures (TIs) | U10: =C10 -> 2499 | V10: =D10 -> 10 | W10: =F10 -> 2 | X10: =G10 -> 2512
B11: ='BDO Prequal'!B54 -> Inventory | C11: ='BDO Prequal'!C54 -> 4202 | D11: ='BDO Prequal'!H54 -> 10 | E11: ='BDO Prequal'!I54 -> 1 | F11: ='BDO Prequal'!J54 -> 2 | G11: ='BDO Prequal'!K54 -> 4215 | I11: =B11 -> Inventory | J11: =C11 -> 4202 | K11: =D11 -> 10 | L11: =G11 -> 4215 | N11: =B11 -> Inventory | O11: =C11 -> 4202 | P11: =D11 -> 10 | Q11: =E11 -> 1 | R11: =G11 -> 4215 | T11: =B11 -> Inventory | U11: =C11 -> 4202 | V11: =D11 -> 10 | W11: =F11 -> 2 | X11: =G11 -> 4215
B12: ='BDO Prequal'!B55 -> Working Capital | C12: ='BDO Prequal'!C55 -> 84348 | D12: ='BDO Prequal'!H55 -> 10 | E12: ='BDO Prequal'!I55 -> 1 | F12: ='BDO Prequal'!J55 -> 2 | G12: ='BDO Prequal'!K55 -> 84361 | I12: =B12 -> Working Capital | J12: =C12 -> 84348 | K12: =D12 -> 10 | L12: =G12 -> 84361 | N12: =B12 -> Working Capital | O12: =C12 -> 84348 | P12: =D12 -> 10 | Q12: =E12 -> 1 | R12: =G12 -> 84361 | T12: =B12 -> Working Capital | U12: =C12 -> 84348 | V12: =D12 -> 10 | W12: =F12 -> 2 | X12: =G12 -> 84361
B13: ='BDO Prequal'!B56 -> Working Capital - Pre Opening | C13: ='BDO Prequal'!C56 -> 58397 | D13: ='BDO Prequal'!H56 -> 10 | E13: ='BDO Prequal'!I56 -> 1 | F13: ='BDO Prequal'!J56 -> 2 | G13: ='BDO Prequal'!K56 -> 58410 | I13: =B13 -> Working Capital - Pre Opening | J13: =C13 -> 58397 | K13: =D13 -> 10 | L13: =G13 -> 58410 | N13: =B13 -> Working Capital - Pre Opening | O13: =C13 -> 58397 | P13: =D13 -> 10 | Q13: =E13 -> 1 | R13: =G13 -> 58410 | T13: =B13 -> Working Capital - Pre Opening | U13: =C13 -> 58397 | V13: =D13 -> 10 | W13: =F13 -> 2 | X13: =G13 -> 58410
B14: ='BDO Prequal'!B57 -> Business Acquisition | C14: ='BDO Prequal'!C57 -> 2919 | D14: ='BDO Prequal'!H57 -> 10 | E14: ='BDO Prequal'!I57 -> 1 | F14: ='BDO Prequal'!J57 -> 2 | G14: ='BDO Prequal'!K57 -> 2932 | I14: =B14 -> Business Acquisition | J14: =C14 -> 2919 | K14: =D14 -> 10 | L14: =G14 -> 2932 | N14: =B14 -> Business Acquisition | O14: =C14 -> 2919 | P14: =D14 -> 10 | Q14: =E14 -> 1 | R14: =G14 -> 2932 | T14: =B14 -> Business Acquisition | U14: =C14 -> 2919 | V14: =D14 -> 10 | W14: =F14 -> 2 | X14: =G14 -> 2932
B15: ='BDO Prequal'!B58 -> Franchise Fees | C15: ='BDO Prequal'!C58 -> 3593 | D15: ='BDO Prequal'!H58 -> 10 | E15: ='BDO Prequal'!I58 -> 1 | F15: ='BDO Prequal'!J58 -> 2 | G15: ='BDO Prequal'!K58 -> 3606 | I15: =B15 -> Franchise Fees | J15: =C15 -> 3593 | K15: =D15 -> 10 | L15: =G15 -> 3606 | N15: =B15 -> Franchise Fees | O15: =C15 -> 3593 | P15: =D15 -> 10 | Q15: =E15 -> 1 | R15: =G15 -> 3606 | T15: =B15 -> Franchise Fees | U15: =C15 -> 3593 | V15: =D15 -> 10 | W15: =F15 -> 2 | X15: =G15 -> 3606
B16: ='BDO Prequal'!B59 -> Construction Hard Costs | C16: ='BDO Prequal'!C59 -> 45097 | D16: ='BDO Prequal'!H59 -> 10 | E16: ='BDO Prequal'!I59 -> 1 | F16: ='BDO Prequal'!J59 -> 2 | G16: ='BDO Prequal'!K59 -> 45110 | I16: =B16 -> Construction Hard Costs | J16: =C16 -> 45097 | K16: =D16 -> 10 | L16: =G16 -> 45110 | N16: =B16 -> Construction Hard Costs | O16: =C16 -> 45097 | P16: =D16 -> 10 | Q16: =E16 -> 1 | R16: =G16 -> 45110 | T16: =B16 -> Construction Hard Costs | U16: =C16 -> 45097 | V16: =D16 -> 10 | W16: =F16 -> 2 | X16: =G16 -> 45110
B17: ='BDO Prequal'!B60 -> Interim Interest Reserve | C17: ='BDO Prequal'!C60 -> 8000 | D17: ='BDO Prequal'!H60 -> 373817 | E17: ='BDO Prequal'!I60 -> 8000 | F17: ='BDO Prequal'!J60 -> 800 | G17: ='BDO Prequal'!K60 -> 381817 | I17: =B17 -> Interim Interest Reserve | J17: =C17 -> 8000 | K17: =D17 -> 373817 | L17: =G17 -> 381817 | N17: =B17 -> Interim Interest Reserve | O17: =C17 -> 8000 | P17: =D17 -> 373817 | Q17: =E17 -> 8000 | R17: =G17 -> 381817 | T17: =B17 -> Interim Interest Reserve | U17: =C17 -> 8000 | V17: =D17 -> 373817 | W17: =F17 -> 800 | X17: =G17 -> 381817
... B21: ='BDO Prequal'!B64 -> SBA Gty Fee | C21: ='BDO Prequal'!C64 -> 5050 | D21: ='BDO Prequal'!H64 -> -5050 | E21: ='BDO Prequal'!I64 -> 0 | F21: ='BDO Prequal'!J64 -> 0 | G21: ='BDO Prequal'!K64 -> 0 | I21: =B21 -> SBA Gty Fee | J21: =C21 -> 5050 | K21: =D21 -> -5050 | L21: =G21 -> 0 | N21: =B21 -> SBA Gty Fee | O21: =C21 -> 5050 | P21: =D21 -> -5050 | Q21: =E21 -> 0 | R21: =G21 -> 0 | T21: =B21 -> SBA Gty Fee | U21: =C21 -> 5050 | V21: =D21 -> -5050 | W21: =F21 -> 0 | X21: =G21 -> 0
B22: Project Total | C22: ='BDO Prequal'!C65 -> -115502 | D22: ='BDO Prequal'!H65 -> 1336917 | E22: ='BDO Prequal'!I65 -> 257182 | F22: ='BDO Prequal'!J65 -> 214570 | G22: ='BDO Prequal'!K65 -> 1684367 | I22: =B22 -> Project Total | J22: =C22 -> -115502 | K22: =D22 -> 1336917 | L22: =G22 -> 1684367 | N22: =B22 -> Project Total | O22: =C22 -> -115502 | P22: =D22 -> 1336917 | Q22: =E22 -> 257182 | R22: =G22 -> 1684367 | T22: =B22 -> Project Total | U22: =C22 -> -115502 | V22: =D22 -> 1336917 | W22: =F22 -> 214570 | X22: =G22 -> 1684367
B23: Percentages | C23: ='BDO Prequal'!C66 -> -0.068572942 | D23: ='BDO Prequal'!H66 -> 0.79372073 | E23: ='BDO Prequal'!I66 -> 0.15268763 | F23: ='BDO Prequal'!J66 -> 0.1273891 | G23: ='BDO Prequal'!K66 -> 1 | I23: =B23 -> Percentages | J23: =C23 -> -0.068572942 | K23: =D23 -> 0.79372073 | L23: =G23 -> 1 | N23: =B23 -> Percentages | O23: =C23 -> -0.068572942 | P23: =D23 -> 0.79372073 | Q23: =E23 -> 0.15268763 | R23: =G23 -> 1 | T23: =B23 -> Percentages | U23: =C23 -> -0.068572942 | V23: =D23 -> 0.79372073 | W23: =F23 -> 0.1273891 | X23: =G23 -> 1
B26: Closing & 3rd Party Costs
B27: (Estimated)
B28: ='BDO Prequal'!S30 -> Loan Packaging Fee | C28: ='BDO Prequal'!T30 -> 2500 | D28: ='BDO Prequal'!U30 -> 1 | E28: ='BDO Prequal'!V30 -> 2500
B29: ='BDO Prequal'!Q31 -> Title Insurance | C29: ='BDO Prequal'!R31 -> 0 | D29: ='BDO Prequal'!S31 -> 0 | E29: ='BDO Prequal'!T31 -> 0
B30: ='BDO Prequal'!Q32 -> Real Estate Tax Fee | C30: ='BDO Prequal'!R32 -> 0 | D30: ='BDO Prequal'!S32 -> 0 | E30: ='BDO Prequal'!T32 -> 0
B31: ='BDO Prequal'!Q33 -> Survey Charges | C31: ='BDO Prequal'!R33 -> 3000 | D31: ='BDO Prequal'!S33 -> 0 | E31: ='BDO Prequal'!T33 -> 0
B32: ='BDO Prequal'!Q34 -> CRE Appraisal | C32: ='BDO Prequal'!R34 -> 3500 | D32: ='BDO Prequal'!S34 -> 0 | E32: ='BDO Prequal'!T34 -> 0
B33: ='BDO Prequal'!Q35 -> Equipment Appraisal | C33: ='BDO Prequal'!R35 -> 0 | D33: ='BDO Prequal'!S35 -> 0 | E33: ='BDO Prequal'!T35 -> 0
B34: ='BDO Prequal'!Q36 -> Appraisal Review | C34: ='BDO Prequal'!R36 -> 0 | D34: ='BDO Prequal'!S36 -> 0 | E34: ='BDO Prequal'!T36 -> 0
B35: ='BDO Prequal'!Q37 -> Site Visit | C35: ='BDO Prequal'!R37 -> 350 | D35: ='BDO Prequal'!S37 -> 0 | E35: ='BDO Prequal'!T37 -> 0
B36: ='BDO Prequal'!Q38 -> Environmental Investigation | C36: ='BDO Prequal'!R38 -> 2500 | D36: ='BDO Prequal'!S38 -> 0 | E36: ='BDO Prequal'!T38 -> 0
B37: ='BDO Prequal'!Q39 -> Business Valuation | C37: ='BDO Prequal'!R39 -> 2500 | D37: ='BDO Prequal'!S39 -> 0 | E37: ='BDO Prequal'!T39 -> 0
B38: ='BDO Prequal'!Q40 -> Residential Appr / Valuation | C38: ='BDO Prequal'!R40 -> 0 | D38: ='BDO Prequal'!S40 -> 0 | E38: ='BDO Prequal'!T40 -> 0
B39: ='BDO Prequal'!Q41 -> Attorney Doc Prep | C39: ='BDO Prequal'!R41 -> 6000 | D39: ='BDO Prequal'!S41 -> 1 | E39: ='BDO Prequal'!T41 -> 6000
B40: ='BDO Prequal'!Q42 -> Interim Loan Fee / Origination | C40: ='BDO Prequal'!R42 -> 0 | D40: ='BDO Prequal'!S42 -> 1 | E40: ='BDO Prequal'!T42 -> 0
... B42: ='BDO Prequal'!Q44 -> Rounding | C42: ='BDO Prequal'!R44 -> 700 | D42: ='BDO Prequal'!S44 -> 1 | E42: ='BDO Prequal'!T44 -> 700
B43: ='BDO Prequal'!Q45 -> Other: UCCs and Misc Closing | C43: ='BDO Prequal'!T45 -> 800 | D43: 1 | E43: ='BDO Prequal'!T45 -> 800
B44: Total Estimated Closing Costs | E44: ='BDO Prequal'!T46 -> 0
B47: Structure Table
C49: ='BDO Prequal'!C31 -> T Bank Loan | D49: ='BDO Prequal'!I31 -> Seller Note | E49: ='BDO Prequal'!J31 -> 3rd Party
B50: Loan Amount | C50: ='BDO Prequal'!C33 -> 1000 | D50: ='BDO Prequal'!I33 -> 7 | E50: ='BDO Prequal'!J33 -> 8
B51: ='BDO Prequal'!B34 -> Base Rate | C51: ='BDO Prequal'!C34 -> 0.075 | D51: ='BDO Prequal'!I34 -> 0.08 | E51: ='BDO Prequal'!J34 -> 0.0624
B52: ='BDO Prequal'!B35 -> Spread | C52: ='BDO Prequal'!C35 -> 0.015 | D52: ='BDO Prequal'!I35 -> 0 | E52: ='BDO Prequal'!J35 -> 0
...

Sheet 504-Hybrid
B3: Loan Terms | J3: Total Project | K3: =SUM(K4:K6) -> 1 | L3: =O36 -> 0 | M3: (difference) | R3: Closing Costs | S3: Cost | T3: Quantity | U3: Total
J4: Bank Loan % | K4: 0.5 | L4: =L3*K4 -> 0 | M4: =K36-L4 -> 0 | R4: Loan Packaging Fee | S4: 2500 | T4: 0 | U4: =S4*T4 -> 0
C5: T Bank 7(a) | D5: Borrower | E5: Seller Note | F5: T Bank 504 | G5: CDC 504 | J5: CDC Loan % | K5: 0.4 | L5: =L3*K5 -> 0 | M5: =N36-L5 -> 0 | R5: Title Insurance | S5: 0 | T5: 0 | U5: =S5*T5 -> 0
B6: Base Rate | C6: 0.075 | E6: 0.08 | F6: 0.075 | G6: 0.0624 | J6: Borrower % | K6: 0.1 | L6: =L3*K6 -> 0 | M6: =L36-L6 -> 0 | R6: Real Estate Tax Fee | S6: 0 | T6: 0 | U6: =S6*T6 -> 0
B7: Spread | C7: 0.015 | E7: 0 | F7: 0.015 | G7: 0 | R7: Survey Charges | S7: 0 | T7: 0 | U7: =S7*T7 -> 0
B8: Indicative Rate | C8: =C6+C7 -> 0.09 | E8: =E6+E7 -> 0.08 | F8: =F6+F7 -> 0.09 | G8: =G6+G7 -> 0.0624 | J8: Bank Interim Loan Fee % | K8: 0.025 | L8: =L4*K8 -> 0 | M8: Blended Rate | N8: =(K36*F8+N36*G8)/SUM(K36+N36) -> #DIV/0! | R8: CRE Appraisal | S8: 3500 | T8: 0 | U8: =S8*T8 -> 0
B9: Amortization Basis | C9: Actual/365 | F9: Actual/365 | J9: SBA TPL Fee % | K9: 0.005 | L9: =L4*K9 -> 0 | R9: Equipment Appraisal | S9: 7500 | T9: 0 | U9: =S9*T9 -> 0
B10: Term (years) | C10: 10 | E10: 10 | F10: 10 | G10: 25 | J10: Referral Fee % | K10: 0 | L10: =K10*L4 -> 0 | M10: Interim Loan | N10: =K36+N36 -> 0 | R10: Appraisal Review | S10: 0 | T10: 0 | U10: =S10*T10 -> 0
B11: Amortization (mos) | C11: =C10*12 -> 120 | E11: =E10*12 -> 120 | F11: =F10*12 -> 120 | G11: =G10*12 -> 300 | J11: Participant Fee % | K11: 0 | L11: =K11*L4 -> 0 | M11: Rounded Fee | N11: =ROUNDUP(L12,-3) -> 0 | R11: Site Visit | S11: 350 | T11: 0 | U11: =S11*T11 -> 0
B12: Est Const Period (mths) | C12: 0 | J12: Origination Fee Total | K12: =SUM(K8:K11) -> 0.03 | L12: =SUM(L8:L11) -> 0 | M12: Fee % to Interim | N12: =N11/N10 -> #DIV/0! | R12: Environmental Investigation | S12: 2500 | T12: 0 | U12: =S12*T12 -> 0
J13: 504 Loan Project | R13: Business Valuation | S13: 2500 | T13: 0 | U13: =S13*T13 -> 0
R14: Residential Appr/Valuation | S14: 0 | T14: 0 | U14: =S14*T14 -> 0
R15: Attorney Doc Prep | S15: 8000 | T15: 0 | U15: =S15*T15 -> 0
B16: Sources and Uses of Proceeds - 7(a) | J16: Sources and Uses of Proceeds - 504 | R16: Interim Loan Fee / Origination | S16: 64000 | T16: 0 | U16: =S16*T16 -> 0
R17: SBA TPL Fee | S17: 13000 | T17: 0 | U17: =S17*T17 -> 0
C18: =C5 -> T Bank 7(a) | D18: =D5 -> Borrower | E18: =E5 -> Seller Note | F18: =G5 -> CDC 504 | G18: Total | K18: T Bank 504 | L18: =D5 -> Borrower | M18: =E5 -> Seller Note | N18: =G5 -> CDC 504 | O18: Total | R18: Rounding | S18: 300 | T18: 0 | U18: =S18*T18 -> 0
B19: Direct Project Costs | J19: Direct Project Costs | R19: Other: UCCs and Misc Closing | U19: =U32 -> 0
B20: Real Estate Acquisition | C20: =G20-SUM(D20:F20) -> 0 | D20: 0 | E20: 0 | F20: 0 | G20: 0 | J20: Real Estate Acquisition | K20: =O20-SUM(L20:N20) -> 0 | L20: 0 | M20: 0 | N20: 0 | O20: 0 | R20: Total Estimated Closing Costs | U20: =SUM(U4:U19) -> 0
B21: Debt Refi - CRE | C21: =G21-SUM(D21:F21) -> 0 | D21: 0 | E21: 0 | F21: 0 | G21: 0 | J21: Debt Refi - CRE | K21: =O21-SUM(L21:N21) -> 0 | L21: 0 | M21: 0 | N21: 0 | O21: 0
B22: Debt Refi - Non-CRE | C22: =G22-SUM(D22:F22) -> 0 | D22: 0 | E22: 0 | F22: 0 | G22: 0 | J22: Debt Refi - Non-CRE | K22: =O22-SUM(L22:N22) -> 0 | L22: 0 | M22: 0 | N22: 0 | O22: 0 | R22: Miscellaneous Closing Costs | S22: Cost | T22: Quantity | U22: Total
B23: Machinery & Equipment | C23: =G23-SUM(D23:F23) -> 0 | D23: 0 | E23: 0 | F23: 0 | G23: 0 | J23: Machinery & Equipment | K23: =O23-SUM(L23:N23) -> 0 | L23: 0 | M23: 0 | N23: 0 | O23: 0 | R23: Business Credit Report | S23: 35 | T23: 0 | U23: =S23*T23 -> 0
B24: Furniture & Fixtures (TIs) | C24: =G24-SUM(D24:F24) -> 0 | D24: 0 | E24: 0 | F24: 0 | G24: 0 | J24: Furniture & Fixtures (TIs) | K24: =O24-SUM(L24:N24) -> 0 | L24: 0 | M24: 0 | N24: 0 | O24: 0 | R24: Personal Credit Report | S24: 25 | T24: 0 | U24: =S24*T24 -> 0
B25: Inventory | C25: =G25-SUM(D25:F25) -> 0 | D25: 0 | E25: 0 | F25: 0 | G25: 0 | J25: Inventory | K25: =O25-SUM(L25:N25) -> 0 | L25: 0 | M25: 0 | N25: 0 | O25: 0 | R25: IRS Transcript Service | S25: 65 | T25: 0 | U25: =S25*T25 -> 0
B26: Working Capital | C26: =G26-SUM(D26:F26) -> 0 | D26: 0 | E26: 0 | F26: 0 | G26: 0 | J26: Working Capital | K26: =O26-SUM(L26:N26) -> 0 | L26: 0 | M26: 0 | N26: 0 | O26: 0 | R26: UCC Searches | S26: 300 | T26: 0 | U26: =S26*T26 -> 0
B27: Working Capital - Pre Opening | C27: =G27-SUM(D27:F27) -> 0 | D27: 0 | E27: 0 | F27: 0 | G27: 0 | J27: Working Capital - Pre Opening | K27: =O27-SUM(L27:N27) -> 0 | L27: 0 | M27: 0 | N27: 0 | O27: 0 | R27: Certificate of Good Standing | S27: 20 | T27: 0 | U27: =S27*T27 -> 0
B28: Business Acquisition | C28: =G28-SUM(D28:F28) -> 0 | D28: 0 | E28: 0 | F28: 0 | G28: 0 | J28: Business Acquisition | K28: =O28-SUM(L28:N28) -> 0 | L28: 0 | M28: 0 | N28: 0 | O28: 0 | R28: Flood Certification | S28: 18 | T28: 0 | U28: =S28*T28 -> 0
B29: Franchise Fees | C29: =G29-SUM(D29:F29) -> 0 | D29: 0 | E29: 0 | F29: 0 | G29: 0 | J29: Franchise Fees | K29: =O29-SUM(L29:N29) -> 0 | L29: 0 | M29: 0 | N29: 0 | O29: 0 | R29: Filing & Recording Fees | S29: 100 | T29: 0 | U29: =S29*T29 -> 0
B30: Construction Hard Costs | C30: =G30-SUM(D30:F30) -> 0 | D30: 0 | E30: 0 | F30: 0 | G30: 0 | J30: Construction Hard Costs | K30: =O30-SUM(L30:N30) -> 0 | L30: 0 | M30: 0 | N30: 0 | O30: 0 | R30: FedEx Charges | S30: 50 | T30: 0 | U30: =S30*T30 -> 0
B31: Interim Interest Reserve | C31: 0 | D31: =G31-C31 -> 0 | E31: 0 | F31: 0 | G31: =ROUND(((C20+F20)*C8/12)*C12+((C36-C20+F36-F20)*C8*0.6/12)*C12,0) -> 0 | H31: Const Contigency | J31: Interim Interest Reserve | K31: 0 | L31: =O31-K31 -> 0 | M31: 0 | N31: 0 | O31: 0 | P31: Const Contigency | R31: Other: rounding | S31: 77 | T31: 0 | U31: =S31*T31 -> 0
B32: Construction Contingency | C32: =G32-D32-E32-F32 -> 0 | D32: 0 | E32: 0 | F32: 0 | G32: =ROUND(G30*H32,0) -> 0 | H32: 0.1 | J32: Construction Contingency | K32: =O32-L32-M32-N32 -> 0 | L32: 0 | M32: 0 | N32: 0 | O32: =ROUND(O30*P32,0) -> 0 | P32: 0.1 | R32: Total Misc. Closing Costs | U32: =SUM(U23:U31) -> 0
B33: Other Construction Soft Costs | C33: =G33-SUM(D33:F33) -> 0 | D33: 0 | E33: 0 | F33: 0 | G33: 0 | J33: Other Construction Soft Costs | K33: =O33-SUM(L33:N33) -> 0 | L33: 0 | M33: 0 | N33: 0 | O33: 0
B34: Closing Costs | C34: =G34-SUM(D34:F34) -> 0 | D34: 0 | E34: 0 | F34: 0 | G34: 0 | J34: Closing Costs | K34: =O34-SUM(L34:N34) -> 0 | L34: 0 | M34: 0 | N34: 0 | O34: 0
B35: SBA Gty Fee | C35: 0 | D35: =G35-C35 -> 0 | G35: 0 | J35: SBA Gty Fee | K35: 0 | L35: =O35-K35 -> 0 | O35: 0
C36: =SUM(C20:C35) -> 0 | D36: =SUM(D20:D35) -> 0 | E36: =SUM(E20:E35) -> 0 | F36: =SUM(F20:F35) -> 0 | G36: =SUM(G20:G35) -> 0 | K36: =SUM(K20:K35) -> 0 | L36: =SUM(L20:L35) -> 0 | M36: =SUM(M20:M35) -> 0 | N36: =SUM(N20:N35) -> 0 | O36: =SUM(O20:O35) -> 0
C37: =IFERROR(C36/$G$36,0) -> 0 | D37: =IFERROR(D36/$G$36,0) -> 0 | E37: =IFERROR(E36/$G$36,0) -> 0 | F37: =IFERROR(F36/$G$36,0) -> 0 | G37: =IFERROR(G36/$G$36,0) -> 0 | K37: =IFERROR(K36/$O$36,0) -> 0 | L37: =IFERROR(L36/$O$36,0) -> 0 | M37: =IFERROR(M36/$O$36,0) -> 0 | N37: =IFERROR(N36/$O$36,0) -> 0 | O37: =IFERROR(O36/$O$36,0) -> 0
C41: =C18 -> T Bank 7(a) | D41: =D18 -> Borrower | E41: =E18 -> Seller Note | F41: =G18 -> Total | K41: =K18 -> T Bank 504 | L41: =L18 -> Borrower | M41: =M18 -> Seller Note | N41: =N18 -> CDC 504 | O41: =O18 -> Total
B42: =B20 -> Real Estate Acquisition | C42: =C20 -> 0 | D42: =D20 -> 0 | E42: =E20 -> 0 | F42: =G20 -> 0 | J42: =J20 -> Real Estate Acquisition | K42: =K20 -> 0 | L42: =L20 -> 0 | M42: =M20 -> 0 | N42: =N20 -> 0 | O42: =O20 -> 0
B43: =B21 -> Debt Refi - CRE | C43: =C21 -> 0 | D43: =D21 -> 0 | E43: =E21 -> 0 | F43: =G21 -> 0 | J43: =J21 -> Debt Refi - CRE | K43: =K21 -> 0 | L43: =L21 -> 0 | M43: =M21 -> 0 | N43: =N21 -> 0 | O43: =O21 -> 0
B44: =B22 -> Debt Refi - Non-CRE | C44: =C22 -> 0 | D44: =D22 -> 0 | E44: =E22 -> 0 | F44: =G22 -> 0 | J44: =J22 -> Debt Refi - Non-CRE | K44: =K22 -> 0 | L44: =L22 -> 0 | M44: =M22 -> 0 | N44: =N22 -> 0 | O44: =O22 -> 0
B45: =B23 -> Machinery & Equipment | C45: =C23 -> 0 | D45: =D23 -> 0 | E45: =E23 -> 0 | F45: =G23 -> 0 | J45: =J23 -> Machinery & Equipment | K45: =K23 -> 0 | L45: =L23 -> 0 | M45: =M23 -> 0 | N45: =N23 -> 0 | O45: =O23 -> 0
...

Sheet Lists
A1: Version | B1: Loan Type | C1: Basics | D1: Request | E1: UW | F1: BDO
A3: Original | B3: N/A | C3: Yes | D3: New | E3: Andrew Taylor | F3: Audrey Wendel
A4: Mod 1 | B4: SBA 7a | C4: No | D4: Renewal | E4: Antony Parker | F4: Ben Eakin
A5: Mod 2 | B5: SBA Express | C5: N/A | D5: Modification | E5: Brent Ruch | F5: Cameron Brewer
A6: Mod 3 | B6: 504 | E6: Jennifer Dennis | F6: Eric Wadley
A7: Mod 4 | B7: USDA | C7: Disbursement | E7: Jessica Gauden | F7: Glenn Giro
A8: Mod 5 | B8: P&E | E8: Rodney Johnson | F8: Greg Swett
A9: Mod 6 | B9: Conventional | C9: Multi | E9: Rose Haynes-Taylor | F9: Jordan Sayler
A10: Mod 7 | C10: Single | D10: True/False | E10: Connor Shaw | F10: Kandace Moon
A11: Mod 8 | E11: Sheila Simms | F11: Kerry Smith
A12: Mod 9 | D12: True | F12: Kevin Coffman
A13: Mod 10 | D13: False | F13: Mike Ramsay
F14: Patrick Phillips
A15: Entity Types | B15: Loan Program | C15: Risk Rating | D15: Statement Type | E15: Revenue Recognition | F15: Rick McMann
F16: Rod Rodriguez
A17: TBD | B17: N/A | C17: 1 | D17: Tax Returns | E17: Cash | F17: Steve Jones
A18: Sole Prop | B18: PLP | C18: 2 | D18: Audited | E18: Accrual
A19: LLC | B19: GP | C19: 3 | D19: Reviewed | E19: Hybrid
A20: S-Corp | B20: 504 | C20: 4 | D20: Compiled | E20: Other
A21: C-Corp | B21: USDA | C21: 5 | D21: Schedule C | F21: Proforma BS
A22: Prof Corp | C22: 5.5 | D22: Internal
A23: Prof LLC | C23: 6 | D23: Form 10K | F23: New BS
A24: Trust | C24: 7 | D24: Form 10Q | F24: Last Year End
A25: LTD Partnership | C25: 8 | D25: Other | F25: Interim
A26: Partnership | C26: 9
F28: Submission
A29: Rate Adjustment | B29: Lien Position | D29: Property Type | E29: Valuation Method
C30: UCC Lien Type | F30: PLP
A31: Daily | B31: First | D31: C-Store | E31: Cost | F31: Standard
A32: Monthly | B32: Second | C32: Purchase Money UCC | D32: Hotel | E32: Appraisal
A33: Calendar Qtr | B33: Third | C33: Blanket UCC | D33: Industrial | E33: Book Value
A34: Other | B34: Fourth | C34: Security Interest | D34: Medical Office | E34: BPO
B35: Best Available | D35: Mixed-Use | E35: Invoice
D36: Mobile Home Park | E36: Estimated | F36: Construction Type
D37: Multi Family | E37: Tax
A38: Entity Class | B38: PFS RE Type | D38: Office | E38: Other | F38: Wood Frame
D39: Office/Warehouse | E39: Roof Type | F39: Steel Frame
A40: Holding Company/EPC | B40: Single Family | D40: Residential | F40: Concrete Frame
A41: Operating Company | B41: Multi Family | D41: Restaurant | E41: Flat - Built Up | F41: Concrete Tilt Up
A42: Affiliate | B42: Commercial | D42: Retail | E42: Flat - Membrane | F42: Concrete Wall
...
