Workbook
Name Beg_Bal: #REF!
Name Beg_Bal: #REF!
Name Cum_Int: #REF!
Name Data: #REF!
Name DisbursementType: #REF!
Name DisbursementType: #REF!
Name End_Bal: #REF!
Name End_Bal: #REF!
Name EXPENSES: #REF!
Name EXPENSES: #REF!
Name Extra_Pay: #REF!
Name Extra_Pay: #REF!
Name Full_Print: #REF!
Name Full_Print: #REF!
Name Header_Row: ROW(#REF!)
Name Header_Row: ROW(#REF!)
Name Int: #REF!
Name Int: #REF!
Name Interest_Rate: #REF!
Name Interest_Rate: #REF!
Name Last_Row: IF('504-Hybrid'!Values_Entered,Header_Row+'504-Hybrid'!Number_of_Payments,Header_Row)
Name Last_Row: IF(Scores!Values_Entered,Scores!Header_Row+Scores!Number_of_Payments,Scores!Header_Row)
Name Last_Row: IF(Values_Entered,Header_Row+Number_of_Payments,Header_Row)
Name Loan_Amount: #REF!
Name Loan_Amount: #REF!
Name Loan_Start: #REF!
Name Loan_Start: #REF!
Name Loan_Years: #REF!
Name Loan_Years: #REF!
Name MajorExpensesList: #REF!
Name MajorExpensesList: #REF!
Name Num_Pmt_Per_Year: #REF!
Name Num_Pmt_Per_Year: #REF!
Name Number_of_Payments: MATCH(0.01,End_Bal,-1)+1
Name Number_of_Payments: MATCH(0.01,Scores!End_Bal,-1)+1
Name Number_of_Payments: MATCH(0.01,End_Bal,-1)+1
Name Pay_Date: #REF!
Name Pay_Num: #REF!
Name Pay_Num: #REF!
Name Payment_Date: DATE(YEAR(Scores!Loan_Start),MONTH(Scores!Loan_Start)+Payment_Number,DAY(Scores!Loan_Start))
Name Payment_Date: DATE(YEAR(Loan_Start),MONTH(Loan_Start)+Payment_Number,DAY(Loan_Start))
Name Periodic_rate: Annual_interest_rate/Payments_per_year
Name Periodic_rate: Annual_interest_rate/Payments_per_year
Name Periodic_rate: Annual_interest_rate/Payments_per_year
Name Princ: #REF!
Name Princ: #REF!
Name Print_Area_Reset: OFFSET(Full_Print,0,0,[0]!Last_Row)
Name Print_Area_Reset: OFFSET(Scores!Full_Print,0,0,Scores!Last_Row)
Name Print_Area_Reset: OFFSET(Full_Print,0,0,Last_Row)
Name Sched_Pay: #REF!
Name Sched_Pay: #REF!
Name Scheduled_Extra_Payments: #REF!
Name Scheduled_Extra_Payments: #REF!
Name Scheduled_Interest_Rate: #REF!
Name Scheduled_Monthly_Payment: #REF!
Name Scheduled_Monthly_Payment: #REF!
Name Total_Interest: #REF!
Name Total_Pay: #REF!
Name Total_Pay: #REF!
Name Total_Payment: Scheduled_Payment+Extra_Payment

Sheet BDO Prequal
B2: BDO Prequalification | U2: Closing Cost Calculator ---> Expand/Collapse Above ---> | AD2: Loan Term Calculator ---> Expand/Collapse Above ---> | AN2: 507 / 7(a) Hybrid Planning ---> Expand/Collapse Above --->
AF6: 504 - Project | AG6: %'s | AH6: Difference
B7: Project | AF7: T Bank Loan | AG7: =P46 -> 0.5 | AH7: =Q46 -> -2886462.5
AF8: CDC Debenture | AG8: =P47 -> 0.3 | AH8: =Q47 -> -669942.5
B9: Business Name: | AF9: Borrower Equity | AG9: =P48 -> 0.2 | AH9: =Q48 -> -122793
I10: BDO: | AF10: Total | AG10: =SUM(AG7:AG9) -> 1 | AH10: =AG55 -> 3541935
I11: Cooperating BDO:
AG13: =C36 -> Total | AH13: =D36 -> Equity | AI13: =Lists!L4 -> SBA 7(a) | AJ13: =Lists!L9 -> Seller Note
B14: Loan Terms | N14: Closing Costs | O14: Cost | P14: Quantity | Q14: Total | AF14: SBA 7(a) Project
E15: 1 | F15: 2 | G15: 3 | H15: 4 | I15: 5 | J15: 6 | K15: 7 | L15: TOTAL | N15: Title Insurance | O15: 0 | P15: 0 | Q15: =O15*P15 -> 0 | R15: 0.5%-1% of CRE value (FL & NY +) | AF15: =B38 -> Real Estate Acquisition | AG15: =SUM(AH15:AJ15) -> 0 | AH15: 0 | AI15: =IFERROR(INDEX($C38:$K38,MATCH(AI$13,$C$36:$K$36,0)),0) -> 0 | AJ15: =IFERROR(INDEX($C38:$K38,MATCH(AJ$13,$C$36:$K$36,0)),0) -> 0
C16: Party | D16: Borrower | E16: T Bank | F16: T Bank | G16: T Bank | H16: Seller | I16: CDC | J16: N/A | K16: N/A | N16: Real Estate Tax Fee | O16: 0 | P16: 0 | Q16: =O16*P16 -> 0 | R16: $166 for 1st $500M, $10 for every $100M after | AF16: =B39 -> Debt Refi - CRE | AG16: =SUM(AH16:AJ16) -> 0 | AH16: 0 | AI16: =IFERROR(INDEX($C39:$K39,MATCH(AI$13,$C$36:$K$36,0)),0) -> 0 | AJ16: =IFERROR(INDEX($C39:$K39,MATCH(AJ$13,$C$36:$K$36,0)),0) -> 0
C17: Financing Type | D17: Equity | E17: SBA 7(a) | F17: SBA 7(a) | G17: SBA 504 | H17: Seller Note | I17: Debenture | J17: N/A | K17: N/A | N17: Survey Charges | O17: 3000 | P17: 0 | Q17: =O17*P17 -> 0 | R17: $1M - $3M | AF17: =B40 -> Debt Refi - Non-CRE | AG17: =SUM(AH17:AJ17) -> 0 | AH17: 0 | AI17: =IFERROR(INDEX($C40:$K40,MATCH(AI$13,$C$36:$K$36,0)),0) -> 0 | AJ17: =IFERROR(INDEX($C40:$K40,MATCH(AJ$13,$C$36:$K$36,0)),0) -> 0
C18: Loan Amount/Injection | D18: =D55 -> 1571792 | E18: =E55 -> 612591 | F18: =F55 -> 2746607 | G18: =G55 -> 1350000 | H18: =H55 -> 320000 | I18: =I55 -> 1871935 | J18: =J55 -> 0 | K18: =K55 -> 0 | N18: CRE Appraisal | O18: 3500 | P18: 0 | Q18: =O18*P18 -> 0 | R18: $3.5M - $6.0M | AF18: =B41 -> Machinery & Equipment | AG18: =SUM(AH18:AJ18) -> 0 | AH18: 0 | AI18: =IFERROR(INDEX($C41:$K41,MATCH(AI$13,$C$36:$K$36,0)),0) -> 0 | AJ18: =IFERROR(INDEX($C41:$K41,MATCH(AJ$13,$C$36:$K$36,0)),0) -> 0
C19: Base Rate | E19: 0.0675 | F19: 0.0594 | G19: 0.0675 | H19: 0.05 | I19: 0.05 | J19: 0.0675 | K19: 0 | N19: Environmental Investigation | O19: 2500 | P19: 0 | Q19: =O19*P19 -> 0 | R19: $2M | AF19: =B42 -> Furniture & Fixtures | AG19: =SUM(AH19:AJ19) -> 0 | AH19: 0 | AI19: =IFERROR(INDEX($C42:$K42,MATCH(AI$13,$C$36:$K$36,0)),0) -> 0 | AJ19: =IFERROR(INDEX($C42:$K42,MATCH(AJ$13,$C$36:$K$36,0)),0) -> 0
C20: Spread | E20: 0.015 | F20: 0 | G20: 0.0275 | H20: 0 | I20: 0.01 | J20: 0.03 | K20: 0 | N20: Residential Appr / Valuation | O20: 500 | P20: 0 | Q20: =O20*P20 -> 0 | R20: $500 - $700 | AF20: =B43 -> Inventory | AG20: =SUM(AH20:AJ20) -> 0 | AH20: 0 | AI20: =IFERROR(INDEX($C43:$K43,MATCH(AI$13,$C$36:$K$36,0)),0) -> 0 | AJ20: =IFERROR(INDEX($C43:$K43,MATCH(AJ$13,$C$36:$K$36,0)),0) -> 0
C21: Indicative Rate | E21: =E19+E20 -> 0.0825 | F21: =F19+F20 -> 0.0594 | G21: =G19+G20 -> 0.095 | H21: =H19+H20 -> 0.05 | I21: =I19+I20 -> 0.06 | J21: =J19+J20 -> 0.0975 | K21: =K19+K20 -> 0 | N21: Business Valuation | O21: 2500 | P21: 1 | Q21: =O21*P21 -> 2500 | R21: $2.5M - $3M | AF21: =B44 -> Working Capital | AG21: =SUM(AH21:AJ21) -> 0 | AH21: 0 | AI21: =IFERROR(INDEX($C44:$K44,MATCH(AI$13,$C$36:$K$36,0)),0) -> 0 | AJ21: =IFERROR(INDEX($C44:$K44,MATCH(AJ$13,$C$36:$K$36,0)),0) -> 0
C22: Amort Basis - I/O - Standby | E22: Actual/365 | F22: Actual/365 | G22: Actual/365 | H22: Actual/365 | I22: Actual/365 | J22: Actual/365 | K22: Actual/365 | N22: Equipment Appraisal | O22: 0 | P22: 0 | Q22: =O22*P22 -> 0 | R22: $1.5M - $3.5M | AF22: =B45 -> Working Capital - Pre Opening | AG22: =SUM(AH22:AJ22) -> 0 | AH22: 0 | AI22: =IFERROR(INDEX($C45:$K45,MATCH(AI$13,$C$36:$K$36,0)),0) -> 0 | AJ22: =IFERROR(INDEX($C45:$K45,MATCH(AJ$13,$C$36:$K$36,0)),0) -> 0
C23: Term (years) | E23: 10 | F23: 10 | G23: 10 | H23: 7 | I23: 3 | J23: 5 | K23: 0 | N23: Site Visit | O23: 350 | P23: 0 | Q23: =O23*P23 -> 0 | R23: 350 | AF23: =B46 -> Business Acquisition | AG23: =SUM(AH23:AJ23) -> 644000 | AH23: 0 | AI23: =IFERROR(INDEX($C46:$K46,MATCH(AI$13,$C$36:$K$36,0)),0) -> 324000 | AJ23: =IFERROR(INDEX($C46:$K46,MATCH(AJ$13,$C$36:$K$36,0)),0) -> 320000
C24: Amortization (mos) | E24: =E23*12 -> 120 | F24: =F23*12 -> 120 | G24: =G23*12 -> 120 | H24: =H23*12 -> 84 | I24: =I23*12 -> 36 | J24: =J23*12 -> 60 | K24: =K23*12 -> 0 | N24: Construction Monitoring | O24: 0 | P24: 0 | Q24: =O24*P24 -> 0 | R24: See Partner ESI pricing sheet | AF24: =B47 -> Franchise Fees | AG24: =SUM(AH24:AJ24) -> 0 | AH24: 0 | AI24: =IFERROR(INDEX($C47:$K47,MATCH(AI$13,$C$36:$K$36,0)),0) -> 0 | AJ24: =IFERROR(INDEX($C47:$K47,MATCH(AJ$13,$C$36:$K$36,0)),0) -> 0
C25: Estimated Payment | E25: =IFERROR(INDEX(Calculations!$K$4:$K$7,MATCH($E$22,Calculations!$B$4:$B$7,0)),0) -> 7515.7979 | F25: =IFERROR(INDEX(Calculations!$K$10:$K$13,MATCH($F$22,Calculations!$B$10:$B$13,0)),0) -> 30417.001 | G25: =IFERROR(INDEX(Calculations!$K$16:$K$19,MATCH($G$22,Calculations!$B$16:$B$19,0)),0) -> 17474.442 | H25: =IFERROR(INDEX(Calculations!$K$22:$K$25,MATCH($H$22,Calculations!$B$22:$B$25,0)),0) -> 4523.4394 | I25: =IFERROR(INDEX(Calculations!$K$28:$K$31,MATCH($I$22,Calculations!$B$28:$B$31,0)),0) -> 56952.537 | J25: =IFERROR(INDEX(Calculations!$K$34:$K$37,MATCH($J$22,Calculations!$B$34:$B$37,0)),0) -> 0 | K25: =IFERROR(INDEX(Calculations!$K$40:$K$43,MATCH($K$22,Calculations!$B$40:$B$43,0)),0) -> 0 | N25: Loan Packaging Fee | O25: 2500 | P25: 1 | Q25: =O25*P25 -> 2500 | R25: $1.5M - 2.5M | AF25: =B48 -> Construction Hard Costs | AG25: =SUM(AH25:AJ25) -> 0 | AH25: 0 | AI25: =IFERROR(INDEX($C48:$K48,MATCH(AI$13,$C$36:$K$36,0)),0) -> 0 | AJ25: =IFERROR(INDEX($C48:$K48,MATCH(AJ$13,$C$36:$K$36,0)),0) -> 0
C26: SBA 7(a) Guarantee Fee | E26: =IF(E17=Lists!$L$4,Calculations!T7,0) -> 13784 | F26: =IF(F17=Lists!$L$4,Calculations!T13,0) -> 74749 | G26: =IF(G17=Lists!$L$4,Calculations!T19,0) -> 0 | H26: =IF(H17=Lists!$L$4,Calculations!T25,0) -> 0 | I26: =IF(I17=Lists!$L$4,Calculations!T31,0) -> 0 | J26: =IF(J17=Lists!$L$4,Calculations!T37,0) -> 0 | K26: =IF(K17=Lists!$L$4,Calculations!T43,0) -> 0 | N26: Closing Doc Prep | O26: 7000 | P26: 0 | Q26: =O26*P26 -> 0 | R26: $3.5M-$6.0M | AF26: =B49 -> Construction Contingency - 10% | AG26: =SUM(AH26:AJ26) -> 222807 | AH26: 0 | AI26: =IFERROR(INDEX($C49:$K49,MATCH(AI$13,$C$36:$K$36,0)),0) -> 222807 | AJ26: =IFERROR(INDEX($C49:$K49,MATCH(AJ$13,$C$36:$K$36,0)),0) -> 0
C27: USDA Guarantee Fee | E27: =IF(E17=Lists!$L$10,Calculations!Z7,0) -> 0 | F27: =IF(F17=Lists!$L$10,Calculations!Z13,0) -> 0 | G27: =IF(G17=Lists!$L$10,Calculations!Z19,0) -> 0 | H27: =IF(H17=Lists!$L$10,Calculations!Z25,0) -> 0 | I27: =IF(I17=Lists!$L$10,Calculations!Z31,0) -> 0 | J27: =IF(J17=Lists!$L$10,Calculations!Z37,0) -> 0 | K27: =IF(K17=Lists!$L$10,Calculations!Z43,0) -> 0 | N27: Interim Loan Fee / Origination | O27: =Q57-O28 -> 112000 | P27: 1 | Q27: =O27*P27 -> 112000 | R27: 1.0% -2.0% Conv/USDA Loans | AF27: =B50 -> Interest Reserve - 3 Mos | AG27: =SUM(AH27:AJ27) -> 0 | AH27: 0 | AI27: =IFERROR(INDEX($C50:$K50,MATCH(AI$13,$C$36:$K$36,0)),0) -> 0 | AJ27: =IFERROR(INDEX($C50:$K50,MATCH(AJ$13,$C$36:$K$36,0)),0) -> 0
C28: Include Interest Reserve? | E28: No | F28: No | G28: No | H28: No | I28: No | J28: No | K28: No | N28: SBA TPL Fee (Third Party Lender) | O28: 0 | P28: 0 | Q28: =O28*P28 -> 0 | R28: 0.5% of T Bank Perm. Loan (504) | AF28: =B51 -> Construction Soft Costs | AG28: =SUM(AH28:AJ28) -> 0 | AH28: 0 | AI28: =IFERROR(INDEX($C51:$K51,MATCH(AI$13,$C$36:$K$36,0)),0) -> 0 | AJ28: =IFERROR(INDEX($C51:$K51,MATCH(AJ$13,$C$36:$K$36,0)),0) -> 0
N29: Rounding | O29: =Q31-SUM(Q15:Q28)-Q30 -> 200 | P29: 1 | Q29: =O29*P29 -> 200 | AF29: =B52 -> Closing Costs | AG29: =SUM(AH29:AJ29) -> 52000 | AH29: 0 | AI29: =IFERROR(INDEX($C52:$K52,MATCH(AI$13,$C$36:$K$36,0)),0) -> 52000 | AJ29: =IFERROR(INDEX($C52:$K52,MATCH(AJ$13,$C$36:$K$36,0)),0) -> 0
C30: Construction Contingency % | D30: 0.1 | F30: Additional Contingecy $ | G30: 0 | I30: SBA 7a Guarantee % | J30: 0.75 | N30: Other: UCCs and Misc Closing | Q30: =IF('BDO Prequal'!C55=0,0,Q43) -> 800 | AF30: =B53 -> SBA Gty Fee | AG30: =SUM(AH30:AJ30) -> 13784 | AH30: 0 | AI30: =IFERROR(INDEX($C53:$K53,MATCH(AI$13,$C$36:$K$36,0)),0) -> 13784 | AJ30: =IFERROR(INDEX($C53:$K53,MATCH(AJ$13,$C$36:$K$36,0)),0) -> 0
C31: Estimated Construction / Interest Only Period | D31: 3 | F31: Additional Interest Reserve $ | G31: 0 | I31: USDA Guarantee % | J31: 0.8 | N31: Total Estimated Closing Costs | Q31: =ROUNDUP(SUM(Q15,Q16,Q17,Q18,Q19,Q20,Q21,Q22,Q23,Q24,Q25,Q26,Q27,Q28,Q30),-3) -> 118000 | AF31: =B54 -> USDA Gty Fee | AG31: =SUM(AH31:AJ31) -> 0 | AH31: 0 | AI31: =IFERROR(INDEX($C54:$K54,MATCH(AI$13,$C$36:$K$36,0)),0) -> 0 | AJ31: =IFERROR(INDEX($C54:$K54,MATCH(AJ$13,$C$36:$K$36,0)),0) -> 0
N32: =IF(C52<>Q31," ***UOP Closing Costs Do Not Match Above - Ensure Cells C52 and Q31 Match if Using Chart***","") -> ***UOP Closing Costs Do Not Match Above - Ensure Cells C52 and Q31 Match if Using Chart*** | AG32: =SUM(AG15:AG31) -> 932591 | AH32: =SUM(AH15:AH31) -> 0 | AI32: =SUM(AH15:AH31) -> 0 | AJ32: =SUM(AJ15:AJ31) -> 320000
N33: Miscellaneous Closing Costs | O33: Cost | P33: Quantity | Q33: Total | AG33: =IFERROR(AG32/$AG$32,0) -> 1 | AH33: =IFERROR(AH32/$AG$32,0) -> 0 | AI33: =IFERROR(AI32/$AG$32,0) -> 0 | AJ33: =IFERROR(AJ32/$AG$32,0) -> 0.34313005
B34: Sources and Uses of Proceeds | N34: Business Credit Report | O34: 35 | P34: 1 | Q34: =O34*P34 -> 35
N35: Personal Credit Report | O35: 25 | P35: 2 | Q35: =O35*P35 -> 50
C36: Total | D36: =D17 -> Equity | E36: =IF(E17=0,"",E17) -> SBA 7(a) | F36: =IF(F17=0,"",F17) -> SBA 7(a) | G36: =IF(G17=0,"",G17) -> SBA 504 | H36: =IF(H17=0,"",H17) -> Seller Note | I36: =IF(I17=0,"",I17) -> Debenture | J36: =IF(J17=0,"",J17) -> N/A | K36: =IF(K17=0,"",K17) -> N/A | N36: IRS Transcript Service | O36: 65 | P36: 2 | Q36: =O36*P36 -> 130 | W36: Loan Considered | X36: 1 | Z36: Product | AA36: =IF(X36=E15,E36,IF(X36=F15,F36,IF(X36=G15,G36,IF(X36=H15,H36,IF(X36=I15,I36,IF(X36=J15,J36,IF(X36=K15,K36,L15))))))) -> SBA 7(a) | AG36: =C36 -> Total | AH36: =D36 -> Equity | AI36: =Lists!L5 -> SBA 504 | AJ36: =Lists!L6 -> Debenture | AK36: =Lists!L9 -> Seller Note
B37: Direct Project Costs | N37: UCC Searches | O37: 300 | P37: 1 | Q37: =O37*P37 -> 300 | AF37: SBA 504 Project
B38: Real Estate Acquisition | C38: =SUM(D38:K38) -> 0 | E38: 0 | F38: 0 | G38: 0 | H38: 0 | I38: 0 | J38: 0 | K38: 0 | N38: Certificate of Good Standing | O38: 20 | P38: 1 | Q38: =O38*P38 -> 20 | Y38: Term (yrs) | Z38: % | AA38: Wgt | AF38: =B38 -> Real Estate Acquisition | AG38: =SUM(AH38:AK38) -> 0 | AH38: 0 | AI38: =IFERROR(INDEX($C38:$K38,MATCH(AI$36,$C$36:$K$36,0)),0) -> 0 | AJ38: =IFERROR(INDEX($C38:$K38,MATCH(AJ$36,$C$36:$K$36,0)),0) -> 0 | AK38: =IFERROR(INDEX($C38:$K38,MATCH(AK$36,$C$36:$K$36,0)),0) -> 0
B39: Debt Refi - CRE | C39: =SUM(D39:K39) -> 0 | D39: 0 | E39: 0 | F39: 0 | G39: 0 | H39: 0 | I39: 0 | J39: 0 | K39: 0 | N39: Flood Certification | O39: 18 | P39: 1 | Q39: =O39*P39 -> 18 | W39: =B38 -> Real Estate Acquisition | X39: =IF($X$36=$E$15,E38,IF($X$36=$F$15,F38,IF($X$36=$G$15,G38,IF($X$36=$H$15,H38,IF($X$36=$I$15,I38,IF($X$36=$J$15,J38,IF($X$36=$K$15,K38,IF($X$36=$L$15,C38,C38)))))))) -> 0 | Y39: 25 | Z39: =IF($X$53=0,0,X39/$X$53) -> 0 | AA39: =Y39*Z39 -> 0 | AF39: =B39 -> Debt Refi - CRE | AG39: =SUM(AH39:AK39) -> 0 | AH39: 0 | AI39: =IFERROR(INDEX($C39:$K39,MATCH(AI$36,$C$36:$K$36,0)),0) -> 0 | AJ39: =IFERROR(INDEX($C39:$K39,MATCH(AJ$36,$C$36:$K$36,0)),0) -> 0 | AK39: =IFERROR(INDEX($C39:$K39,MATCH(AK$36,$C$36:$K$36,0)),0) -> 0
B40: Debt Refi - Non-CRE | C40: =SUM(D40:K40) -> 0 | D40: 0 | E40: 0 | F40: 0 | G40: 0 | H40: 0 | I40: 0 | J40: 0 | K40: 0 | N40: Filing & Recording Fees | O40: 100 | P40: 1 | Q40: =O40*P40 -> 100 | R40: avg $100 | W40: =B39 -> Debt Refi - CRE | X40: =IF($X$36=$E$15,E39,IF($X$36=$F$15,F39,IF($X$36=$G$15,G39,IF($X$36=$H$15,H39,IF($X$36=$I$15,I39,IF($X$36=$J$15,J39,IF($X$36=$K$15,K39,IF($X$36=$L$15,C39,C39)))))))) -> 0 | Y40: 25 | Z40: =IF($X$53=0,0,X40/$X$53) -> 0 | AA40: =Y40*Z40 -> 0 | AF40: =B40 -> Debt Refi - Non-CRE | AG40: =SUM(AH40:AK40) -> 0 | AH40: 0 | AI40: =IFERROR(INDEX($C40:$K40,MATCH(AI$36,$C$36:$K$36,0)),0) -> 0 | AJ40: =IFERROR(INDEX($C40:$K40,MATCH(AJ$36,$C$36:$K$36,0)),0) -> 0 | AK40: =IFERROR(INDEX($C40:$K40,MATCH(AK$36,$C$36:$K$36,0)),0) -> 0
B41: Machinery & Equipment | C41: =SUM(D41:K41) -> 366285 | D41: 366285 | E41: 0 | F41: 0 | G41: 0 | H41: 0 | I41: 0 | J41: 0 | K41: 0 | N41: FedEx Charges | O41: 50 | P41: 1 | Q41: =O41*P41 -> 50 | R41: avg $50 | W41: =B40 -> Debt Refi - Non-CRE | X41: =IF($X$36=$E$15,E40,IF($X$36=$F$15,F40,IF($X$36=$G$15,G40,IF($X$36=$H$15,H40,IF($X$36=$I$15,I40,IF($X$36=$J$15,J40,IF($X$36=$K$15,K40,IF($X$36=$L$15,C40,C40)))))))) -> 0 | Y41: 10 | Z41: =IF($X$53=0,0,X41/$X$53) -> 0 | AA41: =Y41*Z41 -> 0 | AF41: =B41 -> Machinery & Equipment | AG41: =SUM(AH41:AK41) -> 0 | AH41: 0 | AI41: =IFERROR(INDEX($C41:$K41,MATCH(AI$36,$C$36:$K$36,0)),0) -> 0 | AJ41: =IFERROR(INDEX($C41:$K41,MATCH(AJ$36,$C$36:$K$36,0)),0) -> 0 | AK41: =IFERROR(INDEX($C41:$K41,MATCH(AK$36,$C$36:$K$36,0)),0) -> 0
B42: Furniture & Fixtures | C42: =SUM(D42:K42) -> 600000 | D42: 0 | E42: 0 | F42: 600000 | G42: 0 | H42: 0 | I42: 0 | J42: 0 | K42: 0 | N42: Other: rounding | O42: =Q43-SUM(Q34:Q41) -> 97 | P42: 1 | Q42: =O42*P42 -> 97 | W42: =B41 -> Machinery & Equipment | X42: =IF($X$36=$E$15,E41,IF($X$36=$F$15,F41,IF($X$36=$G$15,G41,IF($X$36=$H$15,H41,IF($X$36=$I$15,I41,IF($X$36=$J$15,J41,IF($X$36=$K$15,K41,IF($X$36=$L$15,C41,C41)))))))) -> 0 | Y42: 10 | Z42: =IF($X$53=0,0,X42/$X$53) -> 0 | AA42: =Y42*Z42 -> 0 | AF42: =B42 -> Furniture & Fixtures | AG42: =SUM(AH42:AK42) -> 0 | AH42: 0 | AI42: =IFERROR(INDEX($C42:$K42,MATCH(AI$36,$C$36:$K$36,0)),0) -> 0 | AJ42: =IFERROR(INDEX($C42:$K42,MATCH(AJ$36,$C$36:$K$36,0)),0) -> 0 | AK42: =IFERROR(INDEX($C42:$K42,MATCH(AK$36,$C$36:$K$36,0)),0) -> 0
B43: Inventory | C43: =SUM(D43:K43) -> 0 | D43: 0 | E43: 0 | F43: 0 | G43: 0 | H43: 0 | I43: 0 | J43: 0 | K43: 0 | N43: Total Misc. Closing Costs | Q43: =ROUNDUP(SUM(Q34,Q35,Q36,Q37,Q38,Q39,Q40,Q41),-2) -> 800 | W43: =B42 -> Furniture & Fixtures | X43: =IF($X$36=$E$15,E42,IF($X$36=$F$15,F42,IF($X$36=$G$15,G42,IF($X$36=$H$15,H42,IF($X$36=$I$15,I42,IF($X$36=$J$15,J42,IF($X$36=$K$15,K42,IF($X$36=$L$15,C42,C42)))))))) -> 0 | Y43: 10 | Z43: =IF($X$53=0,0,X43/$X$53) -> 0 | AA43: =Y43*Z43 -> 0 | AF43: =B43 -> Inventory | AG43: =SUM(AH43:AK43) -> 0 | AH43: 0 | AI43: =IFERROR(INDEX($C43:$K43,MATCH(AI$36,$C$36:$K$36,0)),0) -> 0 | AJ43: =IFERROR(INDEX($C43:$K43,MATCH(AJ$36,$C$36:$K$36,0)),0) -> 0 | AK43: =IFERROR(INDEX($C43:$K43,MATCH(AK$36,$C$36:$K$36,0)),0) -> 0
B44: Working Capital | C44: =SUM(D44:K44) -> 573500 | D44: 573500 | E44: 0 | F44: 0 | G44: 0 | H44: 0 | I44: 0 | J44: 0 | K44: 0 | W44: =B43 -> Inventory | X44: =IF($X$36=$E$15,E43,IF($X$36=$F$15,F43,IF($X$36=$G$15,G43,IF($X$36=$H$15,H43,IF($X$36=$I$15,I43,IF($X$36=$J$15,J43,IF($X$36=$K$15,K43,IF($X$36=$L$15,C43,C43)))))))) -> 0 | Y44: 10 | Z44: =IF($X$53=0,0,X44/$X$53) -> 0 | AA44: =Y44*Z44 -> 0 | AF44: =B44 -> Working Capital | AG44: =SUM(AH44:AK44) -> 0 | AH44: 0 | AI44: =IFERROR(INDEX($C44:$K44,MATCH(AI$36,$C$36:$K$36,0)),0) -> 0 | AJ44: =IFERROR(INDEX($C44:$K44,MATCH(AJ$36,$C$36:$K$36,0)),0) -> 0 | AK44: =IFERROR(INDEX($C44:$K44,MATCH(AK$36,$C$36:$K$36,0)),0) -> 0
B45: Working Capital - Pre Opening | C45: =SUM(D45:K45) -> 77000 | D45: 77000 | E45: 0 | F45: 0 | G45: 0 | H45: 0 | I45: 0 | J45: 0 | K45: 0 | N45: Total Project | O45: =C55 -> 8472925 | P45: =SUM(P46:P48) -> 1 | Q45: (difference) | W45: =B44 -> Working Capital | X45: =IF($X$36=$E$15,E44,IF($X$36=$F$15,F44,IF($X$36=$G$15,G44,IF($X$36=$H$15,H44,IF($X$36=$I$15,I44,IF($X$36=$J$15,J44,IF($X$36=$K$15,K44,IF($X$36=$L$15,C44,C44)))))))) -> 0 | Y45: 10 | Z45: =IF($X$53=0,0,X45/$X$53) -> 0 | AA45: =Y45*Z45 -> 0 | AF45: =B45 -> Working Capital - Pre Opening | AG45: =SUM(AH45:AK45) -> 0 | AH45: 0 | AI45: =IFERROR(INDEX($C45:$K45,MATCH(AI$36,$C$36:$K$36,0)),0) -> 0 | AJ45: =IFERROR(INDEX($C45:$K45,MATCH(AJ$36,$C$36:$K$36,0)),0) -> 0 | AK45: =IFERROR(INDEX($C45:$K45,MATCH(AK$36,$C$36:$K$36,0)),0) -> 0
...

Sheet Guarantors
B2: Personal Financial Analysis
J4: Outside Annual Income | P4: Monthly Payments | V4: Actuals
D5: Owner % | F5: Personal Liquidity | H5: AVG. FICO | J5: Outside Income | K5: Spouse Income | L5: Interest Income | M5: Rental Income | N5: Total Outside Annual Income | P5: Loan Payments | Q5: Credit Card | R5: Rent | S5: Child Support, Alimony & Other | T5: Total Monthly Liabilities | V5: Annual Liablities | W5: Outside Income | X5: Net Before Living Expenses | Z5: DTI % (Outside Income) | AA5: =_xlfn.CONCAT("Cash after Liablities at 45% DTI") -> Cash after Liablities at 45% DTI | AB5: Draw Needed | AC5: Income from Borrowing Entities | AD5: DTI% (All Income) | AF5: Include Draw? | AG5: Include in Global?
B6: Jeff Able | D6: 0.23 | F6: 11100 | H6: 702.3 | J6: 0 | K6: 126375 | L6: 0 | M6: 0 | N6: =SUM(J6:M6) -> 126375 | P6: 0 | Q6: 0 | R6: 0 | S6: 0 | T6: =SUM(P6:S6) -> 0 | V6: =T6*12 -> 0 | W6: =N6 -> 126375 | X6: =W6-V6 -> 126375 | Z6: =IFERROR((T6*12)/(N6),0) -> 0 | AA6: =N6-((T6*12)/0.45) -> 126375 | AB6: =IF(AF6=Lists!$H$4,0,IF(AA6<0,-AA6,0)) -> 0 | AC6: 0 | AD6: =IFERROR((T6*12)/(N6+AC6),0) -> 0 | AF6: Yes | AG6: Yes
B7: Lisa McClure | D7: 0.27 | F7: 525000 | H7: 800 | J7: 0 | K7: 0 | L7: 0 | M7: 0 | N7: =SUM(J7:M7) -> 0 | P7: 0 | Q7: 0 | R7: 3000 | S7: 0 | T7: =SUM(P7:S7) -> 3000 | V7: =T7*12 -> 36000 | W7: =N7 -> 0 | X7: =W7-V7 -> -36000 | Z7: =IFERROR((T7*12)/(N7),0) -> 0 | AA7: =N7-((T7*12)/0.45) -> -80000 | AB7: =IF(AF7=Lists!$H$4,0,IF(AA7<0,-AA7,0)) -> 80000 | AC7: 0 | AD7: =IFERROR((T7*12)/(N7+AC7),0) -> 0 | AF7: Yes | AG7: Yes
B8: Brandon Johnson | D8: 0.5 | F8: 100000 | H8: 810 | J8: 0 | K8: 0 | L8: 0 | M8: 0 | N8: =SUM(J8:M8) -> 0 | P8: 0 | Q8: 0 | R8: 5211 | S8: 1500 | T8: =SUM(P8:S8) -> 6711 | V8: =T8*12 -> 80532 | W8: =N8 -> 0 | X8: =W8-V8 -> -80532 | Z8: =IFERROR((T8*12)/(N8),0) -> 0 | AA8: =N8-((T8*12)/0.45) -> -178960 | AB8: =IF(AF8=Lists!$H$4,0,IF(AA8<0,-AA8,0)) -> 178960 | AC8: 0 | AD8: =IFERROR((T8*12)/(N8+AC8),0) -> 0 | AF8: Yes | AG8: Yes
B9: Riku Patel | D9: 0 | F9: 425000 | J9: 0 | K9: 64800 | L9: 0 | M9: 0 | N9: =SUM(J9:M9) -> 64800 | P9: 0 | Q9: 400 | R9: 0 | S9: 1183 | T9: =SUM(P9:S9) -> 1583 | V9: =T9*12 -> 18996 | W9: =N9 -> 64800 | X9: =W9-V9 -> 45804 | Z9: =IFERROR((T9*12)/(N9),0) -> 0.29314815 | AA9: =N9-((T9*12)/0.45) -> 22586.667 | AB9: =IF(AF9=Lists!$H$4,0,IF(AA9<0,-AA9,0)) -> 0 | AC9: 0 | AD9: =IFERROR((T9*12)/(N9+AC9),0) -> 0.29314815 | AF9: Yes | AG9: Yes
B10: Divy Patel | D10: 0 | F10: 657000 | J10: 0 | K10: 67200 | L10: 0 | M10: 0 | N10: =SUM(J10:M10) -> 67200 | P10: 0 | Q10: 965 | R10: 0 | S10: 609 | T10: =SUM(P10:S10) -> 1574 | V10: =T10*12 -> 18888 | W10: =N10 -> 67200 | X10: =W10-V10 -> 48312 | Z10: =IFERROR((T10*12)/(N10),0) -> 0.28107143 | AA10: =N10-((T10*12)/0.45) -> 25226.667 | AB10: =IF(AF10=Lists!$H$4,0,IF(AA10<0,-AA10,0)) -> 0 | AC10: 0 | AD10: =IFERROR((T10*12)/(N10+AC10),0) -> 0.28107143 | AF10: Yes | AG10: Yes
B11: Customer 6 | D11: 0 | F11: 0 | J11: 0 | K11: 0 | L11: 0 | M11: 0 | N11: =SUM(J11:M11) -> 0 | P11: 0 | Q11: 0 | R11: 0 | S11: 0 | T11: =SUM(P11:S11) -> 0 | V11: =T11*12 -> 0 | W11: =N11 -> 0 | X11: =W11-V11 -> 0 | Z11: =IFERROR((T11*12)/(N11),0) -> 0 | AA11: =N11-((T11*12)/0.45) -> 0 | AB11: =IF(AF11=Lists!$H$4,0,IF(AA11<0,-AA11,0)) -> 0 | AC11: 0 | AD11: =IFERROR((T11*12)/(N11+AC11),0) -> 0 | AF11: Yes | AG11: Yes
B12: Customer 7 | D12: 0 | F12: 0 | J12: 0 | K12: 0 | L12: 0 | M12: 0 | N12: =SUM(J12:M12) -> 0 | P12: 0 | Q12: 0 | R12: 0 | S12: 0 | T12: =SUM(P12:S12) -> 0 | V12: =T12*12 -> 0 | W12: =N12 -> 0 | X12: =W12-V12 -> 0 | Z12: =IFERROR((T12*12)/(N12),0) -> 0 | AA12: =N12-((T12*12)/0.45) -> 0 | AB12: =IF(AF12=Lists!$H$4,0,IF(AA12<0,-AA12,0)) -> 0 | AC12: 0 | AD12: =IFERROR((T12*12)/(N12+AC12),0) -> 0 | AF12: Yes | AG12: Yes
B13: Customer 8 | D13: 0 | F13: 0 | J13: 0 | K13: 0 | L13: 0 | M13: 0 | N13: =SUM(J13:M13) -> 0 | P13: 0 | Q13: 0 | R13: 0 | S13: 0 | T13: =SUM(P13:S13) -> 0 | V13: =T13*12 -> 0 | W13: =N13 -> 0 | X13: =W13-V13 -> 0 | Z13: =IFERROR((T13*12)/(N13),0) -> 0 | AA13: =N13-((T13*12)/0.45) -> 0 | AB13: =IF(AF13=Lists!$H$4,0,IF(AA13<0,-AA13,0)) -> 0 | AC13: 0 | AD13: =IFERROR((T13*12)/(N13+AC13),0) -> 0 | AF13: Yes | AG13: Yes
B14: Customer 9 | D14: 0 | F14: 0 | J14: 0 | K14: 0 | L14: 0 | M14: 0 | N14: =SUM(J14:M14) -> 0 | P14: 0 | Q14: 0 | R14: 0 | S14: 0 | T14: =SUM(P14:S14) -> 0 | V14: =T14*12 -> 0 | W14: =N14 -> 0 | X14: =W14-V14 -> 0 | Z14: =IFERROR((T14*12)/(N14),0) -> 0 | AA14: =N14-((T14*12)/0.45) -> 0 | AB14: =IF(AF14=Lists!$H$4,0,IF(AA14<0,-AA14,0)) -> 0 | AC14: 0 | AD14: =IFERROR((T14*12)/(N14+AC14),0) -> 0 | AF14: Yes | AG14: Yes
B15: Customer 10 | D15: 0 | F15: 0 | J15: 0 | K15: 0 | L15: 0 | M15: 0 | N15: =SUM(J15:M15) -> 0 | P15: 0 | Q15: 0 | R15: 0 | S15: 0 | T15: =SUM(P15:S15) -> 0 | V15: =T15*12 -> 0 | W15: =N15 -> 0 | X15: =W15-V15 -> 0 | Z15: =IFERROR((T15*12)/(N15),0) -> 0 | AA15: =N15-((T15*12)/0.45) -> 0 | AB15: =IF(AF15=Lists!$H$4,0,IF(AA15<0,-AA15,0)) -> 0 | AC15: 0 | AD15: =IFERROR((T15*12)/(N15+AC15),0) -> 0 | AF15: Yes | AG15: Yes
F16: =SUM(F6:F15) -> 1718100 | H16: =AVERAGE(H6:H15) -> 770.76667 | J16: =SUM(J6:J15) -> 0 | K16: =SUM(K6:K15) -> 258375 | L16: =SUM(L6:L15) -> 0 | M16: =SUM(M6:M15) -> 0 | N16: =SUM(N6:N15) -> 258375 | P16: =SUM(P6:P15) -> 0 | Q16: =SUM(Q6:Q15) -> 1365 | R16: =SUM(R6:R15) -> 8211 | S16: =SUM(S6:S15) -> 3292 | T16: =SUM(T6:T15) -> 12868 | V16: =SUM(V6:V15) -> 154416 | W16: =SUM(W6:W15) -> 258375 | X16: =SUM(X6:X15) -> 103959 | AA16: =SUM(AA6:AA15) -> -84771.667 | AB16: =IF(SUM(AB6:AB15)<AB18,AB18,SUM(AB6:AB15)) -> 258960 | AC16: =SUM(AC6:AC15) -> 0
U18: Include Minimum Draw? | Z18: Yes | AA18: Draw Required | AB18: =IF(Z18=Lists!H3,24000,0) -> 24000

Sheet Affiliates
B2: Affiliate Analysis
B3: <<< click the + to the left to expand sections below
D4: ='BDO Prequal'!D99 -> 45291 | F4: ='BDO Prequal'!F99 -> 45657 | H4: ='BDO Prequal'!H99 -> 46022 | J4: ='BDO Prequal'!J99 -> 46142
C5: Affiliate 1 - Cash Available | D5: =IF(Affiliates!$K$43="Yes",Affiliates!D90,0) -> 0 | F5: =IF(Affiliates!$K$43="Yes",Affiliates!F90,0) -> 0 | H5: =IF(Affiliates!$K$43="Yes",Affiliates!H90,0) -> 0 | J5: =IF(Affiliates!$K$43="Yes",Affiliates!J90,0) -> 0
C6: Affiliate 1 - Debt Service | D6: =IF(Affiliates!$K$43="Yes",Affiliates!D93,0) -> 0 | F6: =IF(Affiliates!$K$43="Yes",Affiliates!F93,0) -> 0 | H6: =IF(Affiliates!$K$43="Yes",Affiliates!H93,0) -> 0 | J6: =IF(Affiliates!$K$43="Yes",Affiliates!J93,0) -> 0
C7: ='BDO Prequal'!C164 -> Affiliate 1 - Net Cashflow | D7: ='BDO Prequal'!D164 -> 0 | F7: ='BDO Prequal'!F164 -> 0 | H7: ='BDO Prequal'!H164 -> 0 | J7: ='BDO Prequal'!J164 -> 0
C8: Affiliate 2 - Cash Available | D8: =IF(Affiliates!$K$99="Yes",Affiliates!D146,0) -> 0 | F8: =IF(Affiliates!$K$99="Yes",Affiliates!F146,0) -> 0 | H8: =IF(Affiliates!$K$99="Yes",Affiliates!H146,0) -> 0 | J8: =IF(Affiliates!$K$99="Yes",Affiliates!J146,0) -> 0
C9: Affiliate 2 - Debt Service | D9: =IF(Affiliates!$K$99="Yes",Affiliates!D149,0) -> 0 | F9: =IF(Affiliates!$K$99="Yes",Affiliates!F149,0) -> 0 | H9: =IF(Affiliates!$K$99="Yes",Affiliates!H149,0) -> 0 | J9: =IF(Affiliates!$K$99="Yes",Affiliates!J149,0) -> 0
C10: ='BDO Prequal'!C165 -> Affiliate 2 - Net Cashflow | D10: ='BDO Prequal'!D165 -> 0 | F10: ='BDO Prequal'!F165 -> 0 | H10: ='BDO Prequal'!H165 -> 0 | J10: ='BDO Prequal'!J165 -> 0
C11: Affiliate 3 - Cash Available | D11: =IF(Affiliates!$K$155="Yes",Affiliates!D202,0) -> 0 | F11: =IF(Affiliates!$K$155="Yes",Affiliates!F202,0) -> 0 | H11: =IF(Affiliates!$K$155="Yes",Affiliates!H202,0) -> 0 | J11: =IF(Affiliates!$K$155="Yes",Affiliates!J202,0) -> 0
C12: Affiliate 3 - Debt Service | D12: =IF(Affiliates!$K$155="Yes",Affiliates!D205,0) -> 0 | F12: =IF(Affiliates!$K$155="Yes",Affiliates!F205,0) -> 0 | H12: =IF(Affiliates!$K$155="Yes",Affiliates!H205,0) -> 0 | J12: =IF(Affiliates!$K$155="Yes",Affiliates!J205,0) -> 0
C13: ='BDO Prequal'!C166 -> Affiliate 3 - Net Cashflow | D13: ='BDO Prequal'!D166 -> 0 | F13: ='BDO Prequal'!F166 -> 0 | H13: ='BDO Prequal'!H166 -> 0 | J13: ='BDO Prequal'!J166 -> 0
C14: Affiliate 4 - Cash Available | D14: =IF(Affiliates!$K$211="Yes",Affiliates!D258,0) -> 0 | F14: =IF(Affiliates!$K$211="Yes",Affiliates!F258,0) -> 0 | H14: =IF(Affiliates!$K$211="Yes",Affiliates!H258,0) -> 0 | J14: =IF(Affiliates!$K$211="Yes",Affiliates!J258,0) -> 0
C15: Affiliate 4 - Debt Service | D15: =IF(Affiliates!$K$211="Yes",Affiliates!D261,0) -> 0 | F15: =IF(Affiliates!$K$211="Yes",Affiliates!F261,0) -> 0 | H15: =IF(Affiliates!$K$211="Yes",Affiliates!H261,0) -> 0 | J15: =IF(Affiliates!$K$211="Yes",Affiliates!J261,0) -> 0
C16: ='BDO Prequal'!C167 -> Affiliate 4 - Net Cashflow | D16: ='BDO Prequal'!D167 -> 0 | F16: ='BDO Prequal'!F167 -> 0 | H16: ='BDO Prequal'!H167 -> 0 | J16: ='BDO Prequal'!J167 -> 0
C17: Affiliate 5 - Cash Available | D17: =IF(Affiliates!$K$267="Yes",Affiliates!D314,0) -> 0 | F17: =IF(Affiliates!$K$267="Yes",Affiliates!F314,0) -> 0 | H17: =IF(Affiliates!$K$267="Yes",Affiliates!H314,0) -> 0 | J17: =IF(Affiliates!$K$267="Yes",Affiliates!J314,0) -> 0
C18: Affiliate 5 - Debt Service | D18: =IF(Affiliates!$K$267="Yes",Affiliates!D317,0) -> 0 | F18: =IF(Affiliates!$K$267="Yes",Affiliates!F317,0) -> 0 | H18: =IF(Affiliates!$K$267="Yes",Affiliates!H317,0) -> 0 | J18: =IF(Affiliates!$K$267="Yes",Affiliates!J317,0) -> 0
C19: ='BDO Prequal'!C168 -> Affiliate 5 - Net Cashflow | D19: ='BDO Prequal'!D168 -> 0 | F19: ='BDO Prequal'!F168 -> 0 | H19: ='BDO Prequal'!H168 -> 0 | J19: ='BDO Prequal'!J168 -> 0
C20: Affiliate 6 - Cash Available | D20: =IF(Affiliates!$K$323="Yes",Affiliates!D370,0) -> 0 | F20: =IF(Affiliates!$K$323="Yes",Affiliates!F370,0) -> 0 | H20: =IF(Affiliates!$K$323="Yes",Affiliates!H370,0) -> 0 | J20: =IF(Affiliates!$K$323="Yes",Affiliates!J370,0) -> 0
C21: Affiliate 6 - Debt Service | D21: =IF(Affiliates!$K$323="Yes",Affiliates!D373,0) -> 0 | F21: =IF(Affiliates!$K$323="Yes",Affiliates!F373,0) -> 0 | H21: =IF(Affiliates!$K$323="Yes",Affiliates!H373,0) -> 0 | J21: =IF(Affiliates!$K$323="Yes",Affiliates!J373,0) -> 0
C22: ='BDO Prequal'!C169 -> Affiliate 6 - Net Cashflow | D22: ='BDO Prequal'!D169 -> 0 | F22: ='BDO Prequal'!F169 -> 0 | H22: ='BDO Prequal'!H169 -> 0 | J22: ='BDO Prequal'!J169 -> 0
C23: Affiliate 7 - Cash Available | D23: =IF(Affiliates!$K$379="Yes",Affiliates!D426,0) -> 0 | F23: =IF(Affiliates!$K$379="Yes",Affiliates!F426,0) -> 0 | H23: =IF(Affiliates!$K$379="Yes",Affiliates!H426,0) -> 0 | J23: =IF(Affiliates!$K$379="Yes",Affiliates!J426,0) -> 0
C24: Affiliate 7 - Debt Service | D24: =IF(Affiliates!$K$379="Yes",D429,0) -> 0 | F24: =IF(Affiliates!$K$379="Yes",Affiliates!F429,0) -> 0 | H24: =IF(Affiliates!$K$379="Yes",Affiliates!H429,0) -> 0 | J24: =IF(Affiliates!$K$379="Yes",Affiliates!J429,0) -> 0
C25: ='BDO Prequal'!C170 -> Affiliate 7 - Net Cashflow | D25: ='BDO Prequal'!D170 -> 0 | F25: ='BDO Prequal'!F170 -> 0 | H25: ='BDO Prequal'!H170 -> 0 | J25: ='BDO Prequal'!J170 -> 0
C26: Affiliate 8 - Cash Available | D26: =IF(Affiliates!$K$435="Yes",Affiliates!D482,0) -> 0 | F26: =IF(Affiliates!$K$435="Yes",Affiliates!F482,0) -> 0 | H26: =IF(Affiliates!$K$435="Yes",Affiliates!H482,0) -> 0 | J26: =IF(Affiliates!$K$435="Yes",Affiliates!J482,0) -> 0
C27: Affiliate 8 - Debt Service | D27: =IF(Affiliates!$K$435="Yes",D485,0) -> 0 | F27: =IF(Affiliates!$K$435="Yes",F485,0) -> 0 | H27: =IF(Affiliates!$K$435="Yes",H485,0) -> 0 | J27: =IF(Affiliates!$K$435="Yes",J485,0) -> 0
C28: ='BDO Prequal'!C171 -> Affiliate 8 - Net Cashflow | D28: ='BDO Prequal'!D171 -> 0 | F28: ='BDO Prequal'!F171 -> 0 | H28: ='BDO Prequal'!H171 -> 0 | J28: ='BDO Prequal'!J171 -> 0
C29: Affiliate 9 - Cash Available | D29: =IF(Affiliates!$K$491="Yes",Affiliates!D538,0) -> 0 | F29: =IF(Affiliates!$K$491="Yes",Affiliates!F538,0) -> 0 | H29: =IF(Affiliates!$K$491="Yes",Affiliates!H538,0) -> 0 | J29: =IF(Affiliates!$K$491="Yes",Affiliates!J538,0) -> 0
C30: Affiliate 9 - Debt Service | D30: =IF(Affiliates!$K$491="Yes",D541,0) -> 0 | F30: =IF(Affiliates!$K$491="Yes",F541,0) -> 0 | H30: =IF(Affiliates!$K$491="Yes",H541,0) -> 0 | J30: =IF(Affiliates!$K$491="Yes",J541,0) -> 0
C31: ='BDO Prequal'!C172 -> Affiliate 9 - Net Cashflow | D31: ='BDO Prequal'!D172 -> 0 | F31: ='BDO Prequal'!F172 -> 0 | H31: ='BDO Prequal'!H172 -> 0 | J31: ='BDO Prequal'!J172 -> 0
C32: Affiliate 10 - Cash Available | D32: =IF($K$547="Yes",D594,0) -> 0 | F32: =IF($K$547="Yes",F594,0) -> 0 | H32: =IF($K$547="Yes",H594,0) -> 0 | J32: =IF($K$547="Yes",J594,0) -> 0
C33: Affiliate 10 - Debt Service | D33: =IF($K$547="Yes",D597,0) -> 0 | F33: =IF($K$547="Yes",F597,0) -> 0 | H33: =IF($K$547="Yes",H597,0) -> 0 | J33: =IF($K$547="Yes",J597,0) -> 0
C34: ='BDO Prequal'!C173 -> Affiliate 10 - Net Cashflow | D34: ='BDO Prequal'!D173 -> 0 | F34: ='BDO Prequal'!F173 -> 0 | H34: ='BDO Prequal'!H173 -> 0 | J34: ='BDO Prequal'!J173 -> 0
C35: Affiliate 11 - Cash Available | D35: =IF($K$603="Yes",D650,0) -> 0 | F35: =IF($K$603="Yes",F650,0) -> 0 | H35: =IF($K$603="Yes",H650,0) -> 0 | J35: =IF($K$603="Yes",J650,0) -> 0
C36: Affiliate 11 - Debt Service | D36: =IF($K$603="Yes",D650,0) -> 0 | F36: =IF($K$603="Yes",F650,0) -> 0 | H36: =IF($K$603="Yes",H650,0) -> 0 | J36: =IF($K$603="Yes",J650,0) -> 0
C37: ='BDO Prequal'!C174 -> Affiliate 11 - Net Cashflow | D37: ='BDO Prequal'!D174 -> 0 | F37: ='BDO Prequal'!F174 -> 0 | H37: ='BDO Prequal'!H174 -> 0 | J37: ='BDO Prequal'!J174 -> 0
C38: Affiliate 12 - Cash Available | D38: =IF($K$659="Yes",D706,0) -> 0 | F38: =IF($K$659="Yes",F706,0) -> 0 | H38: =IF($K$659="Yes",H706,0) -> 0 | J38: =IF($K$659="Yes",J706,0) -> 0
C39: Affiliate 12 - Debt Service | D39: =IF($K$659="Yes",D709,0) -> 0 | F39: =IF($K$659="Yes",F709,0) -> 0 | H39: =IF($K$659="Yes",H709,0) -> 0 | J39: =IF($K$659="Yes",J709,0) -> 0
C40: ='BDO Prequal'!C175 -> Affiliate 12 - Net Cashflow | D40: ='BDO Prequal'!D175 -> 0 | F40: ='BDO Prequal'!F175 -> 0 | H40: ='BDO Prequal'!H175 -> 0 | J40: ='BDO Prequal'!J175 -> 0
B42: Affiliate 1
...

Sheet Scores
B2: T Bank, N.A. SCORING GRID
B3: Total Score | C3: REPAYMENT | D3: MANAGEMENT | E3: CREDIT | F3: EQUITY | G3: COLLATERAL | H3: Working Capital/Liquidity
B4: =SUM(C4:H4) -> 0
B5: 5 | C5: Pro forma DSC of 1.40x in the most recent year and 1.25x or better for the prior 2 years plus stable/positive trends in the interim. Stable is considered + - 0.05 change in DSC. | D5: 3 or more years ownership in SBC or 3 years as primary responsible employee in SBC or 5 years recent experience in near identical type business as Principal Manager with P&L and HR responsibility. | E5: N/A | F5: 25% cash equity from personal sources Expansions: pro forma tangible D/W of 4:1 or less. | G5: Secured 120% of the loan on a discounted basis with any collateral or 100% secured with 1st lien on RE. 504 1st lien No construction | H5: N/A
B6: 4 | C6: Pro forma DSC of 1.40x or better for most recent years plus 1.25x for the 1 prior year plus stable/positive trends in the interim. Stable is considered + - 0.05 change in DSC. | D6: 2 or more years ownership in SBC or 3 years experience in near identical type business. For startups - this experience, must have been within the last 5 years AND one of the guarantors will devote 100% of time to SBC | E6: FICO Score greater than 750. | F6: 25% cash equity from any source or 20% from personal sources Expansions: pro forma tangible D/W of 5:1 or less. | G6: Secured 100% of the loan on a discounted basis with any collateral or 75% with 1st lien on RE. 504 1st Lien Construction | H6: N/A
B7: 3 | C7: Pro forma DSC of an 1.25x or better in most recent FYE and interim plus stable/positive trends in the interim. Stable is considered + - 0.05 change in DSC. Regardless of DSC declining revenue or profitability trends in the most recent year and/or interim. | D7: 2 years ownership in any industry or 3 years of transferable management experience in any industry, or approved franchise For startups - this experience, must have been within the last 5 years AND one of the guarantors will devote 100% of time to SBC. | E7: FICO Score of 700 to 749. Regardless of any higher FICO score BK between 3 and 5 years in time. Regardless of any higher FICO score expected continuing income of between $5500 and $6000 for every $1000 of CC debt | F7: 20% cash equity from any source or 15% from personal sources Expansions: pro forma tangible D/W of 6:1 or less. | G7: Secured 75% of the loan on a discounted basis with any collateral or 50% with 1st lien on RE. | H7: No or minimal working capital requirement OR Borrower has 1.5X working capital from own liquid resources. Minimal is the lesser of 5% of loan amount or $50K. None is included in loan.
B8: 2 | C8: Pro forma DSC of 1.15x or better in most recent FYE and interim plus positive trends in the interim. Regardless of DSC declining revenue or profitability trends in all periods Projection Based or Start Up with Approved Franchise. | D8: 2 years transferable management experience not specific to this industry or non-approved franchise. For startups - this experience must have been within the last 3 years AND one of the guarantors will 100% of time devoted to SBC | E8: FICO Score 650 to 699 Regardless of any higher FICO score expected continuing income of between $5000 and $5499 for every $1000 of CC debt | F8: 10% cash equity from any source Expansions: pro forma tangible D/W of 8:1 or less. | G8: Secured 50% of the loan on a discounted basis with any collateral or 25% with 1st lien on RE. | H8: Borrower has sufficient documented working Capital to inject from own resources (WC as calculated by U/W). In loan is OK as long as borrower has 1x or greater residual liquidity.
B9: 1 | C9: Projection based or start-up. | D9: Less than 2 years transferable management experience OR reliant on prior owner or franchisor for training. For startups - the experience was over 3 years ago. | E9: FICO Score less than 650 Regardless of any higher FICO score expected continuing income of between $4500 and $4999 for every $1000 of CC debt | F9: Less than 10% injection and/or 50% or more Equity is from Seller note on full standby | G9: < 50% secured with any collateral or less than 25% 1st lien on RE. | H9: All, or substantially all of W/C is included in loan or companion loan and borrower has little or no residual liquidity.
B10: 0 | C10: N/A | D10: Remote management or long distance management with no prior experience of remote management. | E10: BK in the last 3 years. Regardless of any higher FICO score expected continuing income of less than $4500 for every $1000 of CC debt | F10: Any other allowable SBA SOP structure that does not require injection. | G10: No CRE included in collateral or only junior liens on residential. | H10: Working capital included in loan proceeds exceeds 50% of borrower cash injection.
C13: Income | D13: CC Debt | E13: Income Needed $4,500 | F13: Income Needed $4,999 | G13: Income Needed $5,499 | H13: Income Needed $6,000+
B14: =Guarantors!B6 -> Jeff Able | C14: =Guarantors!N6 -> 126375 | D14: 0 | E14: =D14*4.5 -> 0 | F14: =D14*4.999 -> 0 | G14: =D14*5.499 -> 0 | H14: =D14*6 -> 0
B15: =Guarantors!B7 -> Lisa McClure | C15: =Guarantors!N7 -> 0 | D15: 0 | E15: =D15*4.5 -> 0 | F15: =D15*4.999 -> 0 | G15: =D15*5.499 -> 0 | H15: =D15*6 -> 0
B16: =Guarantors!B8 -> Brandon Johnson | C16: =Guarantors!N8 -> 0 | D16: 0 | E16: =D16*4.5 -> 0 | F16: =D16*4.999 -> 0 | G16: =D16*5.499 -> 0 | H16: =D16*6 -> 0
B17: =Guarantors!B9 -> Riku Patel | C17: =Guarantors!N9 -> 64800 | D17: 0 | E17: =D17*4.5 -> 0 | F17: =D17*4.999 -> 0 | G17: =D17*5.499 -> 0 | H17: =D17*6 -> 0
B18: =Guarantors!B10 -> Divy Patel | C18: =Guarantors!N10 -> 67200 | D18: 0 | E18: =D18*4.5 -> 0 | F18: =D18*4.999 -> 0 | G18: =D18*5.499 -> 0 | H18: =D18*6 -> 0
B19: =Guarantors!B11 -> Customer 6 | C19: =Guarantors!N11 -> 0 | D19: 0 | E19: =D19*4.5 -> 0 | F19: =D19*4.999 -> 0 | G19: =D19*5.499 -> 0 | H19: =D19*6 -> 0
B20: =Guarantors!B12 -> Customer 7 | C20: =Guarantors!N12 -> 0 | D20: 0 | E20: =D20*4.5 -> 0 | F20: =D20*4.999 -> 0 | G20: =D20*5.499 -> 0 | H20: =D20*6 -> 0
B21: =Guarantors!B13 -> Customer 8 | C21: =Guarantors!N13 -> 0 | D21: 0 | E21: =D21*4.5 -> 0 | F21: =D21*4.999 -> 0 | G21: =D21*5.499 -> 0 | H21: =D21*6 -> 0
B22: =Guarantors!B14 -> Customer 9 | C22: =Guarantors!N14 -> 0 | D22: 0 | E22: =D22*4.5 -> 0 | F22: =D22*4.999 -> 0 | G22: =D22*5.499 -> 0 | H22: =D22*6 -> 0
B23: =Guarantors!B15 -> Customer 10 | C23: =Guarantors!N15 -> 0 | D23: 0 | E23: =D23*4.5 -> 0 | F23: =D23*4.999 -> 0 | G23: =D23*5.499 -> 0 | H23: =D23*6 -> 0

Sheet Charts
B3: Loan Request | M3: Loan Request
C5: =N5 -> Total | D5: =O5 -> Equity | E5: =P5 -> SBA 7(a) | F5: =Q5 -> SBA 7(a) | G5: =R5 -> SBA 504 | H5: =S5 -> Seller Note | I5: =T5 -> Debenture | J5: =U5 -> N/A | K5: =V5 -> N/A | N5: ='BDO Prequal'!C36 -> Total | O5: ='BDO Prequal'!D36 -> Equity | P5: ='BDO Prequal'!E36 -> SBA 7(a) | Q5: ='BDO Prequal'!F36 -> SBA 7(a) | R5: ='BDO Prequal'!G36 -> SBA 504 | S5: ='BDO Prequal'!H36 -> Seller Note | T5: ='BDO Prequal'!I36 -> Debenture | U5: ='BDO Prequal'!J36 -> N/A | V5: ='BDO Prequal'!K36 -> N/A
B6: {=_xlfn.LET(_xlpm.visRows,_xlfn._xlws.FILTER(ROW($M$6:$M$22),$N$6:$N$22<>0),_xlpm.allRows,_xlfn.VSTACK(_xlpm.visRows,23,24),_xlpm.pos,ROW()-5,IF(_xlpm.pos<=ROWS(_xlpm.allRows),INDEX($M:$M,INDEX(_xlpm.allRows,_xlpm.pos)),""))} -> Machinery & Equipment | C6: {=_xlfn.LET(_xlpm.visRows,_xlfn._xlws.FILTER(ROW($M$6:$M$22),$N$6:$N$22<>0),_xlpm.allRows,_xlfn.VSTACK(_xlpm.visRows,23,24),_xlpm.pos,ROW()-5,IF(_xlpm.pos>ROWS(_xlpm.allRows),"",_xlfn.LET(_xlpm.rn,INDEX(_xlpm.allRows,_xlpm.pos),_xlpm.val,INDEX($N:$N,_xlpm.rn),IF(INDEX($M:$M,_xlpm.rn)="Percentages",IF(_xlpm.val=0,"-",TEXT(_xlpm.val,"0%")),_xlpm.val))))} -> 366285 | D6: {=_xlfn.LET(_xlpm.visRows,_xlfn._xlws.FILTER(ROW($M$6:$M$22),$N$6:$N$22<>0),_xlpm.allRows,_xlfn.VSTACK(_xlpm.visRows,23,24),_xlpm.pos,ROW()-5,IF(_xlpm.pos>ROWS(_xlpm.allRows),"",_xlfn.LET(_xlpm.rn,INDEX(_xlpm.allRows,_xlpm.pos),_xlpm.val,INDEX($O:$O,_xlpm.rn),IF(INDEX($M:$M,_xlpm.rn)="Percentages",IF(_xlpm.val=0,"-",TEXT(_xlpm.val,"0%")),_xlpm.val))))} -> 366285 | E6: {=_xlfn.LET(_xlpm.visRows,_xlfn._xlws.FILTER(ROW($M$6:$M$22),$N$6:$N$22<>0),_xlpm.allRows,_xlfn.VSTACK(_xlpm.visRows,23,24),_xlpm.pos,ROW()-5,IF(_xlpm.pos>ROWS(_xlpm.allRows),"",_xlfn.LET(_xlpm.rn,INDEX(_xlpm.allRows,_xlpm.pos),_xlpm.val,INDEX($P:$P,_xlpm.rn),IF(INDEX($M:$M,_xlpm.rn)="Percentages",IF(_xlpm.val=0,"-",TEXT(_xlpm.val,"0%")),_xlpm.val))))} -> 0 | F6: {=_xlfn.LET(_xlpm.visRows,_xlfn._xlws.FILTER(ROW($M$6:$M$22),$N$6:$N$22<>0),_xlpm.allRows,_xlfn.VSTACK(_xlpm.visRows,23,24),_xlpm.pos,ROW()-5,IF(_xlpm.pos>ROWS(_xlpm.allRows),"",_xlfn.LET(_xlpm.rn,INDEX(_xlpm.allRows,_xlpm.pos),_xlpm.val,INDEX($Q:$Q,_xlpm.rn),IF(INDEX($M:$M,_xlpm.rn)="Percentages",IF(_xlpm.val=0,"-",TEXT(_xlpm.val,"0%")),_xlpm.val))))} -> 0 | G6: {=_xlfn.LET(_xlpm.visRows,_xlfn._xlws.FILTER(ROW($M$6:$M$22),$N$6:$N$22<>0),_xlpm.allRows,_xlfn.VSTACK(_xlpm.visRows,23,24),_xlpm.pos,ROW()-5,IF(_xlpm.pos>ROWS(_xlpm.allRows),"",_xlfn.LET(_xlpm.rn,INDEX(_xlpm.allRows,_xlpm.pos),_xlpm.val,INDEX($R:$R,_xlpm.rn),IF(INDEX($M:$M,_xlpm.rn)="Percentages",IF(_xlpm.val=0,"-",TEXT(_xlpm.val,"0%")),_xlpm.val))))} -> 0 | H6: {=_xlfn.LET(_xlpm.visRows,_xlfn._xlws.FILTER(ROW($M$6:$M$22),$N$6:$N$22<>0),_xlpm.allRows,_xlfn.VSTACK(_xlpm.visRows,23,24),_xlpm.pos,ROW()-5,IF(_xlpm.pos>ROWS(_xlpm.allRows),"",_xlfn.LET(_xlpm.rn,INDEX(_xlpm.allRows,_xlpm.pos),_xlpm.val,INDEX($S:$S,_xlpm.rn),IF(INDEX($M:$M,_xlpm.rn)="Percentages",IF(_xlpm.val=0,"-",TEXT(_xlpm.val,"0%")),_xlpm.val))))} -> 0 | I6: {=_xlfn.LET(_xlpm.visRows,_xlfn._xlws.FILTER(ROW($M$6:$M$22),$N$6:$N$22<>0),_xlpm.allRows,_xlfn.VSTACK(_xlpm.visRows,23,24),_xlpm.pos,ROW()-5,IF(_xlpm.pos>ROWS(_xlpm.allRows),"",_xlfn.LET(_xlpm.rn,INDEX(_xlpm.allRows,_xlpm.pos),_xlpm.val,INDEX($T:$T,_xlpm.rn),IF(INDEX($M:$M,_xlpm.rn)="Percentages",IF(_xlpm.val=0,"-",TEXT(_xlpm.val,"0%")),_xlpm.val))))} -> 0 | J6: {=_xlfn.LET(_xlpm.visRows,_xlfn._xlws.FILTER(ROW($M$6:$M$22),$N$6:$N$22<>0),_xlpm.allRows,_xlfn.VSTACK(_xlpm.visRows,23,24),_xlpm.pos,ROW()-5,IF(_xlpm.pos>ROWS(_xlpm.allRows),"",_xlfn.LET(_xlpm.rn,INDEX(_xlpm.allRows,_xlpm.pos),_xlpm.val,INDEX($U:$U,_xlpm.rn),IF(INDEX($M:$M,_xlpm.rn)="Percentages",IF(_xlpm.val=0,"-",TEXT(_xlpm.val,"0%")),_xlpm.val))))} -> 0 | K6: {=_xlfn.LET(_xlpm.visRows,_xlfn._xlws.FILTER(ROW($M$6:$M$22),$N$6:$N$22<>0),_xlpm.allRows,_xlfn.VSTACK(_xlpm.visRows,23,24),_xlpm.pos,ROW()-5,IF(_xlpm.pos>ROWS(_xlpm.allRows),"",_xlfn.LET(_xlpm.rn,INDEX(_xlpm.allRows,_xlpm.pos),_xlpm.val,INDEX($V:$V,_xlpm.rn),IF(INDEX($M:$M,_xlpm.rn)="Percentages",IF(_xlpm.val=0,"-",TEXT(_xlpm.val,"0%")),_xlpm.val))))} -> 0 | M6: ='BDO Prequal'!B38 -> Real Estate Acquisition | N6: ='BDO Prequal'!C38 -> 0 | O6: ='BDO Prequal'!D38 -> 0 | P6: ='BDO Prequal'!E38 -> 0 | Q6: ='BDO Prequal'!F38 -> 0 | R6: ='BDO Prequal'!G38 -> 0 | S6: ='BDO Prequal'!H38 -> 0 | T6: ='BDO Prequal'!I38 -> 0 | ... V6: ='BDO Prequal'!K38 -> 0
B7: {=_xlfn.LET(_xlpm.visRows,_xlfn._xlws.FILTER(ROW($M$6:$M$22),$N$6:$N$22<>0),_xlpm.allRows,_xlfn.VSTACK(_xlpm.visRows,23,24),_xlpm.pos,ROW()-5,IF(_xlpm.pos<=ROWS(_xlpm.allRows),INDEX($M:$M,INDEX(_xlpm.allRows,_xlpm.pos)),""))} -> Furniture & Fixtures | C7: {=_xlfn.LET(_xlpm.visRows,_xlfn._xlws.FILTER(ROW($M$6:$M$22),$N$6:$N$22<>0),_xlpm.allRows,_xlfn.VSTACK(_xlpm.visRows,23,24),_xlpm.pos,ROW()-5,IF(_xlpm.pos>ROWS(_xlpm.allRows),"",_xlfn.LET(_xlpm.rn,INDEX(_xlpm.allRows,_xlpm.pos),_xlpm.val,INDEX($N:$N,_xlpm.rn),IF(INDEX($M:$M,_xlpm.rn)="Percentages",IF(_xlpm.val=0,"-",TEXT(_xlpm.val,"0%")),_xlpm.val))))} -> 600000 | D7: {=_xlfn.LET(_xlpm.visRows,_xlfn._xlws.FILTER(ROW($M$6:$M$22),$N$6:$N$22<>0),_xlpm.allRows,_xlfn.VSTACK(_xlpm.visRows,23,24),_xlpm.pos,ROW()-5,IF(_xlpm.pos>ROWS(_xlpm.allRows),"",_xlfn.LET(_xlpm.rn,INDEX(_xlpm.allRows,_xlpm.pos),_xlpm.val,INDEX($O:$O,_xlpm.rn),IF(INDEX($M:$M,_xlpm.rn)="Percentages",IF(_xlpm.val=0,"-",TEXT(_xlpm.val,"0%")),_xlpm.val))))} -> 0 | E7: {=_xlfn.LET(_xlpm.visRows,_xlfn._xlws.FILTER(ROW($M$6:$M$22),$N$6:$N$22<>0),_xlpm.allRows,_xlfn.VSTACK(_xlpm.visRows,23,24),_xlpm.pos,ROW()-5,IF(_xlpm.pos>ROWS(_xlpm.allRows),"",_xlfn.LET(_xlpm.rn,INDEX(_xlpm.allRows,_xlpm.pos),_xlpm.val,INDEX($P:$P,_xlpm.rn),IF(INDEX($M:$M,_xlpm.rn)="Percentages",IF(_xlpm.val=0,"-",TEXT(_xlpm.val,"0%")),_xlpm.val))))} -> 0 | F7: {=_xlfn.LET(_xlpm.visRows,_xlfn._xlws.FILTER(ROW($M$6:$M$22),$N$6:$N$22<>0),_xlpm.allRows,_xlfn.VSTACK(_xlpm.visRows,23,24),_xlpm.pos,ROW()-5,IF(_xlpm.pos>ROWS(_xlpm.allRows),"",_xlfn.LET(_xlpm.rn,INDEX(_xlpm.allRows,_xlpm.pos),_xlpm.val,INDEX($Q:$Q,_xlpm.rn),IF(INDEX($M:$M,_xlpm.rn)="Percentages",IF(_xlpm.val=0,"-",TEXT(_xlpm.val,"0%")),_xlpm.val))))} -> 600000 | G7: {=_xlfn.LET(_xlpm.visRows,_xlfn._xlws.FILTER(ROW($M$6:$M$22),$N$6:$N$22<>0),_xlpm.allRows,_xlfn.VSTACK(_xlpm.visRows,23,24),_xlpm.pos,ROW()-5,IF(_xlpm.pos>ROWS(_xlpm.allRows),"",_xlfn.LET(_xlpm.rn,INDEX(_xlpm.allRows,_xlpm.pos),_xlpm.val,INDEX($R:$R,_xlpm.rn),IF(INDEX($M:$M,_xlpm.rn)="Percentages",IF(_xlpm.val=0,"-",TEXT(_xlpm.val,"0%")),_xlpm.val))))} -> 0 | H7: {=_xlfn.LET(_xlpm.visRows,_xlfn._xlws.FILTER(ROW($M$6:$M$22),$N$6:$N$22<>0),_xlpm.allRows,_xlfn.VSTACK(_xlpm.visRows,23,24),_xlpm.pos,ROW()-5,IF(_xlpm.pos>ROWS(_xlpm.allRows),"",_xlfn.LET(_xlpm.rn,INDEX(_xlpm.allRows,_xlpm.pos),_xlpm.val,INDEX($S:$S,_xlpm.rn),IF(INDEX($M:$M,_xlpm.rn)="Percentages",IF(_xlpm.val=0,"-",TEXT(_xlpm.val,"0%")),_xlpm.val))))} -> 0 | I7: {=_xlfn.LET(_xlpm.visRows,_xlfn._xlws.FILTER(ROW($M$6:$M$22),$N$6:$N$22<>0),_xlpm.allRows,_xlfn.VSTACK(_xlpm.visRows,23,24),_xlpm.pos,ROW()-5,IF(_xlpm.pos>ROWS(_xlpm.allRows),"",_xlfn.LET(_xlpm.rn,INDEX(_xlpm.allRows,_xlpm.pos),_xlpm.val,INDEX($T:$T,_xlpm.rn),IF(INDEX($M:$M,_xlpm.rn)="Percentages",IF(_xlpm.val=0,"-",TEXT(_xlpm.val,"0%")),_xlpm.val))))} -> 0 | J7: {=_xlfn.LET(_xlpm.visRows,_xlfn._xlws.FILTER(ROW($M$6:$M$22),$N$6:$N$22<>0),_xlpm.allRows,_xlfn.VSTACK(_xlpm.visRows,23,24),_xlpm.pos,ROW()-5,IF(_xlpm.pos>ROWS(_xlpm.allRows),"",_xlfn.LET(_xlpm.rn,INDEX(_xlpm.allRows,_xlpm.pos),_xlpm.val,INDEX($U:$U,_xlpm.rn),IF(INDEX($M:$M,_xlpm.rn)="Percentages",IF(_xlpm.val=0,"-",TEXT(_xlpm.val,"0%")),_xlpm.val))))} -> 0 | K7: {=_xlfn.LET(_xlpm.visRows,_xlfn._xlws.FILTER(ROW($M$6:$M$22),$N$6:$N$22<>0),_xlpm.allRows,_xlfn.VSTACK(_xlpm.visRows,23,24),_xlpm.pos,ROW()-5,IF(_xlpm.pos>ROWS(_xlpm.allRows),"",_xlfn.LET(_xlpm.rn,INDEX(_xlpm.allRows,_xlpm.pos),_xlpm.val,INDEX($V:$V,_xlpm.rn),IF(INDEX($M:$M,_xlpm.rn)="Percentages",IF(_xlpm.val=0,"-",TEXT(_xlpm.val,"0%")),_xlpm.val))))} -> 0 | M7: ='BDO Prequal'!B39 -> Debt Refi - CRE | N7: ='BDO Prequal'!C39 -> 0 | O7: ='BDO Prequal'!D39 -> 0 | P7: ='BDO Prequal'!E39 -> 0 | Q7: ='BDO Prequal'!F39 -> 0 | R7: ='BDO Prequal'!G39 -> 0 | S7: ='BDO Prequal'!H39 -> 0 | T7: ='BDO Prequal'!I39 -> 0 | ... V7: ='BDO Prequal'!K39 -> 0
B8: {=_xlfn.LET(_xlpm.visRows,_xlfn._xlws.FILTER(ROW($M$6:$M$22),$N$6:$N$22<>0),_xlpm.allRows,_xlfn.VSTACK(_xlpm.visRows,23,24),_xlpm.pos,ROW()-5,IF(_xlpm.pos<=ROWS(_xlpm.allRows),INDEX($M:$M,INDEX(_xlpm.allRows,_xlpm.pos)),""))} -> Working Capital | C8: {=_xlfn.LET(_xlpm.visRows,_xlfn._xlws.FILTER(ROW($M$6:$M$22),$N$6:$N$22<>0),_xlpm.allRows,_xlfn.VSTACK(_xlpm.visRows,23,24),_xlpm.pos,ROW()-5,IF(_xlpm.pos>ROWS(_xlpm.allRows),"",_xlfn.LET(_xlpm.rn,INDEX(_xlpm.allRows,_xlpm.pos),_xlpm.val,INDEX($N:$N,_xlpm.rn),IF(INDEX($M:$M,_xlpm.rn)="Percentages",IF(_xlpm.val=0,"-",TEXT(_xlpm.val,"0%")),_xlpm.val))))} -> 573500 | D8: {=_xlfn.LET(_xlpm.visRows,_xlfn._xlws.FILTER(ROW($M$6:$M$22),$N$6:$N$22<>0),_xlpm.allRows,_xlfn.VSTACK(_xlpm.visRows,23,24),_xlpm.pos,ROW()-5,IF(_xlpm.pos>ROWS(_xlpm.allRows),"",_xlfn.LET(_xlpm.rn,INDEX(_xlpm.allRows,_xlpm.pos),_xlpm.val,INDEX($O:$O,_xlpm.rn),IF(INDEX($M:$M,_xlpm.rn)="Percentages",IF(_xlpm.val=0,"-",TEXT(_xlpm.val,"0%")),_xlpm.val))))} -> 573500 | E8: {=_xlfn.LET(_xlpm.visRows,_xlfn._xlws.FILTER(ROW($M$6:$M$22),$N$6:$N$22<>0),_xlpm.allRows,_xlfn.VSTACK(_xlpm.visRows,23,24),_xlpm.pos,ROW()-5,IF(_xlpm.pos>ROWS(_xlpm.allRows),"",_xlfn.LET(_xlpm.rn,INDEX(_xlpm.allRows,_xlpm.pos),_xlpm.val,INDEX($P:$P,_xlpm.rn),IF(INDEX($M:$M,_xlpm.rn)="Percentages",IF(_xlpm.val=0,"-",TEXT(_xlpm.val,"0%")),_xlpm.val))))} -> 0 | F8: {=_xlfn.LET(_xlpm.visRows,_xlfn._xlws.FILTER(ROW($M$6:$M$22),$N$6:$N$22<>0),_xlpm.allRows,_xlfn.VSTACK(_xlpm.visRows,23,24),_xlpm.pos,ROW()-5,IF(_xlpm.pos>ROWS(_xlpm.allRows),"",_xlfn.LET(_xlpm.rn,INDEX(_xlpm.allRows,_xlpm.pos),_xlpm.val,INDEX($Q:$Q,_xlpm.rn),IF(INDEX($M:$M,_xlpm.rn)="Percentages",IF(_xlpm.val=0,"-",TEXT(_xlpm.val,"0%")),_xlpm.val))))} -> 0 | G8: {=_xlfn.LET(_xlpm.visRows,_xlfn._xlws.FILTER(ROW($M$6:$M$22),$N$6:$N$22<>0),_xlpm.allRows,_xlfn.VSTACK(_xlpm.visRows,23,24),_xlpm.pos,ROW()-5,IF(_xlpm.pos>ROWS(_xlpm.allRows),"",_xlfn.LET(_xlpm.rn,INDEX(_xlpm.allRows,_xlpm.pos),_xlpm.val,INDEX($R:$R,_xlpm.rn),IF(INDEX($M:$M,_xlpm.rn)="Percentages",IF(_xlpm.val=0,"-",TEXT(_xlpm.val,"0%")),_xlpm.val))))} -> 0 | H8: {=_xlfn.LET(_xlpm.visRows,_xlfn._xlws.FILTER(ROW($M$6:$M$22),$N$6:$N$22<>0),_xlpm.allRows,_xlfn.VSTACK(_xlpm.visRows,23,24),_xlpm.pos,ROW()-5,IF(_xlpm.pos>ROWS(_xlpm.allRows),"",_xlfn.LET(_xlpm.rn,INDEX(_xlpm.allRows,_xlpm.pos),_xlpm.val,INDEX($S:$S,_xlpm.rn),IF(INDEX($M:$M,_xlpm.rn)="Percentages",IF(_xlpm.val=0,"-",TEXT(_xlpm.val,"0%")),_xlpm.val))))} -> 0 | I8: {=_xlfn.LET(_xlpm.visRows,_xlfn._xlws.FILTER(ROW($M$6:$M$22),$N$6:$N$22<>0),_xlpm.allRows,_xlfn.VSTACK(_xlpm.visRows,23,24),_xlpm.pos,ROW()-5,IF(_xlpm.pos>ROWS(_xlpm.allRows),"",_xlfn.LET(_xlpm.rn,INDEX(_xlpm.allRows,_xlpm.pos),_xlpm.val,INDEX($T:$T,_xlpm.rn),IF(INDEX($M:$M,_xlpm.rn)="Percentages",IF(_xlpm.val=0,"-",TEXT(_xlpm.val,"0%")),_xlpm.val))))} -> 0 | J8: {=_xlfn.LET(_xlpm.visRows,_xlfn._xlws.FILTER(ROW($M$6:$M$22),$N$6:$N$22<>0),_xlpm.allRows,_xlfn.VSTACK(_xlpm.visRows,23,24),_xlpm.pos,ROW()-5,IF(_xlpm.pos>ROWS(_xlpm.allRows),"",_xlfn.LET(_xlpm.rn,INDEX(_xlpm.allRows,_xlpm.pos),_xlpm.val,INDEX($U:$U,_xlpm.rn),IF(INDEX($M:$M,_xlpm.rn)="Percentages",IF(_xlpm.val=0,"-",TEXT(_xlpm.val,"0%")),_xlpm.val))))} -> 0 | K8: {=_xlfn.LET(_xlpm.visRows,_xlfn._xlws.FILTER(ROW($M$6:$M$22),$N$6:$N$22<>0),_xlpm.allRows,_xlfn.VSTACK(_xlpm.visRows,23,24),_xlpm.pos,ROW()-5,IF(_xlpm.pos>ROWS(_xlpm.allRows),"",_xlfn.LET(_xlpm.rn,INDEX(_xlpm.allRows,_xlpm.pos),_xlpm.val,INDEX($V:$V,_xlpm.rn),IF(INDEX($M:$M,_xlpm.rn)="Percentages",IF(_xlpm.val=0,"-",TEXT(_xlpm.val,"0%")),_xlpm.val))))} -> 0 | M8: ='BDO Prequal'!B40 -> Debt Refi - Non-CRE | N8: ='BDO Prequal'!C40 -> 0 | O8: ='BDO Prequal'!D40 -> 0 | P8: ='BDO Prequal'!E40 -> 0 | Q8: ='BDO Prequal'!F40 -> 0 | R8: ='BDO Prequal'!G40 -> 0 | S8: ='BDO Prequal'!H40 -> 0 | T8: ='BDO Prequal'!I40 -> 0 | ... V8: ='BDO Prequal'!K40 -> 0
B9: {=_xlfn.LET(_xlpm.visRows,_xlfn._xlws.FILTER(ROW($M$6:$M$22),$N$6:$N$22<>0),_xlpm.allRows,_xlfn.VSTACK(_xlpm.visRows,23,24),_xlpm.pos,ROW()-5,IF(_xlpm.pos<=ROWS(_xlpm.allRows),INDEX($M:$M,INDEX(_xlpm.allRows,_xlpm.pos)),""))} -> Working Capital - Pre Opening | C9: {=_xlfn.LET(_xlpm.visRows,_xlfn._xlws.FILTER(ROW($M$6:$M$22),$N$6:$N$22<>0),_xlpm.allRows,_xlfn.VSTACK(_xlpm.visRows,23,24),_xlpm.pos,ROW()-5,IF(_xlpm.pos>ROWS(_xlpm.allRows),"",_xlfn.LET(_xlpm.rn,INDEX(_xlpm.allRows,_xlpm.pos),_xlpm.val,INDEX($N:$N,_xlpm.rn),IF(INDEX($M:$M,_xlpm.rn)="Percentages",IF(_xlpm.val=0,"-",TEXT(_xlpm.val,"0%")),_xlpm.val))))} -> 77000 | D9: {=_xlfn.LET(_xlpm.visRows,_xlfn._xlws.FILTER(ROW($M$6:$M$22),$N$6:$N$22<>0),_xlpm.allRows,_xlfn.VSTACK(_xlpm.visRows,23,24),_xlpm.pos,ROW()-5,IF(_xlpm.pos>ROWS(_xlpm.allRows),"",_xlfn.LET(_xlpm.rn,INDEX(_xlpm.allRows,_xlpm.pos),_xlpm.val,INDEX($O:$O,_xlpm.rn),IF(INDEX($M:$M,_xlpm.rn)="Percentages",IF(_xlpm.val=0,"-",TEXT(_xlpm.val,"0%")),_xlpm.val))))} -> 77000 | E9: {=_xlfn.LET(_xlpm.visRows,_xlfn._xlws.FILTER(ROW($M$6:$M$22),$N$6:$N$22<>0),_xlpm.allRows,_xlfn.VSTACK(_xlpm.visRows,23,24),_xlpm.pos,ROW()-5,IF(_xlpm.pos>ROWS(_xlpm.allRows),"",_xlfn.LET(_xlpm.rn,INDEX(_xlpm.allRows,_xlpm.pos),_xlpm.val,INDEX($P:$P,_xlpm.rn),IF(INDEX($M:$M,_xlpm.rn)="Percentages",IF(_xlpm.val=0,"-",TEXT(_xlpm.val,"0%")),_xlpm.val))))} -> 0 | F9: {=_xlfn.LET(_xlpm.visRows,_xlfn._xlws.FILTER(ROW($M$6:$M$22),$N$6:$N$22<>0),_xlpm.allRows,_xlfn.VSTACK(_xlpm.visRows,23,24),_xlpm.pos,ROW()-5,IF(_xlpm.pos>ROWS(_xlpm.allRows),"",_xlfn.LET(_xlpm.rn,INDEX(_xlpm.allRows,_xlpm.pos),_xlpm.val,INDEX($Q:$Q,_xlpm.rn),IF(INDEX($M:$M,_xlpm.rn)="Percentages",IF(_xlpm.val=0,"-",TEXT(_xlpm.val,"0%")),_xlpm.val))))} -> 0 | G9: {=_xlfn.LET(_xlpm.visRows,_xlfn._xlws.FILTER(ROW($M$6:$M$22),$N$6:$N$22<>0),_xlpm.allRows,_xlfn.VSTACK(_xlpm.visRows,23,24),_xlpm.pos,ROW()-5,IF(_xlpm.pos>ROWS(_xlpm.allRows),"",_xlfn.LET(_xlpm.rn,INDEX(_xlpm.allRows,_xlpm.pos),_xlpm.val,INDEX($R:$R,_xlpm.rn),IF(INDEX($M:$M,_xlpm.rn)="Percentages",IF(_xlpm.val=0,"-",TEXT(_xlpm.val,"0%")),_xlpm.val))))} -> 0 | H9: {=_xlfn.LET(_xlpm.visRows,_xlfn._xlws.FILTER(ROW($M$6:$M$22),$N$6:$N$22<>0),_xlpm.allRows,_xlfn.VSTACK(_xlpm.visRows,23,24),_xlpm.pos,ROW()-5,IF(_xlpm.pos>ROWS(_xlpm.allRows),"",_xlfn.LET(_xlpm.rn,INDEX(_xlpm.allRows,_xlpm.pos),_xlpm.val,INDEX($S:$S,_xlpm.rn),IF(INDEX($M:$M,_xlpm.rn)="Percentages",IF(_xlpm.val=0,"-",TEXT(_xlpm.val,"0%")),_xlpm.val))))} -> 0 | I9: {=_xlfn.LET(_xlpm.visRows,_xlfn._xlws.FILTER(ROW($M$6:$M$22),$N$6:$N$22<>0),_xlpm.allRows,_xlfn.VSTACK(_xlpm.visRows,23,24),_xlpm.pos,ROW()-5,IF(_xlpm.pos>ROWS(_xlpm.allRows),"",_xlfn.LET(_xlpm.rn,INDEX(_xlpm.allRows,_xlpm.pos),_xlpm.val,INDEX($T:$T,_xlpm.rn),IF(INDEX($M:$M,_xlpm.rn)="Percentages",IF(_xlpm.val=0,"-",TEXT(_xlpm.val,"0%")),_xlpm.val))))} -> 0 | J9: {=_xlfn.LET(_xlpm.visRows,_xlfn._xlws.FILTER(ROW($M$6:$M$22),$N$6:$N$22<>0),_xlpm.allRows,_xlfn.VSTACK(_xlpm.visRows,23,24),_xlpm.pos,ROW()-5,IF(_xlpm.pos>ROWS(_xlpm.allRows),"",_xlfn.LET(_xlpm.rn,INDEX(_xlpm.allRows,_xlpm.pos),_xlpm.val,INDEX($U:$U,_xlpm.rn),IF(INDEX($M:$M,_xlpm.rn)="Percentages",IF(_xlpm.val=0,"-",TEXT(_xlpm.val,"0%")),_xlpm.val))))} -> 0 | K9: {=_xlfn.LET(_xlpm.visRows,_xlfn._xlws.FILTER(ROW($M$6:$M$22),$N$6:$N$22<>0),_xlpm.allRows,_xlfn.VSTACK(_xlpm.visRows,23,24),_xlpm.pos,ROW()-5,IF(_xlpm.pos>ROWS(_xlpm.allRows),"",_xlfn.LET(_xlpm.rn,INDEX(_xlpm.allRows,_xlpm.pos),_xlpm.val,INDEX($V:$V,_xlpm.rn),IF(INDEX($M:$M,_xlpm.rn)="Percentages",IF(_xlpm.val=0,"-",TEXT(_xlpm.val,"0%")),_xlpm.val))))} -> 0 | M9: ='BDO Prequal'!B41 -> Machinery & Equipment | N9: ='BDO Prequal'!C41 -> 366285 | O9: ='BDO Prequal'!D41 -> 366285 | P9: ='BDO Prequal'!E41 -> 0 | Q9: ='BDO Prequal'!F41 -> 0 | R9: ='BDO Prequal'!G41 -> 0 | S9: ='BDO Prequal'!H41 -> 0 | T9: ='BDO Prequal'!I41 -> 0 | ... V9: ='BDO Prequal'!K41 -> 0
B10: {=_xlfn.LET(_xlpm.visRows,_xlfn._xlws.FILTER(ROW($M$6:$M$22),$N$6:$N$22<>0),_xlpm.allRows,_xlfn.VSTACK(_xlpm.visRows,23,24),_xlpm.pos,ROW()-5,IF(_xlpm.pos<=ROWS(_xlpm.allRows),INDEX($M:$M,INDEX(_xlpm.allRows,_xlpm.pos)),""))} -> Business Acquisition | C10: {=_xlfn.LET(_xlpm.visRows,_xlfn._xlws.FILTER(ROW($M$6:$M$22),$N$6:$N$22<>0),_xlpm.allRows,_xlfn.VSTACK(_xlpm.visRows,23,24),_xlpm.pos,ROW()-5,IF(_xlpm.pos>ROWS(_xlpm.allRows),"",_xlfn.LET(_xlpm.rn,INDEX(_xlpm.allRows,_xlpm.pos),_xlpm.val,INDEX($N:$N,_xlpm.rn),IF(INDEX($M:$M,_xlpm.rn)="Percentages",IF(_xlpm.val=0,"-",TEXT(_xlpm.val,"0%")),_xlpm.val))))} -> 2219000 | D10: {=_xlfn.LET(_xlpm.visRows,_xlfn._xlws.FILTER(ROW($M$6:$M$22),$N$6:$N$22<>0),_xlpm.allRows,_xlfn.VSTACK(_xlpm.visRows,23,24),_xlpm.pos,ROW()-5,IF(_xlpm.pos>ROWS(_xlpm.allRows),"",_xlfn.LET(_xlpm.rn,INDEX(_xlpm.allRows,_xlpm.pos),_xlpm.val,INDEX($O:$O,_xlpm.rn),IF(INDEX($M:$M,_xlpm.rn)="Percentages",IF(_xlpm.val=0,"-",TEXT(_xlpm.val,"0%")),_xlpm.val))))} -> 225000 | E10: {=_xlfn.LET(_xlpm.visRows,_xlfn._xlws.FILTER(ROW($M$6:$M$22),$N$6:$N$22<>0),_xlpm.allRows,_xlfn.VSTACK(_xlpm.visRows,23,24),_xlpm.pos,ROW()-5,IF(_xlpm.pos>ROWS(_xlpm.allRows),"",_xlfn.LET(_xlpm.rn,INDEX(_xlpm.allRows,_xlpm.pos),_xlpm.val,INDEX($P:$P,_xlpm.rn),IF(INDEX($M:$M,_xlpm.rn)="Percentages",IF(_xlpm.val=0,"-",TEXT(_xlpm.val,"0%")),_xlpm.val))))} -> 324000 | F10: {=_xlfn.LET(_xlpm.visRows,_xlfn._xlws.FILTER(ROW($M$6:$M$22),$N$6:$N$22<>0),_xlpm.allRows,_xlfn.VSTACK(_xlpm.visRows,23,24),_xlpm.pos,ROW()-5,IF(_xlpm.pos>ROWS(_xlpm.allRows),"",_xlfn.LET(_xlpm.rn,INDEX(_xlpm.allRows,_xlpm.pos),_xlpm.val,INDEX($Q:$Q,_xlpm.rn),IF(INDEX($M:$M,_xlpm.rn)="Percentages",IF(_xlpm.val=0,"-",TEXT(_xlpm.val,"0%")),_xlpm.val))))} -> 0 | G10: {=_xlfn.LET(_xlpm.visRows,_xlfn._xlws.FILTER(ROW($M$6:$M$22),$N$6:$N$22<>0),_xlpm.allRows,_xlfn.VSTACK(_xlpm.visRows,23,24),_xlpm.pos,ROW()-5,IF(_xlpm.pos>ROWS(_xlpm.allRows),"",_xlfn.LET(_xlpm.rn,INDEX(_xlpm.allRows,_xlpm.pos),_xlpm.val,INDEX($R:$R,_xlpm.rn),IF(INDEX($M:$M,_xlpm.rn)="Percentages",IF(_xlpm.val=0,"-",TEXT(_xlpm.val,"0%")),_xlpm.val))))} -> 1350000 | H10: {=_xlfn.LET(_xlpm.visRows,_xlfn._xlws.FILTER(ROW($M$6:$M$22),$N$6:$N$22<>0),_xlpm.allRows,_xlfn.VSTACK(_xlpm.visRows,23,24),_xlpm.pos,ROW()-5,IF(_xlpm.pos>ROWS(_xlpm.allRows),"",_xlfn.LET(_xlpm.rn,INDEX(_xlpm.allRows,_xlpm.pos),_xlpm.val,INDEX($S:$S,_xlpm.rn),IF(INDEX($M:$M,_xlpm.rn)="Percentages",IF(_xlpm.val=0,"-",TEXT(_xlpm.val,"0%")),_xlpm.val))))} -> 320000 | I10: {=_xlfn.LET(_xlpm.visRows,_xlfn._xlws.FILTER(ROW($M$6:$M$22),$N$6:$N$22<>0),_xlpm.allRows,_xlfn.VSTACK(_xlpm.visRows,23,24),_xlpm.pos,ROW()-5,IF(_xlpm.pos>ROWS(_xlpm.allRows),"",_xlfn.LET(_xlpm.rn,INDEX(_xlpm.allRows,_xlpm.pos),_xlpm.val,INDEX($T:$T,_xlpm.rn),IF(INDEX($M:$M,_xlpm.rn)="Percentages",IF(_xlpm.val=0,"-",TEXT(_xlpm.val,"0%")),_xlpm.val))))} -> 0 | J10: {=_xlfn.LET(_xlpm.visRows,_xlfn._xlws.FILTER(ROW($M$6:$M$22),$N$6:$N$22<>0),_xlpm.allRows,_xlfn.VSTACK(_xlpm.visRows,23,24),_xlpm.pos,ROW()-5,IF(_xlpm.pos>ROWS(_xlpm.allRows),"",_xlfn.LET(_xlpm.rn,INDEX(_xlpm.allRows,_xlpm.pos),_xlpm.val,INDEX($U:$U,_xlpm.rn),IF(INDEX($M:$M,_xlpm.rn)="Percentages",IF(_xlpm.val=0,"-",TEXT(_xlpm.val,"0%")),_xlpm.val))))} -> 0 | K10: {=_xlfn.LET(_xlpm.visRows,_xlfn._xlws.FILTER(ROW($M$6:$M$22),$N$6:$N$22<>0),_xlpm.allRows,_xlfn.VSTACK(_xlpm.visRows,23,24),_xlpm.pos,ROW()-5,IF(_xlpm.pos>ROWS(_xlpm.allRows),"",_xlfn.LET(_xlpm.rn,INDEX(_xlpm.allRows,_xlpm.pos),_xlpm.val,INDEX($V:$V,_xlpm.rn),IF(INDEX($M:$M,_xlpm.rn)="Percentages",IF(_xlpm.val=0,"-",TEXT(_xlpm.val,"0%")),_xlpm.val))))} -> 0 | M10: ='BDO Prequal'!B42 -> Furniture & Fixtures | N10: ='BDO Prequal'!C42 -> 600000 | O10: ='BDO Prequal'!D42 -> 0 | P10: ='BDO Prequal'!E42 -> 0 | Q10: ='BDO Prequal'!F42 -> 600000 | R10: ='BDO Prequal'!G42 -> 0 | S10: ='BDO Prequal'!H42 -> 0 | T10: ='BDO Prequal'!I42 -> 0 | ... V10: ='BDO Prequal'!K42 -> 0
