Workbook
Name Beg_Bal: #REF!
Name Beg_Bal: #REF!
Name Cum_Int: #REF!
Name Data: #REF!
Name DisbursementType: #REF!
Name DisbursementType: #REF!
Name End_Bal: #REF!
Name End_Bal: #REF!
Name EXPENSES: #REF!
Name EXPENSES: #REF!
Name Extra_Pay: #REF!
Name Extra_Pay: #REF!
Name Full_Print: #REF!
Name Full_Print: #REF!
Name Header_Row: _xlfn.ROW(#REF!)
Name Header_Row: _xlfn.ROW(#REF!)
Name Int: #REF!
Name Int: #REF!
Name Interest_Rate: #REF!
Name Interest_Rate: #REF!
Name Last_Row: IF(#REF!_Entered,Header_Row+#REF!_of_Payments,Header_Row)
Name Last_Row: IF(Scores!Values_Entered,Scores!Header_Row+Scores!Number_of_Payments,Scores!Header_Row)
Name Last_Row: IF(Values_Entered,Header_Row+Number_of_Payments,Header_Row)
Name Loan_Amount: #REF!
Name Loan_Amount: #REF!
Name Loan_Start: #REF!
Name Loan_Start: #REF!
Name Loan_Years: #REF!
Name Loan_Years: #REF!
Name MajorExpensesList: #REF!
Name MajorExpensesList: #REF!
Name Num_Pmt_Per_Year: #REF!
Name Num_Pmt_Per_Year: #REF!
Name Number_of_Payments: MATCH(0.01,End_Bal,-1)+1
Name Number_of_Payments: MATCH(0.01,Scores!End_Bal,-1)+1
Name Number_of_Payments: MATCH(0.01,End_Bal,-1)+1
Name Pay_Date: #REF!
Name Pay_Num: #REF!
Name Pay_Num: #REF!
Name Payment_Date: "DATE(YEAR(#REF!_Start);MONTH(#REF!_Start)+Payment_Number;DAY(#REF!_Start))"
Name Payment_Date: DATE(YEAR(Scores!Loan_Start),MONTH(Scores!Loan_Start)+Payment_Number,DAY(Scores!Loan_Start))
Name Payment_Date: DATE(YEAR(Loan_Start),MONTH(Loan_Start)+Payment_Number,DAY(Loan_Start))
Name Periodic_rate: Annual_interest_rate/Payments_per_year
Name Periodic_rate: Annual_interest_rate/Payments_per_year
Name Periodic_rate: Annual_interest_rate/Payments_per_year
Name Princ: #REF!
Name Princ: #REF!
Name Print_Area_Reset: OFFSET(Full_Print,0,0,#REF!_Row)
Name Print_Area_Reset: OFFSET(Scores!Full_Print,0,0,Scores!Last_Row)
Name Print_Area_Reset: OFFSET(Full_Print,0,0,Last_Row)
Name Sched_Pay: #REF!
Name Sched_Pay: #REF!
Name Scheduled_Extra_Payments: #REF!
Name Scheduled_Extra_Payments: #REF!
Name Scheduled_Interest_Rate: #REF!
Name Scheduled_Monthly_Payment: #REF!
Name Scheduled_Monthly_Payment: #REF!
Name Total_Interest: #REF!
Name Total_Pay: #REF!
Name Total_Pay: #REF!

Sheet Proposed Changes
B1: Tab 1 | C1: Tab 2 | D1: Tab 3 | E1: Tab 4 | F1: Tab 5 | G1: Tab 6 | H1: Tab 7 | I1: Tab 8
B2: Project Structure | C2: Sources & Uses | D2: Financials | E2: PFS | F2: Debt and Liquidity? | G2: Affiliates? | H2: Scores
B4: Sections
B5: Project Description | C5: Sources & Uses | D5: Income Statement | E5: 4) Personal Financial Analysis | F5: Global Debt Coverage? | G5: Income Statement Spreads | H5: Scores | I5: Charts?
B6: Loan Terms | C6: Total Project Cost | D6: Business Debt Schedule | F6: Business Debt Schedule ?
B7: Sources & Uses | C7: Closing Cost | F7: Liquidity Review?
C8: Misc Closing Cost
B10: Ben's Sections:
B11: 1) Loan Structure
B12: Loan Terms
B13: 2) Sources and Uses
B14: Liquidity Review
B15: 3) Income Statement
B16: Global Debt Coverage
B17: Business Debt Schedule
B18: 4) Affiliate Analysis
B19: Income Statement Spreads
B21: 4) Personal Financial Analysis
B22: 5) Collateral Summary

Sheet 1. Project Structure
B4: Project Description
B9: Loan Terms | M9: Loan Terms
C11: T Bank Loan | D11: Borrower | E11: Seller Note | F11: 3rd Party | N11: T Bank 7(a) | O11: Borrower | P11: Seller Note | Q11: T Bank 504 | R11: CDC 504
B12: Product Type | I12: SBA Gty % | J12: 0.75 | M12: Base Rate | N12: 0.075 | P12: 0.08 | Q12: 0.075 | R12: 0.0624
B13: Loan Amount/Injection | C13: =C45 -> 0 | D13: =D45 -> 0 | E13: =E45 -> 0 | F13: 0 | I13: Est. Appraisal Costs | J13: =SUM('2. Sources and Uses'!E43,'2. Sources and Uses'!E44,'2. Sources and Uses'!E45,'2. Sources and Uses'!E49) -> 0 | M13: Spread | N13: 0.015 | P13: 0 | Q13: 0.015 | R13: 0
B14: Base Rate | C14: 0.075 | E14: 0.08 | F14: 0.0624 | I14: Est. Environmental Report Costs | J14: =SUM('2. Sources and Uses'!E46,'2. Sources and Uses'!E47) -> 0 | M14: Indicative Rate | N14: =N12+N13 -> 0.09 | P14: =P12+P13 -> 0.08 | Q14: =Q12+Q13 -> 0.09 | R14: =R12+R13 -> 0.0624
B15: Spread | C15: 0.015 | E15: 0 | F15: 0 | I15: Packaging Fee | J15: =SUM('2. Sources and Uses'!E39) -> 2500 | M15: Amortization Basis | N15: Actual/365 | Q15: Actual/365
B16: Indicative Rate | C16: =C14+C15 -> 0.09 | E16: =E14+E15 -> 0.08 | F16: =F14+F15 -> 0.0624 | I16: Survey | J16: =SUM('2. Sources and Uses'!E42) -> 0 | M16: Term (years) | N16: 10 | P16: 10 | Q16: 10 | R16: 25
B17: Amortization Basis | C17: Actual/365 | I17: Business Valuation | J17: =SUM('2. Sources and Uses'!E48) -> 0 | M17: Amortization (mos) | N17: =N16*12 -> 120 | P17: =P16*12 -> 120 | Q17: =Q16*12 -> 120 | R17: =R16*12 -> 300
B18: Term (years) | C18: 10 | E18: 10 | F18: 25 | I18: Title / Escrow / Closing | J18: =SUM('2. Sources and Uses'!E40,'2. Sources and Uses'!E41) -> 0 | M18: Est Const Period (mths) | N18: 0
B19: Amortization (mos) | C19: =C18*12 -> 120 | E19: =E18*12 -> 120 | F19: =F18*12 -> 300 | I19: SBA GTY Fee | J19: ='2. Sources and Uses'!D80 -> 0
B20: Estimated Payment | C20: =IFERROR(INDEX('2. Sources and Uses'!K92:K94,MATCH($C$17,#REF!,0)),0) -> 0 | E20: =IFERROR(PMT(E16/12,E19,-E13),0) -> 0 | F20: =IFERROR(PMT(F16/12,F19,-F13),0) -> 0 | I20: Other Costs | J20: =E55-SUM(J13:K18) -> -2500
B21: Est Const Period (mths) | C21: 0 | I21: Total SBA Fees & Closing Costs | J21: =SUM(J13:K20) -> 0
B22: Are there funded SBA Loans in last 90 days? | D22: Amount? | E22: 0 | F22: Guarantee %? | G22: 0
B25: Sources and Uses of Proceeds | M25: Sources and Uses of Proceeds - 504
C27: T Bank Loan | D27: Borrower | E27: Seller Note | F27: 3rd Party | G27: Total | H27: SBA Term (yrs) | I27: % | J27: Wgt | N27: T Bank 504 | O27: Borrower | P27: Seller Note | Q27: CDC 504 | R27: Total
B28: Direct Project Costs | M28: Direct Project Costs
B29: Real Estate Acquisition | C29: ='2. Sources and Uses'!C6 -> 0 | D29: ='2. Sources and Uses'!D6 -> 0 | E29: ='2. Sources and Uses'!E6 -> 0 | F29: ='2. Sources and Uses'!F6 -> 0 | G29: ='2. Sources and Uses'!G6 -> 0 | H29: ='2. Sources and Uses'!H6 -> 25 | I29: ='2. Sources and Uses'!I6 -> 0 | J29: ='2. Sources and Uses'!J6 -> 0 | M29: Real Estate Acquisition | N29: ='2. Sources and Uses'!N6 -> 0 | O29: ='2. Sources and Uses'!O6 -> 0 | P29: ='2. Sources and Uses'!P6 -> 0 | Q29: ='2. Sources and Uses'!Q6 -> 0 | R29: ='2. Sources and Uses'!R6 -> 0
B30: Debt Refi - CRE | C30: ='2. Sources and Uses'!C7 -> 0 | D30: ='2. Sources and Uses'!D7 -> 0 | E30: ='2. Sources and Uses'!E7 -> 0 | F30: ='2. Sources and Uses'!F7 -> 0 | G30: ='2. Sources and Uses'!G7 -> 0 | H30: ='2. Sources and Uses'!H7 -> 25 | I30: ='2. Sources and Uses'!I7 -> 0 | J30: ='2. Sources and Uses'!J7 -> 0 | M30: Debt Refi - CRE | N30: ='2. Sources and Uses'!N7 -> 0 | O30: ='2. Sources and Uses'!O7 -> 0 | P30: ='2. Sources and Uses'!P7 -> 0 | Q30: ='2. Sources and Uses'!Q7 -> 0 | R30: ='2. Sources and Uses'!R7 -> 0
B31: Debt Refi - Non-CRE | C31: ='2. Sources and Uses'!C8 -> 0 | D31: ='2. Sources and Uses'!D8 -> 0 | E31: ='2. Sources and Uses'!E8 -> 0 | F31: ='2. Sources and Uses'!F8 -> 0 | G31: ='2. Sources and Uses'!G8 -> 0 | H31: ='2. Sources and Uses'!H8 -> 10 | I31: ='2. Sources and Uses'!I8 -> 0 | J31: ='2. Sources and Uses'!J8 -> 0 | M31: Debt Refi - Non-CRE | N31: ='2. Sources and Uses'!N8 -> 0 | O31: ='2. Sources and Uses'!O8 -> 0 | P31: ='2. Sources and Uses'!P8 -> 0 | Q31: ='2. Sources and Uses'!Q8 -> 0 | R31: ='2. Sources and Uses'!R8 -> 0
B32: Machinery & Equipment | C32: ='2. Sources and Uses'!C9 -> 0 | D32: ='2. Sources and Uses'!D9 -> 0 | E32: ='2. Sources and Uses'!E9 -> 0 | F32: ='2. Sources and Uses'!F9 -> 0 | G32: ='2. Sources and Uses'!G9 -> 0 | H32: ='2. Sources and Uses'!H9 -> 10 | I32: ='2. Sources and Uses'!I9 -> 0 | J32: ='2. Sources and Uses'!J9 -> 0 | M32: Machinery & Equipment | N32: ='2. Sources and Uses'!N9 -> 0 | O32: ='2. Sources and Uses'!O9 -> 0 | P32: ='2. Sources and Uses'!P9 -> 0 | Q32: ='2. Sources and Uses'!Q9 -> 0 | R32: ='2. Sources and Uses'!R9 -> 0
B33: Furniture & Fixtures (TIs) | C33: ='2. Sources and Uses'!C10 -> 0 | D33: ='2. Sources and Uses'!D10 -> 0 | E33: ='2. Sources and Uses'!E10 -> 0 | F33: ='2. Sources and Uses'!F10 -> 0 | G33: ='2. Sources and Uses'!G10 -> 0 | H33: ='2. Sources and Uses'!H10 -> 10 | I33: ='2. Sources and Uses'!I10 -> 0 | J33: ='2. Sources and Uses'!J10 -> 0 | M33: Furniture & Fixtures (TIs) | N33: ='2. Sources and Uses'!N10 -> 0 | O33: ='2. Sources and Uses'!O10 -> 0 | P33: ='2. Sources and Uses'!P10 -> 0 | Q33: ='2. Sources and Uses'!Q10 -> 0 | R33: ='2. Sources and Uses'!R10 -> 0
B34: Inventory | C34: ='2. Sources and Uses'!C11 -> 0 | D34: ='2. Sources and Uses'!D11 -> 0 | E34: ='2. Sources and Uses'!E11 -> 0 | F34: ='2. Sources and Uses'!F11 -> 0 | G34: ='2. Sources and Uses'!G11 -> 0 | H34: ='2. Sources and Uses'!H11 -> 10 | I34: ='2. Sources and Uses'!I11 -> 0 | J34: ='2. Sources and Uses'!J11 -> 0 | M34: Inventory | N34: ='2. Sources and Uses'!N11 -> 0 | O34: ='2. Sources and Uses'!O11 -> 0 | P34: ='2. Sources and Uses'!P11 -> 0 | Q34: ='2. Sources and Uses'!Q11 -> 0 | R34: ='2. Sources and Uses'!R11 -> 0
B35: Working Capital | C35: ='2. Sources and Uses'!C12 -> 0 | D35: ='2. Sources and Uses'!D12 -> 0 | E35: ='2. Sources and Uses'!E12 -> 0 | F35: ='2. Sources and Uses'!F12 -> 0 | G35: ='2. Sources and Uses'!G12 -> 0 | H35: ='2. Sources and Uses'!H12 -> 10 | I35: ='2. Sources and Uses'!I12 -> 0 | J35: ='2. Sources and Uses'!J12 -> 0 | M35: Working Capital | N35: ='2. Sources and Uses'!N12 -> 0 | O35: ='2. Sources and Uses'!O12 -> 0 | P35: ='2. Sources and Uses'!P12 -> 0 | Q35: ='2. Sources and Uses'!Q12 -> 0 | R35: ='2. Sources and Uses'!R12 -> 0
B36: Working Capital - Pre Opening | C36: ='2. Sources and Uses'!C13 -> 0 | D36: ='2. Sources and Uses'!D13 -> 0 | E36: ='2. Sources and Uses'!E13 -> 0 | F36: ='2. Sources and Uses'!F13 -> 0 | G36: ='2. Sources and Uses'!G13 -> 0 | H36: ='2. Sources and Uses'!H13 -> 10 | I36: ='2. Sources and Uses'!I13 -> 0 | J36: ='2. Sources and Uses'!J13 -> 0 | M36: Working Capital - Pre Opening | N36: ='2. Sources and Uses'!N13 -> 0 | O36: ='2. Sources and Uses'!O13 -> 0 | P36: ='2. Sources and Uses'!P13 -> 0 | Q36: ='2. Sources and Uses'!Q13 -> 0 | R36: ='2. Sources and Uses'!R13 -> 0
B37: Business Acquisition | C37: ='2. Sources and Uses'!C14 -> 0 | D37: ='2. Sources and Uses'!D14 -> 0 | E37: ='2. Sources and Uses'!E14 -> 0 | F37: ='2. Sources and Uses'!F14 -> 0 | G37: ='2. Sources and Uses'!G14 -> 0 | H37: ='2. Sources and Uses'!H14 -> 10 | I37: ='2. Sources and Uses'!I14 -> 0 | J37: ='2. Sources and Uses'!J14 -> 0 | M37: Business Acquisition | N37: ='2. Sources and Uses'!N14 -> 0 | O37: ='2. Sources and Uses'!O14 -> 0 | P37: ='2. Sources and Uses'!P14 -> 0 | Q37: ='2. Sources and Uses'!Q14 -> 0 | R37: ='2. Sources and Uses'!R14 -> 0
B38: Franchise Fees | C38: ='2. Sources and Uses'!C15 -> 0 | D38: ='2. Sources and Uses'!D15 -> 0 | E38: ='2. Sources and Uses'!E15 -> 0 | F38: ='2. Sources and Uses'!F15 -> 0 | G38: ='2. Sources and Uses'!G15 -> 0 | H38: ='2. Sources and Uses'!H15 -> 10 | I38: ='2. Sources and Uses'!I15 -> 0 | J38: ='2. Sources and Uses'!J15 -> 0 | M38: Franchise Fees | N38: ='2. Sources and Uses'!N15 -> 0 | O38: ='2. Sources and Uses'!O15 -> 0 | P38: ='2. Sources and Uses'!P15 -> 0 | Q38: ='2. Sources and Uses'!Q15 -> 0 | R38: ='2. Sources and Uses'!R15 -> 0
B39: Construction Hard Costs | C39: ='2. Sources and Uses'!C16 -> 0 | D39: ='2. Sources and Uses'!D16 -> 0 | E39: ='2. Sources and Uses'!E16 -> 0 | F39: ='2. Sources and Uses'!F16 -> 0 | G39: ='2. Sources and Uses'!G16 -> 0 | H39: ='2. Sources and Uses'!H16 -> 25 | I39: ='2. Sources and Uses'!I16 -> 0 | J39: ='2. Sources and Uses'!J16 -> 0 | M39: Construction Hard Costs | N39: ='2. Sources and Uses'!N16 -> 0 | O39: ='2. Sources and Uses'!O16 -> 0 | P39: ='2. Sources and Uses'!P16 -> 0 | Q39: ='2. Sources and Uses'!Q16 -> 0 | R39: ='2. Sources and Uses'!R16 -> 0
B40: Interim Interest Reserve | C40: ='2. Sources and Uses'!C17 -> 0 | D40: ='2. Sources and Uses'!D17 -> 0 | E40: ='2. Sources and Uses'!E17 -> 0 | F40: ='2. Sources and Uses'!F17 -> 0 | G40: ='2. Sources and Uses'!G17 -> 0 | H40: ='2. Sources and Uses'!H17 -> 25 | I40: ='2. Sources and Uses'!I17 -> 0 | J40: ='2. Sources and Uses'!J17 -> 0 | K40: Const Contigency | M40: Interim Interest Reserve | N40: ='2. Sources and Uses'!N17 -> 0 | O40: ='2. Sources and Uses'!O17 -> 0 | P40: ='2. Sources and Uses'!P17 -> 0 | Q40: ='2. Sources and Uses'!Q17 -> 0 | R40: ='2. Sources and Uses'!R17 -> 0 | S40: Const Contigency
B41: Construction Contingency | C41: ='2. Sources and Uses'!C18 -> 0 | D41: ='2. Sources and Uses'!D18 -> 0 | E41: ='2. Sources and Uses'!E18 -> 0 | F41: ='2. Sources and Uses'!F18 -> 0 | G41: ='2. Sources and Uses'!G18 -> 0 | H41: ='2. Sources and Uses'!H18 -> 25 | I41: ='2. Sources and Uses'!I18 -> 0 | J41: ='2. Sources and Uses'!J18 -> 0 | K41: 0.1 | M41: Construction Contingency | N41: ='2. Sources and Uses'!N18 -> 0 | O41: ='2. Sources and Uses'!O18 -> 0 | P41: ='2. Sources and Uses'!P18 -> 0 | Q41: ='2. Sources and Uses'!Q18 -> 0 | R41: ='2. Sources and Uses'!R18 -> 0 | S41: ='2. Sources and Uses'!S18 -> 0.1
B42: Other Construction Soft Costs | C42: ='2. Sources and Uses'!C19 -> 0 | D42: ='2. Sources and Uses'!D19 -> 0 | E42: ='2. Sources and Uses'!E19 -> 0 | F42: ='2. Sources and Uses'!F19 -> 0 | G42: ='2. Sources and Uses'!G19 -> 0 | H42: ='2. Sources and Uses'!H19 -> 25 | I42: ='2. Sources and Uses'!I19 -> 0 | J42: ='2. Sources and Uses'!J19 -> 0 | M42: Other Construction Soft Costs | N42: ='2. Sources and Uses'!N19 -> 0 | O42: ='2. Sources and Uses'!O19 -> 0 | P42: ='2. Sources and Uses'!P19 -> 0 | Q42: ='2. Sources and Uses'!Q19 -> 0 | R42: ='2. Sources and Uses'!R19 -> 0
B43: Closing Costs | C43: ='2. Sources and Uses'!C20 -> 0 | D43: ='2. Sources and Uses'!D20 -> 0 | E43: ='2. Sources and Uses'!E20 -> 0 | F43: ='2. Sources and Uses'!F20 -> 0 | G43: ='2. Sources and Uses'!G20 -> 0 | H43: ='2. Sources and Uses'!H20 -> 10 | I43: ='2. Sources and Uses'!I20 -> 0 | J43: ='2. Sources and Uses'!J20 -> 0 | M43: Closing Costs | N43: ='2. Sources and Uses'!N20 -> 0 | O43: ='2. Sources and Uses'!O20 -> 0 | P43: ='2. Sources and Uses'!P20 -> 0 | Q43: ='2. Sources and Uses'!Q20 -> 0 | R43: ='2. Sources and Uses'!R20 -> 0
B44: SBA Gty Fee | C44: ='2. Sources and Uses'!C21 -> 0 | D44: ='2. Sources and Uses'!D21 -> 0 | E44: ='2. Sources and Uses'!E21 | F44: ='2. Sources and Uses'!F21 | G44: ='2. Sources and Uses'!G21 -> 0 | H44: ='2. Sources and Uses'!H21 -> 10 | I44: ='2. Sources and Uses'!I21 -> 0 | J44: ='2. Sources and Uses'!J21 -> 0 | M44: SBA Gty Fee | N44: ='2. Sources and Uses'!N21 -> 0 | O44: ='2. Sources and Uses'!O21 -> 0 | P44: ='2. Sources and Uses'!P21 | Q44: ='2. Sources and Uses'!Q21 | R44: ='2. Sources and Uses'!R21
C45: ='2. Sources and Uses'!C22 -> 0 | D45: ='2. Sources and Uses'!D22 -> 0 | E45: ='2. Sources and Uses'!E22 -> 0 | F45: ='2. Sources and Uses'!F22 -> 0 | G45: ='2. Sources and Uses'!G22 -> 0 | H45: ='2. Sources and Uses'!H22 | I45: ='2. Sources and Uses'!I22 -> Weighted Term | J45: ='2. Sources and Uses'!J22 -> 0 | N45: ='2. Sources and Uses'!N22 -> 0 | O45: ='2. Sources and Uses'!O22 -> 0 | P45: ='2. Sources and Uses'!P22 -> 0 | Q45: ='2. Sources and Uses'!Q22 -> 0 | R45: ='2. Sources and Uses'!R22 -> 0
C46: ='2. Sources and Uses'!C23 -> 0 | D46: ='2. Sources and Uses'!D23 -> 0 | E46: ='2. Sources and Uses'!E23 -> 0 | F46: ='2. Sources and Uses'!F23 -> 0 | G46: ='2. Sources and Uses'!G23 -> 0 | N46: ='2. Sources and Uses'!N23 -> 0 | O46: ='2. Sources and Uses'!O23 -> 0 | P46: ='2. Sources and Uses'!P23 -> 0 | Q46: ='2. Sources and Uses'!Q23 -> 0 | R46: ='2. Sources and Uses'!R23 -> 0

Sheet 2. Sources and Uses
B2: Sources and Uses of Proceeds | M2: Sources and Uses of Proceeds - 504
C4: T Bank Loan | D4: Borrower | E4: Seller Note | F4: 3rd Party | G4: Total | H4: SBA Term (yrs) | I4: % | J4: Wgt | N4: T Bank 504 | O4: Borrower | P4: Seller Note | Q4: CDC 504 | R4: Total
B5: Direct Project Costs | M5: Direct Project Costs
B6: Real Estate Acquisition | C6: =G6-SUM(D6:F6) -> 0 | D6: 0 | E6: 0 | F6: 0 | G6: 0 | H6: 25 | I6: =IF($C$22=0,0,C6/$C$22) -> 0 | J6: =H6*I6 -> 0 | M6: Real Estate Acquisition | N6: =R6-SUM(O6:Q6) -> 0 | O6: 0 | P6: 0 | Q6: 0 | R6: 0
B7: Debt Refi - CRE | C7: =G7-SUM(D7:F7) -> 0 | D7: 0 | E7: 0 | F7: 0 | G7: 0 | H7: 25 | I7: =IF($C$22=0,0,C7/$C$22) -> 0 | J7: =H7*I7 -> 0 | M7: Debt Refi - CRE | N7: =R7-SUM(O7:Q7) -> 0 | O7: 0 | P7: 0 | Q7: 0 | R7: 0
B8: Debt Refi - Non-CRE | C8: =G8-SUM(D8:F8) -> 0 | D8: 0 | E8: 0 | F8: 0 | G8: 0 | H8: 10 | I8: =IF($C$22=0,0,C8/$C$22) -> 0 | J8: =H8*I8 -> 0 | M8: Debt Refi - Non-CRE | N8: =R8-SUM(O8:Q8) -> 0 | O8: 0 | P8: 0 | Q8: 0 | R8: 0
B9: Machinery & Equipment | C9: =G9-SUM(D9:F9) -> 0 | D9: 0 | E9: 0 | F9: 0 | G9: 0 | H9: 10 | I9: =IF($C$22=0,0,C9/$C$22) -> 0 | J9: =H9*I9 -> 0 | M9: Machinery & Equipment | N9: =R9-SUM(O9:Q9) -> 0 | O9: 0 | P9: 0 | Q9: 0 | R9: 0
B10: Furniture & Fixtures (TIs) | C10: =G10-SUM(D10:F10) -> 0 | D10: 0 | E10: 0 | F10: 0 | G10: 0 | H10: 10 | I10: =IF($C$22=0,0,C10/$C$22) -> 0 | J10: =H10*I10 -> 0 | M10: Furniture & Fixtures (TIs) | N10: =R10-SUM(O10:Q10) -> 0 | O10: 0 | P10: 0 | Q10: 0 | R10: 0
B11: Inventory | C11: =G11-SUM(D11:F11) -> 0 | D11: 0 | E11: 0 | F11: 0 | G11: 0 | H11: 10 | I11: =IF($C$22=0,0,C11/$C$22) -> 0 | J11: =H11*I11 -> 0 | M11: Inventory | N11: =R11-SUM(O11:Q11) -> 0 | O11: 0 | P11: 0 | Q11: 0 | R11: 0
B12: Working Capital | C12: =G12-SUM(D12:F12) -> 0 | D12: 0 | E12: 0 | F12: 0 | G12: 0 | H12: 10 | I12: =IF($C$22=0,0,C12/$C$22) -> 0 | J12: =H12*I12 -> 0 | M12: Working Capital | N12: =R12-SUM(O12:Q12) -> 0 | O12: 0 | P12: 0 | Q12: 0 | R12: 0
B13: Working Capital - Pre Opening | C13: =G13-SUM(D13:F13) -> 0 | D13: 0 | E13: 0 | F13: 0 | G13: 0 | H13: 10 | I13: =IF($C$22=0,0,C13/$C$22) -> 0 | J13: =H13*I13 -> 0 | M13: Working Capital - Pre Opening | N13: =R13-SUM(O13:Q13) -> 0 | O13: 0 | P13: 0 | Q13: 0 | R13: 0
B14: Business Acquisition | C14: =G14-SUM(D14:F14) -> 0 | D14: 0 | E14: 0 | F14: 0 | G14: 0 | H14: 10 | I14: =IF($C$22=0,0,C14/$C$22) -> 0 | J14: =H14*I14 -> 0 | M14: Business Acquisition | N14: =R14-SUM(O14:Q14) -> 0 | O14: 0 | P14: 0 | Q14: 0 | R14: 0
B15: Franchise Fees | C15: =G15-SUM(D15:F15) -> 0 | D15: 0 | E15: 0 | F15: 0 | G15: 0 | H15: 10 | I15: =IF($C$22=0,0,C15/$C$22) -> 0 | J15: =H15*I15 -> 0 | M15: Franchise Fees | N15: =R15-SUM(O15:Q15) -> 0 | O15: 0 | P15: 0 | Q15: 0 | R15: 0
B16: Construction Hard Costs | C16: =G16-SUM(D16:F16) -> 0 | D16: 0 | E16: 0 | F16: 0 | G16: 0 | H16: 25 | I16: =IF($C$22=0,0,C16/$C$22) -> 0 | J16: =H16*I16 -> 0 | M16: Construction Hard Costs | N16: =R16-SUM(O16:Q16) -> 0 | O16: 0 | P16: 0 | Q16: 0 | R16: 0
B17: Interim Interest Reserve | C17: 0 | D17: =G17-C17 -> 0 | E17: 0 | F17: 0 | G17: =ROUND(((C6+F6)*'1. Project Structure'!C16/12)*'1. Project Structure'!C21+((C22-C6+F22-F6)*'1. Project Structure'!C16*0.6/12)*'1. Project Structure'!C21,0) -> 0 | H17: 25 | I17: =IF($C$22=0,0,C17/$C$22) -> 0 | J17: =H17*I17 -> 0 | K17: Const Contigency | M17: Interim Interest Reserve | N17: 0 | O17: =R17-N17 -> 0 | P17: 0 | Q17: 0 | R17: =ROUND(((N6+Q6)*'1. Project Structure'!N14/12)*'1. Project Structure'!N18+((N22-N6+Q22-Q6)*'1. Project Structure'!N14*0.6/12)*'1. Project Structure'!N18,0) -> 0 | S17: Const Contigency
B18: Construction Contingency | C18: =G18-D18-E18-F18 -> 0 | D18: 0 | E18: 0 | F18: 0 | G18: =ROUND(G17*K18,0) -> 0 | H18: 25 | I18: =IF($C$22=0,0,C18/$C$22) -> 0 | J18: =H18*I18 -> 0 | K18: 0.1 | M18: Construction Contingency | N18: =R18-O18-P18-Q18 -> 0 | O18: 0 | P18: 0 | Q18: 0 | R18: =ROUND(R17*V18,0) -> 0 | S18: 0.1
B19: Other Construction Soft Costs | C19: =G19-SUM(D19:F19) -> 0 | D19: 0 | E19: 0 | F19: 0 | G19: 0 | H19: 25 | I19: =IF($C$22=0,0,C19/$C$22) -> 0 | J19: =H19*I19 -> 0 | M19: Other Construction Soft Costs | N19: =R19-SUM(O19:Q19) -> 0 | O19: 0 | P19: 0 | Q19: 0 | R19: 0
B20: Closing Costs | C20: =G20-SUM(D20:F20) -> 0 | D20: 0 | E20: 0 | F20: 0 | G20: 0 | H20: 10 | I20: =IF($C$22=0,0,C20/$C$22) -> 0 | J20: =H20*I20 -> 0 | M20: Closing Costs | N20: =R20-SUM(O20:Q20) -> 0 | O20: 0 | P20: 0 | Q20: 0 | R20: 0
B21: SBA Gty Fee | C21: 0 | D21: =G21-C21 -> 0 | G21: =D80 -> 0 | H21: 10 | I21: =IF($C$22=0,0,C21/$C$22) -> 0 | J21: =H21*I21 -> 0 | M21: SBA Gty Fee | N21: 0 | O21: =R21-N21 -> 0 | R21: =O80
C22: 0 | D22: =SUM(D6:D21) -> 0 | E22: =SUM(E6:E21) -> 0 | F22: =SUM(F6:F21) -> 0 | G22: =SUM(G6:G21) -> 0 | I22: Weighted Term | J22: =SUM(J6:J21) -> 0 | N22: 0 | O22: =SUM(O6:O21) -> 0 | P22: =SUM(P6:P21) -> 0 | Q22: =SUM(Q6:Q21) -> 0 | R22: =SUM(R6:R21) -> 0
C23: =IFERROR(C22/$G$22,0) -> 0 | D23: =IFERROR(D22/$G$22,0) -> 0 | E23: =IFERROR(E22/$G$22,0) -> 0 | F23: =IFERROR(F22/$G$22,0) -> 0 | G23: =IFERROR(G22/$G$22,0) -> 0 | N23: =IFERROR(N22/$R$22,0) -> 0 | O23: =IFERROR(O22/$R$22,0) -> 0 | P23: =IFERROR(P22/$R$22,0) -> 0 | Q23: =IFERROR(Q22/$R$22,0) -> 0 | R23: =IFERROR(R22/$R$22,0) -> 0
B26: Total Project | C26: =SUM(C27:C29) -> 1 | D26: =G22 -> 0 | E26: (difference)
B27: Bank Loan % | C27: 0.5 | D27: =D26*C27 -> 0 | E27: =C22-D27 -> 0
B28: CDC Loan % | C28: 0.4 | D28: =D26*C28 -> 0 | E28: =F22-D28 -> 0
B29: Borrower % | C29: 0.1 | D29: =D26*C29 -> 0 | E29: =D22-D29 -> 0
B31: Bank Interim Loan Fee % | C31: 0.025 | D31: =D27*C31 -> 0 | E31: Blended Rate | F31: (C22*'1. Project Structure'.c16 + F22*'1. Project Structure'.f16)/SUM('1. Project Structure'.c13+'1. Project Structure'.F13)
B32: SBA TPL Fee % | C32: 0.005 | D32: =D27*C32 -> 0
B33: Referral Fee % | C33: 0 | D33: =D27*C33 -> 0 | E33: Interim Loan | F33: =C22+F22 -> 0
B34: Participant Fee % | C34: 0 | D34: =C22*C34 -> 0 | E34: Rounded Fee | F34: =ROUNDUP(D35,-3) -> 1000
B35: Origination Fee Total | C35: =SUM(C31:C34) -> 0.03 | D35: =SUM(D31:D34) -> 0 | E35: Fee % to Interim | F35: =F34/F33 -> #DIV/0!
B36: 504 Loan Project
B38: Closing Costs | C38: Cost | D38: Quantity | E38: Total
B39: Loan Packaging Fee | C39: 2500 | D39: 1 | E39: =C39*D39 -> 2500
B40: Title Insurance | C40: 0 | D40: 0 | E40: =C40*D40 -> 0
B41: Real Estate Tax Fee | C41: 0 | D41: 0 | E41: =C41*D41 -> 0
B42: Survey Charges | C42: 3000 | D42: 0 | E42: =C42*D42 -> 0
B43: CRE Appraisal | C43: 3500 | D43: 0 | E43: =C43*D43 -> 0
B44: Equipment Appraisal | C44: 0 | D44: 0 | E44: =C44*D44 -> 0
B45: Appraisal Review | C45: 0 | D45: 0 | E45: =C45*D45 -> 0
B46: Site Visit | C46: 350 | D46: 0 | E46: =C46*D46 -> 0
...

Sheet 3. Financials
B3: Income Statement Spreads
B4: {Insert business name which represents PSOR}
B5: Include in Global? | C5: Yes
B6: Statement Date | D6: 44926 | F6: =EOMONTH(D6,F7) -> 45291 | H6: =EOMONTH(F6,H7) -> 45657 | J6: =EOMONTH(H6,J7) -> 45747 | N6: Projections | P6: Projections
B7: Months Covered | D7: 12 | F7: 12 | H7: 12 | J7: 3 | N7: Customer | P7: Customer
B8: Statement Type | D8: Tax Returns | F8: Tax Returns | J8: Internal | N8: Year | P8: Year
B9: Revenue Recognition | N9: 1 | P9: 2
B10: REVENUE
B11: Revenue | C11: (Product Line #1) | D11: 1 | E11: =IF(D$14=0,0,D11/D$14) -> 0 | F11: 0 | G11: =IF(F$14=0,0,F11/F$14) -> 0 | H11: 0 | I11: =IF(H$14=0,0,H11/H$14) -> 0 | J11: 0 | K11: =IF(J$14=0,0,J11/J$14) -> 0 | M11: Revenue (Product Line #1) | N11: 0 | O11: =IF(N$14=0,0,N11/N$14) -> 0 | P11: 0 | Q11: =IF(P$14=0,0,P11/P$14) -> 0
B12: COGS | C12: (Product Line #1) | D12: 0 | E12: =IF(D$14=0,0,D12/D$14) -> 0 | F12: 0 | G12: =IF(F$14=0,0,F12/F$14) -> 0 | H12: 0 | I12: =IF(H$14=0,0,H12/H$14) -> 0 | J12: 0 | K12: =IF(J$14=0,0,J12/J$14) -> 0 | M12: COGS (Product Line #1) | N12: 0 | O12: =IF(N$14=0,0,N12/N$14) -> 0 | P12: 0 | Q12: =IF(P$14=0,0,P12/P$14) -> 0
B13: Gross Margin | C13: (Product Line #1) | D13: =D11-D12 -> 1 | E13: =IF(D$14=0,0,D13/D$14) -> 0 | F13: =F11-F12 -> 0 | G13: =IF(F$14=0,0,F13/F$14) -> 0 | H13: =H11-H12 -> 0 | I13: =IF(H$14=0,0,H13/H$14) -> 0 | J13: =J11-J12 -> 0 | K13: =IF(J$14=0,0,J13/J$14) -> 0 | M13: Gross Margin (Product Line #1) | N13: =N11-N12 -> 0 | O13: =IF(N$14=0,0,N13/N$14) -> 0 | P13: =P11-P12 -> 0 | Q13: =IF(P$14=0,0,P13/P$14) -> 0
C14: Total Revenue | D14: 0 | E14: =IF(D$14=0,0,D14/D$14) -> 0 | F14: 0 | G14: =IF(F$14=0,0,F14/F$14) -> 0 | H14: 0 | I14: =IF(H$14=0,0,H14/H$14) -> 0 | J14: 0 | K14: =IF(J$14=0,0,J14/J$14) -> 0 | M14: Total Revenue | N14: =N11 -> 0 | O14: =IF(N$14=0,0,N14/N$14) -> 0 | P14: =P11 -> 0 | Q14: =IF(P$14=0,0,P14/P$14) -> 0
C15: Total COGS | D15: 0 | E15: =IF(D$14=0,0,D15/D$14) -> 0 | F15: 0 | G15: =IF(F$14=0,0,F15/F$14) -> 0 | H15: 0 | I15: =IF(H$14=0,0,H15/H$14) -> 0 | J15: 0 | K15: =IF(J$14=0,0,J15/J$14) -> 0 | M15: Total COGS | N15: =N12 -> 0 | O15: =IF(N$14=0,0,N15/N$14) -> 0 | P15: =P12 -> 0 | Q15: =IF(P$14=0,0,P15/P$14) -> 0
C16: Total Gross Margin | D16: =D14-D15 -> 0 | E16: =IF(D$14=0,0,D16/D$14) -> 0 | F16: =F14-F15 -> 0 | G16: =IF(F$14=0,0,F16/F$14) -> 0 | H16: =H14-H15 -> 0 | I16: =IF(H$14=0,0,H16/H$14) -> 0 | J16: =J14-J15 -> 0 | K16: =IF(J$14=0,0,J16/J$14) -> 0 | M16: Total Gross Margin | N16: =N14-N15 -> 0 | O16: =IF(N$14=0,0,N16/N$14) -> 0 | P16: =P14-P15 -> 0 | Q16: =IF(P$14=0,0,P16/P$14) -> 0
C18: OPERATING EXPENSES | M18: OPERATING EXPENSES
C19: Officer's Compensation | D19: 0 | E19: =IF(D$14=0,0,D19/D$14) -> 0 | F19: 0 | G19: =IF(F$14=0,0,F19/F$14) -> 0 | H19: 0 | I19: =IF(H$14=0,0,H19/H$14) -> 0 | J19: 0 | K19: =IF(J$14=0,0,J19/J$14) -> 0 | M19: Officer's Compensation | N19: 0 | O19: =IF(N$14=0,0,N19/N$14) -> 0 | P19: 0 | Q19: =IF(P$14=0,0,P19/P$14) -> 0
C20: Salaries & Wages | D20: 0 | E20: =IF(D$14=0,0,D20/D$14) -> 0 | F20: 0 | G20: =IF(F$14=0,0,F20/F$14) -> 0 | H20: 0 | I20: =IF(H$14=0,0,H20/H$14) -> 0 | J20: 0 | K20: =IF(J$14=0,0,J20/J$14) -> 0 | M20: Salaries & Wages | N20: 0 | O20: =IF(N$14=0,0,N20/N$14) -> 0 | P20: 0 | Q20: =IF(P$14=0,0,P20/P$14) -> 0
C21: Repairs & Maintenance | D21: 0 | E21: =IF(D$14=0,0,D21/D$14) -> 0 | F21: 0 | G21: =IF(F$14=0,0,F21/F$14) -> 0 | H21: 0 | I21: =IF(H$14=0,0,H21/H$14) -> 0 | J21: 0 | K21: =IF(J$14=0,0,J21/J$14) -> 0 | M21: Repairs & Maintenance | N21: 0 | O21: =IF(N$14=0,0,N21/N$14) -> 0 | P21: 0 | Q21: =IF(P$14=0,0,P21/P$14) -> 0
C22: Bad Debts | D22: 0 | E22: =IF(D$14=0,0,D22/D$14) -> 0 | F22: 0 | G22: =IF(F$14=0,0,F22/F$14) -> 0 | H22: 0 | I22: =IF(H$14=0,0,H22/H$14) -> 0 | J22: 0 | K22: =IF(J$14=0,0,J22/J$14) -> 0 | M22: Bad Debts | N22: 0 | O22: =IF(N$14=0,0,N22/N$14) -> 0 | P22: 0 | Q22: =IF(P$14=0,0,P22/P$14) -> 0
C23: Rents | D23: 0 | E23: =IF(D$14=0,0,D23/D$14) -> 0 | F23: 0 | G23: =IF(F$14=0,0,F23/F$14) -> 0 | H23: 0 | I23: =IF(H$14=0,0,H23/H$14) -> 0 | J23: 0 | K23: =IF(J$14=0,0,J23/J$14) -> 0 | M23: Rents | N23: 0 | O23: =IF(N$14=0,0,N23/N$14) -> 0 | P23: 0 | Q23: =IF(P$14=0,0,P23/P$14) -> 0
C24: Taxes & Licenses | D24: 0 | E24: =IF(D$14=0,0,D24/D$14) -> 0 | F24: 0 | G24: =IF(F$14=0,0,F24/F$14) -> 0 | H24: 0 | I24: =IF(H$14=0,0,H24/H$14) -> 0 | J24: 0 | K24: =IF(J$14=0,0,J24/J$14) -> 0 | M24: Taxes & Licenses | N24: 0 | O24: =IF(N$14=0,0,N24/N$14) -> 0 | P24: 0 | Q24: =IF(P$14=0,0,P24/P$14) -> 0
C25: Interest | D25: 0 | E25: =IF(D$14=0,0,D25/D$14) -> 0 | F25: 0 | G25: =IF(F$14=0,0,F25/F$14) -> 0 | H25: 0 | I25: =IF(H$14=0,0,H25/H$14) -> 0 | J25: 0 | K25: =IF(J$14=0,0,J25/J$14) -> 0 | M25: Interest | N25: 0 | O25: =IF(N$14=0,0,N25/N$14) -> 0 | P25: 0 | Q25: =IF(P$14=0,0,P25/P$14) -> 0
C26: Depreciation & Amortization | D26: 0 | E26: =IF(D$14=0,0,D26/D$14) -> 0 | F26: 0 | G26: =IF(F$14=0,0,F26/F$14) -> 0 | H26: 0 | I26: =IF(H$14=0,0,H26/H$14) -> 0 | J26: 0 | K26: =IF(J$14=0,0,J26/J$14) -> 0 | M26: Depreciation & Amortization | N26: 0 | O26: =IF(N$14=0,0,N26/N$14) -> 0 | P26: 0 | Q26: =IF(P$14=0,0,P26/P$14) -> 0
C27: Advertising | D27: 0 | E27: =IF(D$14=0,0,D27/D$14) -> 0 | F27: 0 | G27: =IF(F$14=0,0,F27/F$14) -> 0 | H27: 0 | I27: =IF(H$14=0,0,H27/H$14) -> 0 | J27: 0 | K27: =IF(J$14=0,0,J27/J$14) -> 0 | M27: Advertising | N27: 0 | O27: =IF(N$14=0,0,N27/N$14) -> 0 | P27: 0 | Q27: =IF(P$14=0,0,P27/P$14) -> 0
C28: Other | D28: 0 | E28: =IF(D$14=0,0,D28/D$14) -> 0 | F28: 0 | G28: =IF(F$14=0,0,F28/F$14) -> 0 | H28: 0 | I28: =IF(H$14=0,0,H28/H$14) -> 0 | J28: 0 | K28: =IF(J$14=0,0,J28/J$14) -> 0 | M28: Other | N28: 0 | O28: =IF(N$14=0,0,N28/N$14) -> 0 | P28: 0 | Q28: =IF(P$14=0,0,P28/P$14) -> 0
C29: Other | D29: 0 | E29: =IF(D$14=0,0,D29/D$14) -> 0 | F29: 0 | G29: =IF(F$14=0,0,F29/F$14) -> 0 | H29: 0 | I29: =IF(H$14=0,0,H29/H$14) -> 0 | J29: 0 | K29: =IF(J$14=0,0,J29/J$14) -> 0 | M29: Other | N29: =0-SUM(N19:N28) -> 0 | O29: =IF(N$14=0,0,N29/N$14) -> 0 | P29: =0-SUM(P19:P28) -> 0 | Q29: =IF(P$14=0,0,P29/P$14) -> 0
C30: Total Operating Expenses | D30: =SUM(D19:D29) -> 0 | E30: =IF(D$14=0,0,D30/D$14) -> 0 | F30: =SUM(F19:F29) -> 0 | G30: =IF(F$14=0,0,F30/F$14) -> 0 | H30: =SUM(H19:H29) -> 0 | I30: =IF(H$14=0,0,H30/H$14) -> 0 | J30: =SUM(J19:J29) -> 0 | K30: =IF(J$14=0,0,J30/J$14) -> 0 | M30: Total Operating Expenses | N30: =SUM(N19:N29) -> 0 | O30: =IF(N$14=0,0,N30/N$14) -> 0 | P30: =SUM(P19:P29) -> 0 | Q30: =IF(P$14=0,0,P30/P$14) -> 0
C32: Ordinary Income | D32: =D16-D30 -> 0 | E32: =IF(D$14=0,0,D32/D$14) -> 0 | F32: =F16-F30 -> 0 | G32: =IF(F$14=0,0,F32/F$14) -> 0 | H32: =H16-H30 -> 0 | I32: =IF(H$14=0,0,H32/H$14) -> 0 | J32: =J16-J30 -> 0 | K32: =IF(J$14=0,0,J32/J$14) -> 0 | M32: Ordinary Income | N32: =N16-N30 -> 0 | O32: =IF(N$14=0,0,N32/N$14) -> 0 | P32: =P16-P30 -> 0 | Q32: =IF(P$14=0,0,P32/P$14) -> 0
C34: Other Income | D34: 0 | E34: =IF(D$14=0,0,D34/D$14) -> 0 | F34: 0 | G34: =IF(F$14=0,0,F34/F$14) -> 0 | H34: 0 | I34: =IF(H$14=0,0,H34/H$14) -> 0 | J34: 0 | K34: =IF(J$14=0,0,J34/J$14) -> 0 | M34: Other Income | N34: 0 | O34: =IF(N$14=0,0,N34/N$14) -> 0 | P34: 0 | Q34: =IF(P$14=0,0,P34/P$14) -> 0
C35: Other Income | D35: 0 | E35: =IF(D$14=0,0,D35/D$14) -> 0 | F35: 0 | G35: =IF(F$14=0,0,F35/F$14) -> 0 | H35: 0 | I35: =IF(H$14=0,0,H35/H$14) -> 0 | J35: 0 | K35: =IF(J$14=0,0,J35/J$14) -> 0 | M35: Other Income | N35: 0 | O35: =IF(N$14=0,0,N35/N$14) -> 0 | P35: 0 | Q35: =IF(P$14=0,0,P35/P$14) -> 0
C36: Other Expense | D36: 0 | E36: =IF(D$14=0,0,D36/D$14) -> 0 | F36: 0 | G36: =IF(F$14=0,0,F36/F$14) -> 0 | H36: 0 | I36: =IF(H$14=0,0,H36/H$14) -> 0 | J36: 0 | K36: =IF(J$14=0,0,J36/J$14) -> 0 | M36: Other Expense | N36: 0 | O36: =IF(N$14=0,0,N36/N$14) -> 0 | P36: 0 | Q36: =IF(P$14=0,0,P36/P$14) -> 0
C37: Other Expense | D37: 0 | E37: =IF(D$14=0,0,D37/D$14) -> 0 | F37: 0 | G37: =IF(F$14=0,0,F37/F$14) -> 0 | H37: 0 | I37: =IF(H$14=0,0,H37/H$14) -> 0 | J37: 0 | K37: =IF(J$14=0,0,J37/J$14) -> 0 | M37: Other Expense | N37: 0 | O37: =IF(N$14=0,0,N37/N$14) -> 0 | P37: 0 | Q37: =IF(P$14=0,0,P37/P$14) -> 0
C38: Total Other Income (Expenses) | D38: =SUM(D34:D37) -> 0 | E38: =IF(D$14=0,0,D38/D$14) -> 0 | F38: =SUM(F34:F37) -> 0 | G38: =IF(F$14=0,0,F38/F$14) -> 0 | H38: =SUM(H34:H37) -> 0 | I38: =IF(H$14=0,0,H38/H$14) -> 0 | J38: =SUM(J34:J37) -> 0 | K38: =IF(J$14=0,0,J38/J$14) -> 0 | M38: Total Other Income (Expenses) | N38: =SUM(N34:N37) -> 0 | O38: =IF(N$14=0,0,N38/N$14) -> 0 | P38: =SUM(P34:P37) -> 0 | Q38: =IF(P$14=0,0,P38/P$14) -> 0
C40: Net Income Before Taxes | D40: =D16-D30+D38 -> 0 | E40: =IF(D$14=0,0,D40/D$14) -> 0 | F40: =F16-F30+F38 -> 0 | G40: =IF(F$14=0,0,F40/F$14) -> 0 | H40: =H16-H30+H38 -> 0 | I40: =IF(H$14=0,0,H40/H$14) -> 0 | J40: =J16-J30+J38 -> 0 | K40: =IF(J$14=0,0,J40/J$14) -> 0 | M40: Net Income Before Taxes | N40: =N16-N30+N38 -> 0 | O40: =IF(N$14=0,0,N40/N$14) -> 0 | P40: =P16-P30+P38 -> 0 | Q40: =IF(P$14=0,0,P40/P$14) -> 0
C41: Income Taxes | D41: 0 | E41: =IF(D$14=0,0,D41/D$14) -> 0 | F41: 0 | G41: =IF(F$14=0,0,F41/F$14) -> 0 | H41: 0 | I41: =IF(H$14=0,0,H41/H$14) -> 0 | J41: 0 | K41: =IF(J$14=0,0,J41/J$14) -> 0 | M41: Income Taxes | N41: 0 | O41: =IF(N$14=0,0,N41/N$14) -> 0 | P41: 0 | Q41: =IF(P$14=0,0,P41/P$14) -> 0
C43: NET INCOME AFTER TAXES | D43: =D40-D41 -> 0 | E43: =IF(D$14=0,0,D43/D$14) -> 0 | F43: =F40-F41 -> 0 | G43: =IF(F$14=0,0,F43/F$14) -> 0 | H43: =H40-H41 -> 0 | I43: =IF(H$14=0,0,H43/H$14) -> 0 | J43: =J40-J41 -> 0 | K43: =IF(J$14=0,0,J43/J$14) -> 0 | M43: NET INCOME AFTER TAXES | N43: =N40-N41 -> 0 | O43: =IF(N$14=0,0,N43/N$14) -> 0 | P43: =P40-P41 -> 0 | Q43: =IF(P$14=0,0,P43/P$14) -> 0
C45: Add Backs : | M45: Add Backs :
C46: + Compensation of Officers | D46: =D19 -> 0 | F46: =F19 -> 0 | H46: =H19 -> 0 | J46: =J19 -> 0 | M46: + Compensation of Officers | N46: =N19 -> 0 | O46: =IF(N$14=0,0,N46/N$14) -> 0 | P46: =P19 -> 0 | Q46: =IF(P$14=0,0,P46/P$14) -> 0
C47: + Depreciation/Amortization | D47: =D26 -> 0 | F47: =F26 -> 0 | H47: =H26 -> 0 | J47: =J26 -> 0 | M47: + Depreciation/Amortization | N47: =N26 -> 0 | O47: =IF(N$14=0,0,N47/N$14) -> 0 | P47: =P26 -> 0 | Q47: =IF(P$14=0,0,P47/P$14) -> 0
C48: + Interest Expense | D48: =D25 -> 0 | F48: =F25 -> 0 | H48: =H25 -> 0 | J48: =J25 -> 0 | M48: + Interest Expense | N48: =N25 -> 0 | O48: =IF(N$14=0,0,N48/N$14) -> 0 | P48: =P25 -> 0 | Q48: =IF(P$14=0,0,P48/P$14) -> 0
...

Sheet 4. PFS 
B1: Loan Structure
B2: Purchase and Sale Close Date, if known, otherwise Target Closing Date
B5: Entity Name: - Financials | D5: Role | F5: Yrs. In Bus. | G5: Guarantor?
I6: BDO:
I7: Cooperating BDO:
I8: Broker Name:
I9: Broker Fee:
B11: * List entities in the following order (as applicable): Borrower, Co-Borrower, Operating Entity, Corp. Guarantor, Affiliate.
B12: Individual Guarantor Info: | C12: Ownership Exp. (yrs) | D12: Ownership % | E12: FICO | F12: Prior BK? | G12: Prior Loss to Gov't | H12: Debarred by SBA? | I12: Pending Legal Action? | J12: Criminal History?
B20: Business / Property Address:
C21: (Street) | F21: (City) (State) (ZIP)
B23: Personal Financial Analysis | M23: + Collapse /Expand (Additional Individuals)
B25: Last Name, First Initial
B27: Liquid Assets* | C27: 0 | E27: 0 | G27: 0 | I27: 0 | N27: 0 | P27: 0 | R27: 0 | T27: 0
B28: Include in Global?
B29: Annual Income Sources other than SBC:
B30: Spouses salary/pension | C30: 0 | E30: 0 | G30: 0 | I30: 0 | N30: 0 | P30: 0 | R30: 0 | T30: 0
B31: Interest and Dividends | C31: 0 | E31: 0 | G31: 0 | I31: 0 | N31: 0 | P31: 0 | R31: 0 | T31: 0
B32: Business Income (Sch C) | C32: 0 | E32: 0 | G32: 0 | I32: 0 | N32: 0 | P32: 0 | R32: 0 | T32: 0
B33: Net Rental Income (Sch E) | C33: 0 | E33: 0 | G33: 0 | I33: 0 | N33: 0 | P33: 0 | R33: 0 | T33: 0
B34: Social Security Income | C34: 0 | E34: 0 | G34: 0 | I34: 0 | N34: 0 | P34: 0 | R34: 0 | T34: 0
B35: Other: (Income from Affiliate) | C35: 0 | E35: 0 | G35: 0 | I35: 0 | N35: 0 | P35: 0 | R35: 0 | T35: 0
B36: Other: (alimony, ongoing capital gains) | C36: 0 | E36: 0 | G36: 0 | I36: 0 | N36: 0 | P36: 0 | R36: 0 | T36: 0
B37: Total Annual Outside Income | C37: =SUM(C30:C36) -> 0 | E37: =SUM(E30:E36) -> 0 | G37: =SUM(G30:G36) -> 0 | I37: =SUM(I30:I36) -> 0 | N37: =SUM(N30:N36) -> 0 | P37: =SUM(P30:P36) -> 0 | R37: =SUM(R30:R36) -> 0 | T37: =SUM(T30:T36) -> 0
B39: Fixed Monthly Expenses:
B40: Home/Primary Residence | C40: 0 | E40: 0 | G40: 0 | I40: 0 | N40: 0 | P40: 0 | R40: 0 | T40: 0
B41: Other Mortgages | C41: 0 | E41: 0 | G41: 0 | I41: 0 | N41: 0 | P41: 0 | R41: 0 | T41: 0
B42: Other Installment Loans | C42: 0 | E42: 0 | G42: 0 | I42: 0 | N42: 0 | P42: 0 | R42: 0 | T42: 0
B43: Vehicle Loans | C43: 0 | E43: 0 | G43: 0 | I43: 0 | N43: 0 | P43: 0 | R43: 0 | T43: 0
B44: Credit Cards | C44: 0 | E44: 0 | G44: 0 | I44: 0 | N44: 0 | P44: 0 | R44: 0 | T44: 0
B45: Other: | C45: 0 | E45: 0 | G45: 0 | I45: 0 | N45: 0 | P45: 0 | R45: 0 | T45: 0
B46: Total Fixed Monthly Expenses | C46: =SUM(C40:C45) -> 0 | E46: =SUM(E40:E45) -> 0 | G46: =SUM(G40:G45) -> 0 | I46: =SUM(I40:I45) -> 0 | N46: =SUM(N40:N45) -> 0 | P46: =SUM(P40:P45) -> 0 | R46: =SUM(R40:R45) -> 0 | T46: =SUM(T40:T45) -> 0
B48: Annualized Monthly Fixed Expenses | C48: =C46*12 -> 0 | E48: =E46*12 -> 0 | G48: =G46*12 -> 0 | I48: =I46*12 -> 0 | N48: =N46*12 -> 0 | P48: =P46*12 -> 0 | R48: =R46*12 -> 0 | T48: =T46*12 -> 0
B49: Debt Ratio prior to draw | C49: =IF(C37=0,0,C48/C37) -> 0 | E49: =IF(E37=0,0,E48/E37) -> 0 | G49: =IF(G37=0,0,G48/G37) -> 0 | I49: =IF(I37=0,0,I48/I37) -> 0 | N49: =IF(N37=0,0,N48/N37) -> 0 | P49: =IF(P37=0,0,P48/P37) -> 0 | R49: =IF(R37=0,0,R48/R37) -> 0 | T49: =IF(T37=0,0,T48/T37) -> 0
B50: Calculated draw (Mo. Exp x2) | C50: =(C46*12/50)*100 -> 0 | E50: =(E46*12/50)*100 -> 0 | G50: =(G46*12/50)*100 -> 0 | I50: =(I46*12/50)*100 -> 0 | N50: =(N46*12/50)*100 -> 0 | P50: =(P46*12/50)*100 -> 0 | R50: =(R46*12/50)*100 -> 0 | T50: =(T46*12/50)*100 -> 0
B52: Monthly Expenses not Doubled
B53: Lifestyle Adjustment | C53: =C61 -> 0 | E53: =E61 -> 0 | G53: =G61 -> 0 | I53: =I61 -> 0 | N53: =N61 -> 0 | P53: =P61 -> 0 | R53: =R61 -> 0 | T53: =T61 -> 0
B54: Alimony Payments | C54: 0 | E54: 0 | G54: 0 | I54: 0 | N54: 0 | P54: 0 | R54: 0 | T54: 0
B55: Rental/Other Property Payments | C55: 0 | E55: 0 | G55: 0 | I55: 0 | N55: 0 | P55: 0 | R55: 0 | T55: 0
B56: Other | C56: 0 | E56: 0 | G56: 0 | I56: 0 | N56: 0 | P56: 0 | R56: 0 | T56: 0
...

Sheet 5.Collateral
B2: Collateral Analysis
B3: Collateral Summary
B4: Collateral | C4: Prop Type | D4: Valuation Method | E4: Address | G4: Gross Value | H4: Liquidation Value | I4: Discounted Value | J4: Senior Liens | K4: Liquidation Value
B5: Primary Real Estate | E5: 9000 houston houston tx, 55994 | G5: 0 | H5: 0.85 | I5: =G5*H5 -> 0 | J5: 0 | K5: =IF(I5-J5<0,0,I5-J5) -> 0
B6: Secondary Real Estate | G6: 0 | H6: 0.85 | I6: =G6*H6 -> 0 | J6: 0 | K6: =IF(I6-J6<0,0,I6-J6) -> 0
B7: Secondary Real Estate | G7: 0 | H7: 0.85 | I7: =G7*H7 -> 0 | J7: 0 | K7: =IF(I7-J7<0,0,I7-J7) -> 0
B8: Accounts Receivable | E8: =IF(G8=0," ","") | G8: 0 | H8: 0.1 | I8: =G8*H8 -> 0 | J8: 0 | K8: =IF(I8-J8<0,0,I8-J8) -> 0
B9: Machinery & Equipment | E9: =IF(G9=0," ","") | G9: 0 | H9: 0.5 | I9: =G9*H9 -> 0 | J9: 0 | K9: =IF(I9-J9<0,0,I9-J9) -> 0
B10: Inventory | E10: =IF(G10=0," ","") | G10: 0 | H10: 0.1 | I10: =G10*H10 -> 0 | J10: 0 | K10: =IF(I10-J10<0,0,I10-J10) -> 0
B11: FF&E | E11: =IF(G11=0," ","") | G11: 0 | H11: 0.1 | I11: =G11*H11 -> 0 | J11: 0 | K11: =IF(I11-J11<0,0,I11-J11) -> 0
B12: Lease Hold Improvements | E12: =IF(G12=0," ","") | G12: 0 | H12: 0.05 | I12: =G12*H12 -> 0 | J12: 0 | K12: =IF(I12-J12<0,0,I12-J12) -> 0
B13: Miscellaneous | E13: =IF(G13=0," ","") | G13: 0 | H13: 0 | I13: =G13*H13 -> 0 | J13: 0 | K13: =IF(I13-J13<0,0,I13-J13) -> 0
F14: Totals | I14: =SUM(I5:I13) -> 0 | J14: =SUM(J5:J13) -> 0 | K14: =SUM(K5:K13) -> 0
B16: Loan Amount | C16: ='2. Sources and Uses'!C22 -> 0 | E16: Gross LTV | G16: =IFERROR((C16+J14)/G14,0) -> 0 | H16: Net LTV | J16: Net LTV | K16: =IFERROR((J14+C16)/I14,0) -> 0
B17: Discounted Collateral Value | C17: =K14 -> 0 | E17: Gross Coverage | G17: =IFERROR(G14/(C16+J14),0) -> 0 | H17: Net Coverage | J17: Net Coverage | K17: =IFERROR(I14/(J14+C16),0) -> 0
B18: Gross Exposure Amount | C18: =IF(C16-C17<0,0,C16-C17) -> 0
B19: SBA Gty % | C19: ='1. Project Structure'!J12 -> 0.75 | E19: Life Insurance Requirement | F19: Life Insurance Required | G19: =C16-(K5+K6+K7) -> 0
B20: SBA Guarantee Amount | C20: =IF(C18>0,C19*C18,0) -> 0
B21: Maximum Exposure | C21: =IF(C20>0,C18-C20,0) -> 0

Sheet Charts
B3: Loan Request | I3: Loan Request | N3: Loan Request | T3: Loan Request
C5: ='2. Sources and Uses'!C4 -> T Bank Loan | D5: ='2. Sources and Uses'!D4 -> Borrower | E5: ='2. Sources and Uses'!E4 -> Seller Note | F5: ='2. Sources and Uses'!F4 -> 3rd Party | G5: ='2. Sources and Uses'!G4 -> Total | J5: =C5 -> T Bank Loan | K5: =D5 -> Borrower | L5: =G5 -> Total | O5: =C5 -> T Bank Loan | P5: =D5 -> Borrower | Q5: =E5 -> Seller Note | R5: =G5 -> Total | U5: =C5 -> T Bank Loan | V5: =D5 -> Borrower | W5: =F5 -> 3rd Party | X5: =G5 -> Total
B6: ='2. Sources and Uses'!B6 -> Real Estate Acquisition | C6: ='2. Sources and Uses'!C6 -> 0 | D6: ='2. Sources and Uses'!D6 -> 0 | E6: ='2. Sources and Uses'!E6 -> 0 | F6: ='2. Sources and Uses'!F6 -> 0 | G6: ='2. Sources and Uses'!G6 -> 0 | I6: =B6 -> Real Estate Acquisition | J6: =C6 -> 0 | K6: =D6 -> 0 | L6: =G6 -> 0 | N6: =B6 -> Real Estate Acquisition | O6: =C6 -> 0 | P6: =D6 -> 0 | Q6: =E6 -> 0 | R6: =G6 -> 0 | T6: =B6 -> Real Estate Acquisition | U6: =C6 -> 0 | V6: =D6 -> 0 | W6: =F6 -> 0 | X6: =G6 -> 0
B7: ='2. Sources and Uses'!B7 -> Debt Refi - CRE | C7: ='2. Sources and Uses'!C7 -> 0 | D7: ='2. Sources and Uses'!D7 -> 0 | E7: ='2. Sources and Uses'!E7 -> 0 | F7: ='2. Sources and Uses'!F7 -> 0 | G7: ='2. Sources and Uses'!G7 -> 0 | I7: =B7 -> Debt Refi - CRE | J7: =C7 -> 0 | K7: =D7 -> 0 | L7: =G7 -> 0 | N7: =B7 -> Debt Refi - CRE | O7: =C7 -> 0 | P7: =D7 -> 0 | Q7: =E7 -> 0 | R7: =G7 -> 0 | T7: =B7 -> Debt Refi - CRE | U7: =C7 -> 0 | V7: =D7 -> 0 | W7: =F7 -> 0 | X7: =G7 -> 0
B8: ='2. Sources and Uses'!B8 -> Debt Refi - Non-CRE | C8: ='2. Sources and Uses'!C8 -> 0 | D8: ='2. Sources and Uses'!D8 -> 0 | E8: ='2. Sources and Uses'!E8 -> 0 | F8: ='2. Sources and Uses'!F8 -> 0 | G8: ='2. Sources and Uses'!G8 -> 0 | I8: =B8 -> Debt Refi - Non-CRE | J8: =C8 -> 0 | K8: =D8 -> 0 | L8: =G8 -> 0 | N8: =B8 -> Debt Refi - Non-CRE | O8: =C8 -> 0 | P8: =D8 -> 0 | Q8: =E8 -> 0 | R8: =G8 -> 0 | T8: =B8 -> Debt Refi - Non-CRE | U8: =C8 -> 0 | V8: =D8 -> 0 | W8: =F8 -> 0 | X8: =G8 -> 0
B9: ='2. Sources and Uses'!B9 -> Machinery & Equipment | C9: ='2. Sources and Uses'!C9 -> 0 | D9: ='2. Sources and Uses'!D9 -> 0 | E9: ='2. Sources and Uses'!E9 -> 0 | F9: ='2. Sources and Uses'!F9 -> 0 | G9: ='2. Sources and Uses'!G9 -> 0 | I9: =B9 -> Machinery & Equipment | J9: =C9 -> 0 | K9: =D9 -> 0 | L9: =G9 -> 0 | N9: =B9 -> Machinery & Equipment | O9: =C9 -> 0 | P9: =D9 -> 0 | Q9: =E9 -> 0 | R9: =G9 -> 0 | T9: =B9 -> Machinery & Equipment | U9: =C9 -> 0 | V9: =D9 -> 0 | W9: =F9 -> 0 | X9: =G9 -> 0
B10: ='2. Sources and Uses'!B10 -> Furniture & Fixtures (TIs) | C10: ='2. Sources and Uses'!C10 -> 0 | D10: ='2. Sources and Uses'!D10 -> 0 | E10: ='2. Sources and Uses'!E10 -> 0 | F10: ='2. Sources and Uses'!F10 -> 0 | G10: ='2. Sources and Uses'!G10 -> 0 | I10: =B10 -> Furniture & Fixtures (TIs) | J10: =C10 -> 0 | K10: =D10 -> 0 | L10: =G10 -> 0 | N10: =B10 -> Furniture & Fixtures (TIs) | O10: =C10 -> 0 | P10: =D10 -> 0 | Q10: =E10 -> 0 | R10: =G10 -> 0 | T10: =B10 -> Furniture & Fixtures (TIs) | U10: =C10 -> 0 | V10: =D10 -> 0 | W10: =F10 -> 0 | X10: =G10 -> 0
B11: ='2. Sources and Uses'!B11 -> Inventory | C11: ='2. Sources and Uses'!C11 -> 0 | D11: ='2. Sources and Uses'!D11 -> 0 | E11: ='2. Sources and Uses'!E11 -> 0 | F11: ='2. Sources and Uses'!F11 -> 0 | G11: ='2. Sources and Uses'!G11 -> 0 | I11: =B11 -> Inventory | J11: =C11 -> 0 | K11: =D11 -> 0 | L11: =G11 -> 0 | N11: =B11 -> Inventory | O11: =C11 -> 0 | P11: =D11 -> 0 | Q11: =E11 -> 0 | R11: =G11 -> 0 | T11: =B11 -> Inventory | U11: =C11 -> 0 | V11: =D11 -> 0 | W11: =F11 -> 0 | X11: =G11 -> 0
B12: ='2. Sources and Uses'!B12 -> Working Capital | C12: ='2. Sources and Uses'!C12 -> 0 | D12: ='2. Sources and Uses'!D12 -> 0 | E12: ='2. Sources and Uses'!E12 -> 0 | F12: ='2. Sources and Uses'!F12 -> 0 | G12: ='2. Sources and Uses'!G12 -> 0 | I12: =B12 -> Working Capital | J12: =C12 -> 0 | K12: =D12 -> 0 | L12: =G12 -> 0 | N12: =B12 -> Working Capital | O12: =C12 -> 0 | P12: =D12 -> 0 | Q12: =E12 -> 0 | R12: =G12 -> 0 | T12: =B12 -> Working Capital | U12: =C12 -> 0 | V12: =D12 -> 0 | W12: =F12 -> 0 | X12: =G12 -> 0
B13: ='2. Sources and Uses'!B13 -> Working Capital - Pre Opening | C13: ='2. Sources and Uses'!C13 -> 0 | D13: ='2. Sources and Uses'!D13 -> 0 | E13: ='2. Sources and Uses'!E13 -> 0 | F13: ='2. Sources and Uses'!F13 -> 0 | G13: ='2. Sources and Uses'!G13 -> 0 | I13: =B13 -> Working Capital - Pre Opening | J13: =C13 -> 0 | K13: =D13 -> 0 | L13: =G13 -> 0 | N13: =B13 -> Working Capital - Pre Opening | O13: =C13 -> 0 | P13: =D13 -> 0 | Q13: =E13 -> 0 | R13: =G13 -> 0 | T13: =B13 -> Working Capital - Pre Opening | U13: =C13 -> 0 | V13: =D13 -> 0 | W13: =F13 -> 0 | X13: =G13 -> 0
B14: ='2. Sources and Uses'!B14 -> Business Acquisition | C14: ='2. Sources and Uses'!C14 -> 0 | D14: ='2. Sources and Uses'!D14 -> 0 | E14: ='2. Sources and Uses'!E14 -> 0 | F14: ='2. Sources and Uses'!F14 -> 0 | G14: ='2. Sources and Uses'!G14 -> 0 | I14: =B14 -> Business Acquisition | J14: =C14 -> 0 | K14: =D14 -> 0 | L14: =G14 -> 0 | N14: =B14 -> Business Acquisition | O14: =C14 -> 0 | P14: =D14 -> 0 | Q14: =E14 -> 0 | R14: =G14 -> 0 | T14: =B14 -> Business Acquisition | U14: =C14 -> 0 | V14: =D14 -> 0 | W14: =F14 -> 0 | X14: =G14 -> 0
B15: ='2. Sources and Uses'!B15 -> Franchise Fees | C15: ='2. Sources and Uses'!C15 -> 0 | D15: ='2. Sources and Uses'!D15 -> 0 | E15: ='2. Sources and Uses'!E15 -> 0 | F15: ='2. Sources and Uses'!F15 -> 0 | G15: ='2. Sources and Uses'!G15 -> 0 | I15: =B15 -> Franchise Fees | J15: =C15 -> 0 | K15: =D15 -> 0 | L15: =G15 -> 0 | N15: =B15 -> Franchise Fees | O15: =C15 -> 0 | P15: =D15 -> 0 | Q15: =E15 -> 0 | R15: =G15 -> 0 | T15: =B15 -> Franchise Fees | U15: =C15 -> 0 | V15: =D15 -> 0 | W15: =F15 -> 0 | X15: =G15 -> 0
B16: ='2. Sources and Uses'!B16 -> Construction Hard Costs | C16: ='2. Sources and Uses'!C16 -> 0 | D16: ='2. Sources and Uses'!D16 -> 0 | E16: ='2. Sources and Uses'!E16 -> 0 | F16: ='2. Sources and Uses'!F16 -> 0 | G16: ='2. Sources and Uses'!G16 -> 0 | I16: =B16 -> Construction Hard Costs | J16: =C16 -> 0 | K16: =D16 -> 0 | L16: =G16 -> 0 | N16: =B16 -> Construction Hard Costs | O16: =C16 -> 0 | P16: =D16 -> 0 | Q16: =E16 -> 0 | R16: =G16 -> 0 | T16: =B16 -> Construction Hard Costs | U16: =C16 -> 0 | V16: =D16 -> 0 | W16: =F16 -> 0 | X16: =G16 -> 0
B17: ='2. Sources and Uses'!B17 -> Interim Interest Reserve | C17: ='2. Sources and Uses'!C17 -> 0 | D17: ='2. Sources and Uses'!D17 -> 0 | E17: ='2. Sources and Uses'!E17 -> 0 | F17: ='2. Sources and Uses'!F17 -> 0 | G17: ='2. Sources and Uses'!G17 -> 0 | I17: =B17 -> Interim Interest Reserve | J17: =C17 -> 0 | K17: =D17 -> 0 | L17: =G17 -> 0 | N17: =B17 -> Interim Interest Reserve | O17: =C17 -> 0 | P17: =D17 -> 0 | Q17: =E17 -> 0 | R17: =G17 -> 0 | T17: =B17 -> Interim Interest Reserve | U17: =C17 -> 0 | V17: =D17 -> 0 | W17: =F17 -> 0 | X17: =G17 -> 0
... B21: ='2. Sources and Uses'!B21 -> SBA Gty Fee | C21: ='2. Sources and Uses'!C21 -> 0 | D21: ='2. Sources and Uses'!D21 -> 0 | E21: ='2. Sources and Uses'!E21 | F21: ='2. Sources and Uses'!F21 | G21: ='2. Sources and Uses'!G21 -> 0 | I21: =B21 -> SBA Gty Fee | J21: =C21 -> 0 | K21: =D21 -> 0 | L21: =G21 -> 0 | N21: =B21 -> SBA Gty Fee | O21: =C21 -> 0 | P21: =D21 -> 0 | Q21: =E21 | R21: =G21 -> 0 | T21: =B21 -> SBA Gty Fee | U21: =C21 -> 0 | V21: =D21 -> 0 | W21: =F21 | X21: =G21 -> 0
B22: Project Total | C22: ='2. Sources and Uses'!C22 -> 0 | D22: ='2. Sources and Uses'!D22 -> 0 | E22: ='2. Sources and Uses'!E22 -> 0 | F22: ='2. Sources and Uses'!F22 -> 0 | G22: ='2. Sources and Uses'!G22 -> 0 | I22: =B22 -> Project Total | J22: =C22 -> 0 | K22: =D22 -> 0 | L22: =G22 -> 0 | N22: =B22 -> Project Total | O22: =C22 -> 0 | P22: =D22 -> 0 | Q22: =E22 -> 0 | R22: =G22 -> 0 | T22: =B22 -> Project Total | U22: =C22 -> 0 | V22: =D22 -> 0 | W22: =F22 -> 0 | X22: =G22 -> 0
B23: Percentages | C23: ='2. Sources and Uses'!C23 -> 0 | D23: ='2. Sources and Uses'!D23 -> 0 | E23: ='2. Sources and Uses'!E23 -> 0 | F23: ='2. Sources and Uses'!F23 -> 0 | G23: ='2. Sources and Uses'!G23 -> 0 | I23: =B23 -> Percentages | J23: =C23 -> 0 | K23: =D23 -> 0 | L23: =G23 -> 0 | N23: =B23 -> Percentages | O23: =C23 -> 0 | P23: =D23 -> 0 | Q23: =E23 -> 0 | R23: =G23 -> 0 | T23: =B23 -> Percentages | U23: =C23 -> 0 | V23: =D23 -> 0 | W23: =F23 -> 0 | X23: =G23 -> 0
B26: Closing & 3rd Party Costs
B27: (Estimated)
B28: ='2. Sources and Uses'!B39 -> Loan Packaging Fee | C28: ='2. Sources and Uses'!C39 -> 2500 | D28: ='2. Sources and Uses'!D39 -> 1 | E28: ='2. Sources and Uses'!E39 -> 2500
B29: ='2. Sources and Uses'!B40 -> Title Insurance | C29: ='2. Sources and Uses'!C40 -> 0 | D29: ='2. Sources and Uses'!D40 -> 0 | E29: ='2. Sources and Uses'!E40 -> 0
B30: ='2. Sources and Uses'!B41 -> Real Estate Tax Fee | C30: ='2. Sources and Uses'!C41 -> 0 | D30: ='2. Sources and Uses'!D41 -> 0 | E30: ='2. Sources and Uses'!E41 -> 0
B31: ='2. Sources and Uses'!B42 -> Survey Charges | C31: ='2. Sources and Uses'!C42 -> 3000 | D31: ='2. Sources and Uses'!D42 -> 0 | E31: ='2. Sources and Uses'!E42 -> 0
B32: ='2. Sources and Uses'!B43 -> CRE Appraisal | C32: ='2. Sources and Uses'!C43 -> 3500 | D32: ='2. Sources and Uses'!D43 -> 0 | E32: ='2. Sources and Uses'!E43 -> 0
B33: ='2. Sources and Uses'!B44 -> Equipment Appraisal | C33: ='2. Sources and Uses'!C44 -> 0 | D33: ='2. Sources and Uses'!D44 -> 0 | E33: ='2. Sources and Uses'!E44 -> 0
B34: ='2. Sources and Uses'!B45 -> Appraisal Review | C34: ='2. Sources and Uses'!C45 -> 0 | D34: ='2. Sources and Uses'!D45 -> 0 | E34: ='2. Sources and Uses'!E45 -> 0
B35: ='2. Sources and Uses'!B46 -> Site Visit | C35: ='2. Sources and Uses'!C46 -> 350 | D35: ='2. Sources and Uses'!D46 -> 0 | E35: ='2. Sources and Uses'!E46 -> 0
B36: ='2. Sources and Uses'!B47 -> Environmental Investigation | C36: ='2. Sources and Uses'!C47 -> 2500 | D36: ='2. Sources and Uses'!D47 -> 0 | E36: ='2. Sources and Uses'!E47 -> 0
B37: ='2. Sources and Uses'!B48 -> Business Valuation | C37: ='2. Sources and Uses'!C48 -> 2500 | D37: ='2. Sources and Uses'!D48 -> 0 | E37: ='2. Sources and Uses'!E48 -> 0
B38: ='2. Sources and Uses'!B49 -> Residential Appr/Valuation | C38: ='2. Sources and Uses'!C49 -> 0 | D38: ='2. Sources and Uses'!D49 -> 0 | E38: ='2. Sources and Uses'!E49 -> 0
B39: ='2. Sources and Uses'!B50 -> Attorney Doc Prep | C39: ='2. Sources and Uses'!C50 -> 6000 | D39: ='2. Sources and Uses'!D50 -> 1 | E39: ='2. Sources and Uses'!E50 -> 6000
... B43: ='2. Sources and Uses'!B54 -> Other: UCCs and Misc Closing | C43: ='2. Sources and Uses'!C54 | D43: ='2. Sources and Uses'!D54 | E43: ='2. Sources and Uses'!E54 -> 800
B44: Total Estimated Closing Costs | E44: ='2. Sources and Uses'!E55 -> 10000
B47: Structure Table
C49: ='1. Project Structure'!C11 -> T Bank Loan | D49: ='1. Project Structure'!E11 -> Seller Note | E49: ='1. Project Structure'!F11 -> 3rd Party
B50: Loan Amount | C50: ='1. Project Structure'!C13 -> 0 | D50: ='1. Project Structure'!E13 -> 0 | E50: ='1. Project Structure'!F13 -> 0
B51: ='1. Project Structure'!B14 -> Base Rate | C51: ='1. Project Structure'!C14 -> 0.075 | D51: ='1. Project Structure'!E14 -> 0.08 | E51: ='1. Project Structure'!F14 -> 0.0624
B52: ='1. Project Structure'!B15 -> Spread | C52: ='1. Project Structure'!C15 -> 0.015 | D52: ='1. Project Structure'!E15 -> 0 | E52: ='1. Project Structure'!F15 -> 0
B53: ='1. Project Structure'!B16 -> Indicative Rate | C53: ='1. Project Structure'!C16 -> 0.09 | D53: ='1. Project Structure'!E16 -> 0.08 | E53: ='1. Project Structure'!F16 -> 0.0624
B54: Adjustment / Fix | C54: Quarterly | D54: Fixed | E54: Fixed
...

Sheet 6. Affiliates
B2: Affiliate Analysis
B3: Income Statement Spreads
B4: {Insert business name which represents Affiliate 1}
B5: Include in Global? | C5: No
B6: Statement Date | D6: 44926 | F6: =EOMONTH(D6,F7) -> 45291 | H6: =EOMONTH(F6,H7) -> 45657 | J6: =EOMONTH(H6,J7) -> 45747
B7: Months Covered | D7: 12 | F7: 12 | H7: 12 | J7: 3
B8: Statement Type | D8: Tax Returns | F8: Tax Returns | J8: Internal
B9: Revenue Recognition
B10: REVENUE | J10: =(J11/J7)*12 -> 0
B11: Revenue | C11: (Product Line #1) | D11: 0 | E11: =IF(D$20=0,0,D11/D$20) -> 0 | F11: 0 | G11: =IF(F$20=0,0,F11/F$20) -> 0 | H11: 0 | I11: =IF(H$20=0,0,H11/H$20) -> 0 | J11: 0 | K11: =IF(J$20=0,0,J11/J$20) -> 0
B12: COGS | C12: (Product Line #1) | D12: 0 | E12: =IF(D$20=0,0,D12/D$20) -> 0 | F12: 0 | G12: =IF(F$20=0,0,F12/F$20) -> 0 | H12: 0 | I12: =IF(H$20=0,0,H12/H$20) -> 0 | J12: 0 | K12: =IF(J$20=0,0,J12/J$20) -> 0
B13: Gross Margin | C13: (Product Line #1) | D13: =D11-D12 -> 0 | E13: =IF(D$20=0,0,D13/D$20) -> 0 | F13: =F11-F12 -> 0 | G13: =IF(F$20=0,0,F13/F$20) -> 0 | H13: =H11-H12 -> 0 | I13: =IF(H$20=0,0,H13/H$20) -> 0 | J13: =J11-J12 -> 0 | K13: =IF(J$20=0,0,J13/J$20) -> 0
B14: Revenue | C14: (Product Line #2) | D14: 0 | E14: =IF(D$20=0,0,D14/D$20) -> 0 | F14: 0 | G14: =IF(F$20=0,0,F14/F$20) -> 0 | H14: 0 | I14: =IF(H$20=0,0,H14/H$20) -> 0 | J14: 0 | K14: =IF(J$20=0,0,J14/J$20) -> 0
B15: COGS | C15: (Product Line #2) | D15: 0 | E15: =IF(D$20=0,0,D15/D$20) -> 0 | F15: 0 | G15: =IF(F$20=0,0,F15/F$20) -> 0 | H15: 0 | I15: =IF(H$20=0,0,H15/H$20) -> 0 | J15: 0 | K15: =IF(J$20=0,0,J15/J$20) -> 0
B16: Gross Margin | C16: (Product Line #2) | D16: =D14-D15 -> 0 | E16: =IF(D$20=0,0,D16/D$20) -> 0 | F16: =F14-F15 -> 0 | G16: =IF(F$20=0,0,F16/F$20) -> 0 | H16: =H14-H15 -> 0 | I16: =IF(H$20=0,0,H16/H$20) -> 0 | J16: =J14-J15 -> 0 | K16: =IF(J$20=0,0,J16/J$20) -> 0
B17: Revenue | C17: (Product Line #3) | D17: 0 | E17: =IF(D$20=0,0,D17/D$20) -> 0 | F17: 0 | G17: =IF(F$20=0,0,F17/F$20) -> 0 | H17: 0 | I17: =IF(H$20=0,0,H17/H$20) -> 0 | J17: 0 | K17: =IF(J$20=0,0,J17/J$20) -> 0
B18: COGS | C18: (Product Line #3) | D18: 0 | E18: =IF(D$20=0,0,D18/D$20) -> 0 | F18: 0 | G18: =IF(F$20=0,0,F18/F$20) -> 0 | H18: 0 | I18: =IF(H$20=0,0,H18/H$20) -> 0 | J18: 0 | K18: =IF(J$20=0,0,J18/J$20) -> 0
B19: Gross Margin | C19: (Product Line #3) | D19: =D17-D18 -> 0 | E19: =IF(D$20=0,0,D19/D$20) -> 0 | F19: =F17-F18 -> 0 | G19: =IF(F$20=0,0,F19/F$20) -> 0 | H19: =H17-H18 -> 0 | I19: =IF(H$20=0,0,H19/H$20) -> 0 | J19: =J17-J18 -> 0 | K19: =IF(J$20=0,0,J19/J$20) -> 0
B20: Click to expand/collapse | C20: Total Revenue | D20: =D11+D14+D17 -> 0 | E20: =IF(D$20=0,0,D20/D$20) -> 0 | F20: =F11+F14+F17 -> 0 | G20: =IF(F$20=0,0,F20/F$20) -> 0 | H20: =H11+H14+H17 -> 0 | I20: =IF(H$20=0,0,H20/H$20) -> 0 | J20: =J11+J14+J17 -> 0 | K20: =IF(J$20=0,0,J20/J$20) -> 0
C21: Total COGS | D21: =D12+D15+D18 -> 0 | E21: =IF(D$20=0,0,D21/D$20) -> 0 | F21: =F12+F15+F18 -> 0 | G21: =IF(F$20=0,0,F21/F$20) -> 0 | H21: =H12+H15+H18 -> 0 | I21: =IF(H$20=0,0,H21/H$20) -> 0 | J21: =J12+J15+J18 -> 0 | K21: =IF(J$20=0,0,J21/J$20) -> 0
C22: Total Gross Margin | D22: =D20-D21 -> 0 | E22: =IF(D$20=0,0,D22/D$20) -> 0 | F22: =F20-F21 -> 0 | G22: =IF(F$20=0,0,F22/F$20) -> 0 | H22: =H20-H21 -> 0 | I22: =IF(H$20=0,0,H22/H$20) -> 0 | J22: =J20-J21 -> 0 | K22: =IF(J$20=0,0,J22/J$20) -> 0
C24: OPERATING EXPENSES
C25: Officer's Compensation | D25: 0 | E25: =IF(D$20=0,0,D25/D$20) -> 0 | F25: 0 | G25: =IF(F$20=0,0,F25/F$20) -> 0 | H25: 0 | I25: =IF(H$20=0,0,H25/H$20) -> 0 | J25: 0 | K25: =IF(J$20=0,0,J25/J$20) -> 0
C26: Salaries & Wages | D26: 0 | E26: =IF(D$20=0,0,D26/D$20) -> 0 | F26: 0 | G26: =IF(F$20=0,0,F26/F$20) -> 0 | H26: 0 | I26: =IF(H$20=0,0,H26/H$20) -> 0 | J26: 0 | K26: =IF(J$20=0,0,J26/J$20) -> 0
C27: Repairs & Maintenance | D27: 0 | E27: =IF(D$20=0,0,D27/D$20) -> 0 | F27: 0 | G27: =IF(F$20=0,0,F27/F$20) -> 0 | H27: 0 | I27: =IF(H$20=0,0,H27/H$20) -> 0 | J27: 0 | K27: =IF(J$20=0,0,J27/J$20) -> 0
C28: Bad Debts | D28: 0 | E28: =IF(D$20=0,0,D28/D$20) -> 0 | F28: 0 | G28: =IF(F$20=0,0,F28/F$20) -> 0 | H28: 0 | I28: =IF(H$20=0,0,H28/H$20) -> 0 | J28: 0 | K28: =IF(J$20=0,0,J28/J$20) -> 0
C29: Rents | D29: 0 | E29: =IF(D$20=0,0,D29/D$20) -> 0 | F29: 0 | G29: =IF(F$20=0,0,F29/F$20) -> 0 | H29: 0 | I29: =IF(H$20=0,0,H29/H$20) -> 0 | J29: 0 | K29: =IF(J$20=0,0,J29/J$20) -> 0
C30: Taxes & Licenses | D30: 0 | E30: =IF(D$20=0,0,D30/D$20) -> 0 | F30: 0 | G30: =IF(F$20=0,0,F30/F$20) -> 0 | H30: 0 | I30: =IF(H$20=0,0,H30/H$20) -> 0 | J30: 0 | K30: =IF(J$20=0,0,J30/J$20) -> 0
C31: Interest | D31: 0 | E31: =IF(D$20=0,0,D31/D$20) -> 0 | F31: 0 | G31: =IF(F$20=0,0,F31/F$20) -> 0 | H31: 0 | I31: =IF(H$20=0,0,H31/H$20) -> 0 | J31: 0 | K31: =IF(J$20=0,0,J31/J$20) -> 0
C32: Depreciation & Amortization | D32: 0 | E32: =IF(D$20=0,0,D32/D$20) -> 0 | F32: 0 | G32: =IF(F$20=0,0,F32/F$20) -> 0 | H32: 0 | I32: =IF(H$20=0,0,H32/H$20) -> 0 | J32: 0 | K32: =IF(J$20=0,0,J32/J$20) -> 0
C33: Advertising | D33: 0 | E33: =IF(D$20=0,0,D33/D$20) -> 0 | F33: 0 | G33: =IF(F$20=0,0,F33/F$20) -> 0 | H33: 0 | I33: =IF(H$20=0,0,H33/H$20) -> 0 | J33: 0 | K33: =IF(J$20=0,0,J33/J$20) -> 0
C34: Pension, Profit Sharing | D34: 0 | E34: =IF(D$20=0,0,D34/D$20) -> 0 | F34: 0 | G34: =IF(F$20=0,0,F34/F$20) -> 0 | H34: 0 | I34: =IF(H$20=0,0,H34/H$20) -> 0 | J34: 0 | K34: =IF(J$20=0,0,J34/J$20) -> 0
C35: Employee Benefits | D35: 0 | E35: =IF(D$20=0,0,D35/D$20) -> 0 | F35: 0 | G35: =IF(F$20=0,0,F35/F$20) -> 0 | H35: 0 | I35: =IF(H$20=0,0,H35/H$20) -> 0 | J35: 0 | K35: =IF(J$20=0,0,J35/J$20) -> 0
C36: Insurance | D36: 0 | E36: =IF(D$20=0,0,D36/D$20) -> 0 | F36: 0 | G36: =IF(F$20=0,0,F36/F$20) -> 0 | H36: 0 | I36: =IF(H$20=0,0,H36/H$20) -> 0 | J36: 0 | K36: =IF(J$20=0,0,J36/J$20) -> 0
... C46: Other | D46: 0 | E46: =IF(D$20=0,0,D46/D$20) -> 0 | F46: 0 | G46: =IF(F$20=0,0,F46/F$20) -> 0 | H46: 0 | I46: =IF(H$20=0,0,H46/H$20) -> 0 | J46: 0 | K46: =IF(J$20=0,0,J46/J$20) -> 0
B47: Click to expand/collapse | C47: Other | D47: 0 | E47: =IF(D$20=0,0,D47/D$20) -> 0 | F47: 0 | G47: =IF(F$20=0,0,F47/F$20) -> 0 | H47: 0 | I47: =IF(H$20=0,0,H47/H$20) -> 0 | J47: 0 | K47: =IF(J$20=0,0,J47/J$20) -> 0
C48: Other | D48: =0-SUM(D25:D47) -> 0 | E48: =IF(D$20=0,0,D48/D$20) -> 0 | F48: =0-SUM(F25:F47) -> 0 | G48: =IF(F$20=0,0,F48/F$20) -> 0 | H48: =0-SUM(H25:H47) -> 0 | I48: =IF(H$20=0,0,H48/H$20) -> 0 | J48: =0-SUM(J25:J47) -> 0 | K48: =IF(J$20=0,0,J48/J$20) -> 0
C49: Total Operating Expenses | D49: =SUM(D25:D48) -> 0 | E49: =IF(D$20=0,0,D49/D$20) -> 0 | F49: =SUM(F25:F48) -> 0 | G49: =IF(F$20=0,0,F49/F$20) -> 0 | H49: =SUM(H25:H48) -> 0 | I49: =IF(H$20=0,0,H49/H$20) -> 0 | J49: =SUM(J25:J48) -> 0 | K49: =IF(J$20=0,0,J49/J$20) -> 0
C51: Ordinary Income | D51: =D22-D49 -> 0 | E51: =IF(D$20=0,0,D51/D$20) -> 0 | F51: =F22-F49 -> 0 | G51: =IF(F$20=0,0,F51/F$20) -> 0 | H51: =H22-H49 -> 0 | I51: =IF(H$20=0,0,H51/H$20) -> 0 | J51: =J22-J49 -> 0 | K51: =IF(J$20=0,0,J51/J$20) -> 0
C53: Other Income | D53: 0 | E53: =IF(D$20=0,0,D53/D$20) -> 0 | F53: 0 | G53: =IF(F$20=0,0,F53/F$20) -> 0 | H53: 0 | I53: =IF(H$20=0,0,H53/H$20) -> 0 | J53: 0 | K53: =IF(J$20=0,0,J53/J$20) -> 0
...

Sheet Lists
A1: Version | B1: Loan Type | C1: Basics | D1: Request | E1: UW | F1: BDO
A3: Original | B3: N/A | C3: Yes | D3: New | E3: Andrew Taylor | F3: Audrey Wendel
A4: Mod 1 | B4: SBA 7a | C4: No | D4: Renewal | E4: Antony Parker | F4: Ben Eakin
A5: Mod 2 | B5: SBA Express | C5: N/A | D5: Modification | E5: Brent Ruch | F5: Cameron Brewer
A6: Mod 3 | B6: 504 | E6: Jennifer Dennis | F6: Eric Wadley
A7: Mod 4 | B7: USDA | C7: Disbursement | E7: Jessica Gauden | F7: Glenn Giro
A8: Mod 5 | B8: P&E | E8: Rodney Johnson | F8: Greg Swett
A9: Mod 6 | B9: Conventional | C9: Multi | E9: Rose Haynes-Taylor | F9: Jordan Sayler
A10: Mod 7 | C10: Single | D10: True/False | E10: Connor Shaw | F10: Kandace Moon
A11: Mod 8 | E11: Sheila Simms | F11: Kerry Smith
A12: Mod 9 | D12: True | F12: Kevin Coffman
A13: Mod 10 | D13: False | F13: Mike Ramsay
F14: Patrick Phillips
A15: Entity Types | B15: Loan Program | C15: Risk Rating | D15: Statement Type | E15: Revenue Recognition | F15: Rick McMann
F16: Rod Rodriguez
A17: TBD | B17: N/A | C17: 1 | D17: Tax Returns | E17: Cash | F17: Steve Jones
A18: Sole Prop | B18: PLP | C18: 2 | D18: Audited | E18: Accrual
A19: LLC | B19: GP | C19: 3 | D19: Reviewed | E19: Hybrid
A20: S-Corp | B20: 504 | C20: 4 | D20: Compiled | E20: Other
A21: C-Corp | B21: USDA | C21: 5 | D21: Schedule C | F21: Proforma BS
A22: Prof Corp | C22: 5.5 | D22: Internal
A23: Prof LLC | C23: 6 | D23: Form 10K | F23: New BS
A24: Trust | C24: 7 | D24: Form 10Q | F24: Last Year End
A25: LTD Partnership | C25: 8 | D25: Other | F25: Interim
A26: Partnership | C26: 9
F28: Submission
A29: Rate Adjustment | B29: Lien Position | D29: Property Type | E29: Valuation Method
C30: UCC Lien Type | F30: PLP
A31: Daily | B31: First | D31: C-Store | E31: Cost | F31: Standard
A32: Monthly | B32: Second | C32: Purchase Money UCC | D32: Hotel | E32: Appraisal
A33: Calendar Qtr | B33: Third | C33: Blanket UCC | D33: Industrial | E33: Book Value
A34: Other | B34: Fourth | C34: Security Interest | D34: Medical Office | E34: BPO
B35: Best Available | D35: Mixed-Use | E35: Invoice
D36: Mobile Home Park | E36: Estimated | F36: Construction Type
D37: Multi Family | E37: Tax
